ERROR 2022-07-23 19:12:25,124 241 log.py log 34020 123145567297536 Internal Server Error: /api/v1/auth/register/
Traceback (most recent call last):
  File "/Users/owner/Desktop/flixcave/venv/lib/python3.10/site-packages/django/core/handlers/exception.py", line 55, in inner
    response = get_response(request)
  File "/Users/owner/Desktop/flixcave/venv/lib/python3.10/site-packages/django/core/handlers/base.py", line 197, in _get_response
    response = wrapped_callback(request, *callback_args, **callback_kwargs)
  File "/Users/owner/Desktop/flixcave/venv/lib/python3.10/site-packages/django/views/decorators/csrf.py", line 54, in wrapped_view
    return view_func(*args, **kwargs)
  File "/Users/owner/Desktop/flixcave/venv/lib/python3.10/site-packages/django/views/generic/base.py", line 84, in view
    return self.dispatch(request, *args, **kwargs)
  File "/Users/owner/Desktop/flixcave/venv/lib/python3.10/site-packages/rest_framework/views.py", line 509, in dispatch
    response = self.handle_exception(exc)
  File "/Users/owner/Desktop/flixcave/venv/lib/python3.10/site-packages/rest_framework/views.py", line 469, in handle_exception
    self.raise_uncaught_exception(exc)
  File "/Users/owner/Desktop/flixcave/venv/lib/python3.10/site-packages/rest_framework/views.py", line 480, in raise_uncaught_exception
    raise exc
  File "/Users/owner/Desktop/flixcave/venv/lib/python3.10/site-packages/rest_framework/views.py", line 506, in dispatch
    response = handler(request, *args, **kwargs)
  File "/Users/owner/Desktop/flixcave/authentication/views.py", line 24, in post
    CustomUser.objects.create(
TypeError: CustomUserManager.create() takes 3 positional arguments but 4 were given
ERROR 2022-07-23 19:12:25,127 187 basehttp.py basehttp 34020 123145567297536 "POST /api/v1/auth/register/ HTTP/1.1" 500 92456
ERROR 2022-07-23 19:32:27,723 241 log.py log 34578 123145567838208 Internal Server Error: /api/v1/auth/register/
Traceback (most recent call last):
  File "/Users/owner/Desktop/flixcave/venv/lib/python3.10/site-packages/django/core/handlers/exception.py", line 55, in inner
    response = get_response(request)
  File "/Users/owner/Desktop/flixcave/venv/lib/python3.10/site-packages/django/core/handlers/base.py", line 197, in _get_response
    response = wrapped_callback(request, *callback_args, **callback_kwargs)
  File "/Users/owner/Desktop/flixcave/venv/lib/python3.10/site-packages/django/views/decorators/csrf.py", line 54, in wrapped_view
    return view_func(*args, **kwargs)
  File "/Users/owner/Desktop/flixcave/venv/lib/python3.10/site-packages/django/views/generic/base.py", line 84, in view
    return self.dispatch(request, *args, **kwargs)
  File "/Users/owner/Desktop/flixcave/venv/lib/python3.10/site-packages/rest_framework/views.py", line 509, in dispatch
    response = self.handle_exception(exc)
  File "/Users/owner/Desktop/flixcave/venv/lib/python3.10/site-packages/rest_framework/views.py", line 469, in handle_exception
    self.raise_uncaught_exception(exc)
  File "/Users/owner/Desktop/flixcave/venv/lib/python3.10/site-packages/rest_framework/views.py", line 480, in raise_uncaught_exception
    raise exc
  File "/Users/owner/Desktop/flixcave/venv/lib/python3.10/site-packages/rest_framework/views.py", line 506, in dispatch
    response = handler(request, *args, **kwargs)
  File "/Users/owner/Desktop/flixcave/authentication/views.py", line 23, in post
    CustomUser.objects.create(data['email'], data['password'], **data)
TypeError: CustomUserManager.create() got multiple values for argument 'email'
ERROR 2022-07-23 19:32:27,730 187 basehttp.py basehttp 34578 123145567838208 "POST /api/v1/auth/register/ HTTP/1.1" 500 92566
ERROR 2022-07-23 19:36:49,830 241 log.py log 34613 123145340964864 Internal Server Error: /api/v1/auth/register/
Traceback (most recent call last):
  File "/Users/owner/Desktop/flixcave/venv/lib/python3.10/site-packages/django/core/handlers/exception.py", line 55, in inner
    response = get_response(request)
  File "/Users/owner/Desktop/flixcave/venv/lib/python3.10/site-packages/django/core/handlers/base.py", line 197, in _get_response
    response = wrapped_callback(request, *callback_args, **callback_kwargs)
  File "/Users/owner/Desktop/flixcave/venv/lib/python3.10/site-packages/django/views/decorators/csrf.py", line 54, in wrapped_view
    return view_func(*args, **kwargs)
  File "/Users/owner/Desktop/flixcave/venv/lib/python3.10/site-packages/django/views/generic/base.py", line 84, in view
    return self.dispatch(request, *args, **kwargs)
  File "/Users/owner/Desktop/flixcave/venv/lib/python3.10/site-packages/rest_framework/views.py", line 509, in dispatch
    response = self.handle_exception(exc)
  File "/Users/owner/Desktop/flixcave/venv/lib/python3.10/site-packages/rest_framework/views.py", line 469, in handle_exception
    self.raise_uncaught_exception(exc)
  File "/Users/owner/Desktop/flixcave/venv/lib/python3.10/site-packages/rest_framework/views.py", line 480, in raise_uncaught_exception
    raise exc
  File "/Users/owner/Desktop/flixcave/venv/lib/python3.10/site-packages/rest_framework/views.py", line 506, in dispatch
    response = handler(request, *args, **kwargs)
  File "/Users/owner/Desktop/flixcave/authentication/views.py", line 23, in post
    CustomUser.objects.create(
  File "/Users/owner/Desktop/flixcave/account/models.py", line 31, in create
    user = self.model(email=email, password=password, **extra_fields)
  File "/Users/owner/Desktop/flixcave/venv/lib/python3.10/site-packages/django/db/models/base.py", line 559, in __init__
    raise TypeError(
TypeError: CustomUser() got an unexpected keyword argument 'confirm_password'
ERROR 2022-07-23 19:36:49,831 187 basehttp.py basehttp 34613 123145340964864 "POST /api/v1/auth/register/ HTTP/1.1" 500 102814
ERROR 2022-07-23 19:37:52,107 241 log.py log 34678 123145515737088 Internal Server Error: /api/v1/auth/register/
Traceback (most recent call last):
  File "/Users/owner/Desktop/flixcave/venv/lib/python3.10/site-packages/django/core/handlers/exception.py", line 55, in inner
    response = get_response(request)
  File "/Users/owner/Desktop/flixcave/venv/lib/python3.10/site-packages/django/core/handlers/base.py", line 197, in _get_response
    response = wrapped_callback(request, *callback_args, **callback_kwargs)
  File "/Users/owner/Desktop/flixcave/venv/lib/python3.10/site-packages/django/views/decorators/csrf.py", line 54, in wrapped_view
    return view_func(*args, **kwargs)
  File "/Users/owner/Desktop/flixcave/venv/lib/python3.10/site-packages/django/views/generic/base.py", line 84, in view
    return self.dispatch(request, *args, **kwargs)
  File "/Users/owner/Desktop/flixcave/venv/lib/python3.10/site-packages/rest_framework/views.py", line 509, in dispatch
    response = self.handle_exception(exc)
  File "/Users/owner/Desktop/flixcave/venv/lib/python3.10/site-packages/rest_framework/views.py", line 469, in handle_exception
    self.raise_uncaught_exception(exc)
  File "/Users/owner/Desktop/flixcave/venv/lib/python3.10/site-packages/rest_framework/views.py", line 480, in raise_uncaught_exception
    raise exc
  File "/Users/owner/Desktop/flixcave/venv/lib/python3.10/site-packages/rest_framework/views.py", line 506, in dispatch
    response = handler(request, *args, **kwargs)
  File "/Users/owner/Desktop/flixcave/authentication/views.py", line 23, in post
    CustomUser.objects.create(
  File "/Users/owner/Desktop/flixcave/account/models.py", line 31, in create
    user = self.model(email=email, password=password, **extra_fields)
  File "/Users/owner/Desktop/flixcave/venv/lib/python3.10/site-packages/django/db/models/base.py", line 559, in __init__
    raise TypeError(
TypeError: CustomUser() got an unexpected keyword argument 'confirm_password'
ERROR 2022-07-23 19:37:52,109 187 basehttp.py basehttp 34678 123145515737088 "POST /api/v1/auth/register/ HTTP/1.1" 500 102842
ERROR 2022-07-23 19:39:40,647 241 log.py log 34742 123145445203968 Internal Server Error: /api/v1/auth/register/
Traceback (most recent call last):
  File "/Users/owner/Desktop/flixcave/venv/lib/python3.10/site-packages/django/core/handlers/exception.py", line 55, in inner
    response = get_response(request)
  File "/Users/owner/Desktop/flixcave/venv/lib/python3.10/site-packages/django/core/handlers/base.py", line 197, in _get_response
    response = wrapped_callback(request, *callback_args, **callback_kwargs)
  File "/Users/owner/Desktop/flixcave/venv/lib/python3.10/site-packages/django/views/decorators/csrf.py", line 54, in wrapped_view
    return view_func(*args, **kwargs)
  File "/Users/owner/Desktop/flixcave/venv/lib/python3.10/site-packages/django/views/generic/base.py", line 84, in view
    return self.dispatch(request, *args, **kwargs)
  File "/Users/owner/Desktop/flixcave/venv/lib/python3.10/site-packages/rest_framework/views.py", line 509, in dispatch
    response = self.handle_exception(exc)
  File "/Users/owner/Desktop/flixcave/venv/lib/python3.10/site-packages/rest_framework/views.py", line 469, in handle_exception
    self.raise_uncaught_exception(exc)
  File "/Users/owner/Desktop/flixcave/venv/lib/python3.10/site-packages/rest_framework/views.py", line 480, in raise_uncaught_exception
    raise exc
  File "/Users/owner/Desktop/flixcave/venv/lib/python3.10/site-packages/rest_framework/views.py", line 506, in dispatch
    response = handler(request, *args, **kwargs)
  File "/Users/owner/Desktop/flixcave/authentication/views.py", line 23, in post
    CustomUser.objects.create(
  File "/Users/owner/Desktop/flixcave/account/models.py", line 28, in create
    extra_fields = {key: val for key,
  File "/Users/owner/Desktop/flixcave/account/models.py", line 28, in <dictcomp>
    extra_fields = {key: val for key,
ValueError: too many values to unpack (expected 2)
ERROR 2022-07-23 19:39:40,648 187 basehttp.py basehttp 34742 123145445203968 "POST /api/v1/auth/register/ HTTP/1.1" 500 99895
ERROR 2022-07-23 19:39:40,955 241 log.py log 34742 123145445203968 Internal Server Error: /api/v1/auth/register/
Traceback (most recent call last):
  File "/Users/owner/Desktop/flixcave/venv/lib/python3.10/site-packages/django/core/handlers/exception.py", line 55, in inner
    response = get_response(request)
  File "/Users/owner/Desktop/flixcave/venv/lib/python3.10/site-packages/django/core/handlers/base.py", line 197, in _get_response
    response = wrapped_callback(request, *callback_args, **callback_kwargs)
  File "/Users/owner/Desktop/flixcave/venv/lib/python3.10/site-packages/django/views/decorators/csrf.py", line 54, in wrapped_view
    return view_func(*args, **kwargs)
  File "/Users/owner/Desktop/flixcave/venv/lib/python3.10/site-packages/django/views/generic/base.py", line 84, in view
    return self.dispatch(request, *args, **kwargs)
  File "/Users/owner/Desktop/flixcave/venv/lib/python3.10/site-packages/rest_framework/views.py", line 509, in dispatch
    response = self.handle_exception(exc)
  File "/Users/owner/Desktop/flixcave/venv/lib/python3.10/site-packages/rest_framework/views.py", line 469, in handle_exception
    self.raise_uncaught_exception(exc)
  File "/Users/owner/Desktop/flixcave/venv/lib/python3.10/site-packages/rest_framework/views.py", line 480, in raise_uncaught_exception
    raise exc
  File "/Users/owner/Desktop/flixcave/venv/lib/python3.10/site-packages/rest_framework/views.py", line 506, in dispatch
    response = handler(request, *args, **kwargs)
  File "/Users/owner/Desktop/flixcave/authentication/views.py", line 23, in post
    CustomUser.objects.create(
  File "/Users/owner/Desktop/flixcave/account/models.py", line 28, in create
    extra_fields = {key: val for key,
  File "/Users/owner/Desktop/flixcave/account/models.py", line 28, in <dictcomp>
    extra_fields = {key: val for key,
ValueError: too many values to unpack (expected 2)
ERROR 2022-07-23 19:39:40,956 187 basehttp.py basehttp 34742 123145445203968 "POST /api/v1/auth/register/ HTTP/1.1" 500 99895
ERROR 2022-07-23 19:50:34,866 241 log.py log 34959 123145511714816 Internal Server Error: /api/v1/auth/register/
Traceback (most recent call last):
  File "/Users/owner/Desktop/flixcave/venv/lib/python3.10/site-packages/django/core/handlers/exception.py", line 55, in inner
    response = get_response(request)
  File "/Users/owner/Desktop/flixcave/venv/lib/python3.10/site-packages/django/core/handlers/base.py", line 197, in _get_response
    response = wrapped_callback(request, *callback_args, **callback_kwargs)
  File "/Users/owner/Desktop/flixcave/venv/lib/python3.10/site-packages/django/views/decorators/csrf.py", line 54, in wrapped_view
    return view_func(*args, **kwargs)
  File "/Users/owner/Desktop/flixcave/venv/lib/python3.10/site-packages/django/views/generic/base.py", line 84, in view
    return self.dispatch(request, *args, **kwargs)
  File "/Users/owner/Desktop/flixcave/venv/lib/python3.10/site-packages/rest_framework/views.py", line 509, in dispatch
    response = self.handle_exception(exc)
  File "/Users/owner/Desktop/flixcave/venv/lib/python3.10/site-packages/rest_framework/views.py", line 469, in handle_exception
    self.raise_uncaught_exception(exc)
  File "/Users/owner/Desktop/flixcave/venv/lib/python3.10/site-packages/rest_framework/views.py", line 480, in raise_uncaught_exception
    raise exc
  File "/Users/owner/Desktop/flixcave/venv/lib/python3.10/site-packages/rest_framework/views.py", line 506, in dispatch
    response = handler(request, *args, **kwargs)
  File "/Users/owner/Desktop/flixcave/authentication/views.py", line 23, in post
    CustomUser.objects.create(
  File "/Users/owner/Desktop/flixcave/account/models.py", line 28, in create
    test = {key: val for key, val in extra_fields if key == 'confirm_password'}
  File "/Users/owner/Desktop/flixcave/account/models.py", line 28, in <dictcomp>
    test = {key: val for key, val in extra_fields if key == 'confirm_password'}
ValueError: too many values to unpack (expected 2)
ERROR 2022-07-23 19:50:34,888 187 basehttp.py basehttp 34959 123145511714816 "POST /api/v1/auth/register/ HTTP/1.1" 500 100311
ERROR 2022-07-23 19:52:27,938 241 log.py log 34980 123145551822848 Internal Server Error: /api/v1/auth/register/
Traceback (most recent call last):
  File "/Users/owner/Desktop/flixcave/venv/lib/python3.10/site-packages/django/core/handlers/exception.py", line 55, in inner
    response = get_response(request)
  File "/Users/owner/Desktop/flixcave/venv/lib/python3.10/site-packages/django/core/handlers/base.py", line 197, in _get_response
    response = wrapped_callback(request, *callback_args, **callback_kwargs)
  File "/Users/owner/Desktop/flixcave/venv/lib/python3.10/site-packages/django/views/decorators/csrf.py", line 54, in wrapped_view
    return view_func(*args, **kwargs)
  File "/Users/owner/Desktop/flixcave/venv/lib/python3.10/site-packages/django/views/generic/base.py", line 84, in view
    return self.dispatch(request, *args, **kwargs)
  File "/Users/owner/Desktop/flixcave/venv/lib/python3.10/site-packages/rest_framework/views.py", line 509, in dispatch
    response = self.handle_exception(exc)
  File "/Users/owner/Desktop/flixcave/venv/lib/python3.10/site-packages/rest_framework/views.py", line 469, in handle_exception
    self.raise_uncaught_exception(exc)
  File "/Users/owner/Desktop/flixcave/venv/lib/python3.10/site-packages/rest_framework/views.py", line 480, in raise_uncaught_exception
    raise exc
  File "/Users/owner/Desktop/flixcave/venv/lib/python3.10/site-packages/rest_framework/views.py", line 506, in dispatch
    response = handler(request, *args, **kwargs)
  File "/Users/owner/Desktop/flixcave/authentication/views.py", line 23, in post
    CustomUser.objects.create(
  File "/Users/owner/Desktop/flixcave/account/models.py", line 28, in create
    test = {key: val for key, val in extra_fields}
  File "/Users/owner/Desktop/flixcave/account/models.py", line 28, in <dictcomp>
    test = {key: val for key, val in extra_fields}
ValueError: too many values to unpack (expected 2)
ERROR 2022-07-23 19:52:27,939 187 basehttp.py basehttp 34980 123145551822848 "POST /api/v1/auth/register/ HTTP/1.1" 500 100151
ERROR 2022-07-23 21:58:38,781 241 log.py log 36422 123145565327360 Internal Server Error: /api/v1/auth/register/
Traceback (most recent call last):
  File "/Users/owner/Desktop/flixcave/venv/lib/python3.10/site-packages/django/db/backends/utils.py", line 89, in _execute
    return self.cursor.execute(sql, params)
psycopg2.errors.UndefinedTable: relation "verification_token_verificationtoken" does not exist
LINE 1: INSERT INTO "verification_token_verificationtoken" ("created...
                    ^


The above exception was the direct cause of the following exception:

Traceback (most recent call last):
  File "/Users/owner/Desktop/flixcave/venv/lib/python3.10/site-packages/django/core/handlers/exception.py", line 55, in inner
    response = get_response(request)
  File "/Users/owner/Desktop/flixcave/venv/lib/python3.10/site-packages/django/core/handlers/base.py", line 197, in _get_response
    response = wrapped_callback(request, *callback_args, **callback_kwargs)
  File "/Users/owner/Desktop/flixcave/venv/lib/python3.10/site-packages/django/views/decorators/csrf.py", line 54, in wrapped_view
    return view_func(*args, **kwargs)
  File "/Users/owner/Desktop/flixcave/venv/lib/python3.10/site-packages/django/views/generic/base.py", line 84, in view
    return self.dispatch(request, *args, **kwargs)
  File "/Users/owner/Desktop/flixcave/venv/lib/python3.10/site-packages/rest_framework/views.py", line 509, in dispatch
    response = self.handle_exception(exc)
  File "/Users/owner/Desktop/flixcave/venv/lib/python3.10/site-packages/rest_framework/views.py", line 469, in handle_exception
    self.raise_uncaught_exception(exc)
  File "/Users/owner/Desktop/flixcave/venv/lib/python3.10/site-packages/rest_framework/views.py", line 480, in raise_uncaught_exception
    raise exc
  File "/Users/owner/Desktop/flixcave/venv/lib/python3.10/site-packages/rest_framework/views.py", line 506, in dispatch
    response = handler(request, *args, **kwargs)
  File "/Users/owner/Desktop/flixcave/authentication/views.py", line 27, in post
    token = VerificationToken.objects.create(user)
  File "/Users/owner/Desktop/flixcave/verification_token/models.py", line 16, in create
    verification_token.save()
  File "/Users/owner/Desktop/flixcave/venv/lib/python3.10/site-packages/django/db/models/base.py", line 806, in save
    self.save_base(
  File "/Users/owner/Desktop/flixcave/venv/lib/python3.10/site-packages/django/db/models/base.py", line 857, in save_base
    updated = self._save_table(
  File "/Users/owner/Desktop/flixcave/venv/lib/python3.10/site-packages/django/db/models/base.py", line 1000, in _save_table
    results = self._do_insert(
  File "/Users/owner/Desktop/flixcave/venv/lib/python3.10/site-packages/django/db/models/base.py", line 1041, in _do_insert
    return manager._insert(
  File "/Users/owner/Desktop/flixcave/venv/lib/python3.10/site-packages/django/db/models/manager.py", line 85, in manager_method
    return getattr(self.get_queryset(), name)(*args, **kwargs)
  File "/Users/owner/Desktop/flixcave/venv/lib/python3.10/site-packages/django/db/models/query.py", line 1434, in _insert
    return query.get_compiler(using=using).execute_sql(returning_fields)
  File "/Users/owner/Desktop/flixcave/venv/lib/python3.10/site-packages/django/db/models/sql/compiler.py", line 1621, in execute_sql
    cursor.execute(sql, params)
  File "/Users/owner/Desktop/flixcave/venv/lib/python3.10/site-packages/django/db/backends/utils.py", line 103, in execute
    return super().execute(sql, params)
  File "/Users/owner/Desktop/flixcave/venv/lib/python3.10/site-packages/django/db/backends/utils.py", line 67, in execute
    return self._execute_with_wrappers(
  File "/Users/owner/Desktop/flixcave/venv/lib/python3.10/site-packages/django/db/backends/utils.py", line 80, in _execute_with_wrappers
    return executor(sql, params, many, context)
  File "/Users/owner/Desktop/flixcave/venv/lib/python3.10/site-packages/django/db/backends/utils.py", line 84, in _execute
    with self.db.wrap_database_errors:
  File "/Users/owner/Desktop/flixcave/venv/lib/python3.10/site-packages/django/db/utils.py", line 91, in __exit__
    raise dj_exc_value.with_traceback(traceback) from exc_value
  File "/Users/owner/Desktop/flixcave/venv/lib/python3.10/site-packages/django/db/backends/utils.py", line 89, in _execute
    return self.cursor.execute(sql, params)
django.db.utils.ProgrammingError: relation "verification_token_verificationtoken" does not exist
LINE 1: INSERT INTO "verification_token_verificationtoken" ("created...
                    ^

ERROR 2022-07-23 21:58:38,785 187 basehttp.py basehttp 36422 123145565327360 "POST /api/v1/auth/register/ HTTP/1.1" 500 169984
ERROR 2022-07-23 22:04:44,306 241 log.py log 36654 123145432305664 Internal Server Error: /api/v1/auth/register/
Traceback (most recent call last):
  File "/Users/owner/Desktop/flixcave/venv/lib/python3.10/site-packages/django/core/handlers/exception.py", line 55, in inner
    response = get_response(request)
  File "/Users/owner/Desktop/flixcave/venv/lib/python3.10/site-packages/django/core/handlers/base.py", line 197, in _get_response
    response = wrapped_callback(request, *callback_args, **callback_kwargs)
  File "/Users/owner/Desktop/flixcave/venv/lib/python3.10/site-packages/django/views/decorators/csrf.py", line 54, in wrapped_view
    return view_func(*args, **kwargs)
  File "/Users/owner/Desktop/flixcave/venv/lib/python3.10/site-packages/django/views/generic/base.py", line 84, in view
    return self.dispatch(request, *args, **kwargs)
  File "/Users/owner/Desktop/flixcave/venv/lib/python3.10/site-packages/rest_framework/views.py", line 509, in dispatch
    response = self.handle_exception(exc)
  File "/Users/owner/Desktop/flixcave/venv/lib/python3.10/site-packages/rest_framework/views.py", line 469, in handle_exception
    self.raise_uncaught_exception(exc)
  File "/Users/owner/Desktop/flixcave/venv/lib/python3.10/site-packages/rest_framework/views.py", line 480, in raise_uncaught_exception
    raise exc
  File "/Users/owner/Desktop/flixcave/venv/lib/python3.10/site-packages/rest_framework/views.py", line 506, in dispatch
    response = handler(request, *args, **kwargs)
  File "/Users/owner/Desktop/flixcave/authentication/views.py", line 29, in post
    CustomUser.verfication_email(token=token, user=user)
AttributeError: type object 'CustomUser' has no attribute 'verfication_email'
ERROR 2022-07-23 22:04:44,307 187 basehttp.py basehttp 36654 123145432305664 "POST /api/v1/auth/register/ HTTP/1.1" 500 93384
ERROR 2022-07-23 22:55:30,927 241 log.py log 37882 123145341218816 Internal Server Error: /api/v1/auth/verify/
Traceback (most recent call last):
  File "/Users/owner/Desktop/flixcave/venv/lib/python3.10/site-packages/django/core/handlers/exception.py", line 55, in inner
    response = get_response(request)
  File "/Users/owner/Desktop/flixcave/venv/lib/python3.10/site-packages/django/core/handlers/base.py", line 197, in _get_response
    response = wrapped_callback(request, *callback_args, **callback_kwargs)
  File "/Users/owner/Desktop/flixcave/venv/lib/python3.10/site-packages/django/views/decorators/csrf.py", line 54, in wrapped_view
    return view_func(*args, **kwargs)
  File "/Users/owner/Desktop/flixcave/venv/lib/python3.10/site-packages/django/views/generic/base.py", line 84, in view
    return self.dispatch(request, *args, **kwargs)
  File "/Users/owner/Desktop/flixcave/venv/lib/python3.10/site-packages/rest_framework/views.py", line 509, in dispatch
    response = self.handle_exception(exc)
  File "/Users/owner/Desktop/flixcave/venv/lib/python3.10/site-packages/rest_framework/views.py", line 469, in handle_exception
    self.raise_uncaught_exception(exc)
  File "/Users/owner/Desktop/flixcave/venv/lib/python3.10/site-packages/rest_framework/views.py", line 480, in raise_uncaught_exception
    raise exc
  File "/Users/owner/Desktop/flixcave/venv/lib/python3.10/site-packages/rest_framework/views.py", line 506, in dispatch
    response = handler(request, *args, **kwargs)
  File "/Users/owner/Desktop/flixcave/authentication/views.py", line 27, in post
    CustomUser.objects.verify_account(serializer.validated_data)
  File "/Users/owner/Desktop/flixcave/account/models.py", line 28, in verify_account
    print(decoded_token['uid'])
KeyError: 'uid'
ERROR 2022-07-23 22:55:30,930 187 basehttp.py basehttp 37882 123145341218816 "POST /api/v1/auth/verify/ HTTP/1.1" 500 95854
ERROR 2022-07-23 22:56:34,616 241 log.py log 37911 123145383260160 Internal Server Error: /api/v1/auth/verify/
Traceback (most recent call last):
  File "/Users/owner/Desktop/flixcave/venv/lib/python3.10/site-packages/jwt/api_jws.py", line 220, in _load
    signing_input, crypto_segment = jwt.rsplit(b".", 1)
ValueError: not enough values to unpack (expected 2, got 1)

The above exception was the direct cause of the following exception:

Traceback (most recent call last):
  File "/Users/owner/Desktop/flixcave/venv/lib/python3.10/site-packages/rest_framework_simplejwt/backends.py", line 105, in decode
    return jwt.decode(
  File "/Users/owner/Desktop/flixcave/venv/lib/python3.10/site-packages/jwt/api_jwt.py", line 129, in decode
    decoded = self.decode_complete(jwt, key, algorithms, options, **kwargs)
  File "/Users/owner/Desktop/flixcave/venv/lib/python3.10/site-packages/jwt/api_jwt.py", line 100, in decode_complete
    decoded = api_jws.decode_complete(
  File "/Users/owner/Desktop/flixcave/venv/lib/python3.10/site-packages/jwt/api_jws.py", line 171, in decode_complete
    payload, signing_input, header, signature = self._load(jwt)
  File "/Users/owner/Desktop/flixcave/venv/lib/python3.10/site-packages/jwt/api_jws.py", line 223, in _load
    raise DecodeError("Not enough segments") from err
jwt.exceptions.DecodeError: Not enough segments

During handling of the above exception, another exception occurred:

Traceback (most recent call last):
  File "/Users/owner/Desktop/flixcave/venv/lib/python3.10/site-packages/django/core/handlers/exception.py", line 55, in inner
    response = get_response(request)
  File "/Users/owner/Desktop/flixcave/venv/lib/python3.10/site-packages/django/core/handlers/base.py", line 197, in _get_response
    response = wrapped_callback(request, *callback_args, **callback_kwargs)
  File "/Users/owner/Desktop/flixcave/venv/lib/python3.10/site-packages/django/views/decorators/csrf.py", line 54, in wrapped_view
    return view_func(*args, **kwargs)
  File "/Users/owner/Desktop/flixcave/venv/lib/python3.10/site-packages/django/views/generic/base.py", line 84, in view
    return self.dispatch(request, *args, **kwargs)
  File "/Users/owner/Desktop/flixcave/venv/lib/python3.10/site-packages/rest_framework/views.py", line 509, in dispatch
    response = self.handle_exception(exc)
  File "/Users/owner/Desktop/flixcave/venv/lib/python3.10/site-packages/rest_framework/views.py", line 469, in handle_exception
    self.raise_uncaught_exception(exc)
  File "/Users/owner/Desktop/flixcave/venv/lib/python3.10/site-packages/rest_framework/views.py", line 480, in raise_uncaught_exception
    raise exc
  File "/Users/owner/Desktop/flixcave/venv/lib/python3.10/site-packages/rest_framework/views.py", line 506, in dispatch
    response = handler(request, *args, **kwargs)
  File "/Users/owner/Desktop/flixcave/authentication/views.py", line 27, in post
    CustomUser.objects.verify_account(serializer.validated_data)
  File "/Users/owner/Desktop/flixcave/account/models.py", line 24, in verify_account
    decoded_token = TokenBackend(
  File "/Users/owner/Desktop/flixcave/venv/lib/python3.10/site-packages/rest_framework_simplejwt/backends.py", line 120, in decode
    raise TokenBackendError(_("Token is invalid or expired"))
rest_framework_simplejwt.exceptions.TokenBackendError: Token is invalid or expired
ERROR 2022-07-23 22:56:34,619 187 basehttp.py basehttp 37911 123145383260160 "POST /api/v1/auth/verify/ HTTP/1.1" 500 125106
ERROR 2022-07-23 22:58:51,827 30 models.py models 37955 123145443766272 Invalid or malformed token.
ERROR 2022-07-23 23:02:51,082 30 models.py models 38062 123145600970752 Invalid or malformed token.
ERROR 2022-07-24 15:28:18,102 241 log.py log 41132 123145560567808 Internal Server Error: /api/v1/auth/login/
Traceback (most recent call last):
  File "/Users/owner/Desktop/flixcave/authentication/views.py", line 73, in post
    raise ObjectDoesNotExist(result)
django.core.exceptions.ObjectDoesNotExist: {'type': 'error', 'msg': 'A user with this email does not exist.', 'status': 404}

During handling of the above exception, another exception occurred:

Traceback (most recent call last):
  File "/Users/owner/Desktop/flixcave/venv/lib/python3.10/site-packages/django/core/handlers/exception.py", line 55, in inner
    response = get_response(request)
  File "/Users/owner/Desktop/flixcave/venv/lib/python3.10/site-packages/django/core/handlers/base.py", line 197, in _get_response
    response = wrapped_callback(request, *callback_args, **callback_kwargs)
  File "/Users/owner/Desktop/flixcave/venv/lib/python3.10/site-packages/django/views/decorators/csrf.py", line 54, in wrapped_view
    return view_func(*args, **kwargs)
  File "/Users/owner/Desktop/flixcave/venv/lib/python3.10/site-packages/django/views/generic/base.py", line 84, in view
    return self.dispatch(request, *args, **kwargs)
  File "/Users/owner/Desktop/flixcave/venv/lib/python3.10/site-packages/rest_framework/views.py", line 509, in dispatch
    response = self.handle_exception(exc)
  File "/Users/owner/Desktop/flixcave/venv/lib/python3.10/site-packages/rest_framework/views.py", line 469, in handle_exception
    self.raise_uncaught_exception(exc)
  File "/Users/owner/Desktop/flixcave/venv/lib/python3.10/site-packages/rest_framework/views.py", line 480, in raise_uncaught_exception
    raise exc
  File "/Users/owner/Desktop/flixcave/venv/lib/python3.10/site-packages/rest_framework/views.py", line 506, in dispatch
    response = handler(request, *args, **kwargs)
  File "/Users/owner/Desktop/flixcave/authentication/views.py", line 79, in post
    print(e['type'])
TypeError: 'ObjectDoesNotExist' object is not subscriptable
ERROR 2022-07-24 15:28:18,161 187 basehttp.py basehttp 41132 123145560567808 "POST /api/v1/auth/login/ HTTP/1.1" 500 96229
ERROR 2022-07-24 15:30:53,816 241 log.py log 41218 123145406980096 Internal Server Error: /api/v1/auth/login/
Traceback (most recent call last):
  File "/Users/owner/Desktop/flixcave/venv/lib/python3.10/site-packages/django/core/handlers/exception.py", line 55, in inner
    response = get_response(request)
  File "/Users/owner/Desktop/flixcave/venv/lib/python3.10/site-packages/django/core/handlers/base.py", line 220, in _get_response
    response = response.render()
  File "/Users/owner/Desktop/flixcave/venv/lib/python3.10/site-packages/django/template/response.py", line 114, in render
    self.content = self.rendered_content
  File "/Users/owner/Desktop/flixcave/venv/lib/python3.10/site-packages/rest_framework/response.py", line 70, in rendered_content
    ret = renderer.render(self.data, accepted_media_type, context)
  File "/Users/owner/Desktop/flixcave/venv/lib/python3.10/site-packages/rest_framework/renderers.py", line 100, in render
    ret = json.dumps(
  File "/Users/owner/Desktop/flixcave/venv/lib/python3.10/site-packages/rest_framework/utils/json.py", line 25, in dumps
    return json.dumps(*args, **kwargs)
  File "/Library/Frameworks/Python.framework/Versions/3.10/lib/python3.10/json/__init__.py", line 238, in dumps
    **kw).encode(obj)
  File "/Library/Frameworks/Python.framework/Versions/3.10/lib/python3.10/json/encoder.py", line 199, in encode
    chunks = self.iterencode(o, _one_shot=True)
  File "/Library/Frameworks/Python.framework/Versions/3.10/lib/python3.10/json/encoder.py", line 257, in iterencode
    return _iterencode(o, 0)
  File "/Users/owner/Desktop/flixcave/venv/lib/python3.10/site-packages/rest_framework/utils/encoders.py", line 67, in default
    return super().default(obj)
  File "/Library/Frameworks/Python.framework/Versions/3.10/lib/python3.10/json/encoder.py", line 179, in default
    raise TypeError(f'Object of type {o.__class__.__name__} '
TypeError: Object of type ObjectDoesNotExist is not JSON serializable
ERROR 2022-07-24 15:30:53,817 241 log.py log 41218 123145423769600 Internal Server Error: /api/v1/auth/login/
Traceback (most recent call last):
  File "/Users/owner/Desktop/flixcave/venv/lib/python3.10/site-packages/django/core/handlers/exception.py", line 55, in inner
    response = get_response(request)
  File "/Users/owner/Desktop/flixcave/venv/lib/python3.10/site-packages/django/core/handlers/base.py", line 220, in _get_response
    response = response.render()
  File "/Users/owner/Desktop/flixcave/venv/lib/python3.10/site-packages/django/template/response.py", line 114, in render
    self.content = self.rendered_content
  File "/Users/owner/Desktop/flixcave/venv/lib/python3.10/site-packages/rest_framework/response.py", line 70, in rendered_content
    ret = renderer.render(self.data, accepted_media_type, context)
  File "/Users/owner/Desktop/flixcave/venv/lib/python3.10/site-packages/rest_framework/renderers.py", line 100, in render
    ret = json.dumps(
  File "/Users/owner/Desktop/flixcave/venv/lib/python3.10/site-packages/rest_framework/utils/json.py", line 25, in dumps
    return json.dumps(*args, **kwargs)
  File "/Library/Frameworks/Python.framework/Versions/3.10/lib/python3.10/json/__init__.py", line 238, in dumps
    **kw).encode(obj)
  File "/Library/Frameworks/Python.framework/Versions/3.10/lib/python3.10/json/encoder.py", line 199, in encode
    chunks = self.iterencode(o, _one_shot=True)
  File "/Library/Frameworks/Python.framework/Versions/3.10/lib/python3.10/json/encoder.py", line 257, in iterencode
    return _iterencode(o, 0)
  File "/Users/owner/Desktop/flixcave/venv/lib/python3.10/site-packages/rest_framework/utils/encoders.py", line 67, in default
    return super().default(obj)
  File "/Library/Frameworks/Python.framework/Versions/3.10/lib/python3.10/json/encoder.py", line 179, in default
    raise TypeError(f'Object of type {o.__class__.__name__} '
TypeError: Object of type ObjectDoesNotExist is not JSON serializable
ERROR 2022-07-24 15:30:53,819 187 basehttp.py basehttp 41218 123145406980096 "POST /api/v1/auth/login/ HTTP/1.1" 500 100577
ERROR 2022-07-24 15:30:53,820 187 basehttp.py basehttp 41218 123145423769600 "POST /api/v1/auth/login/ HTTP/1.1" 500 100577
ERROR 2022-07-24 15:35:51,641 241 log.py log 41343 123145414594560 Internal Server Error: /api/v1/auth/login/
Traceback (most recent call last):
  File "/Users/owner/Desktop/flixcave/authentication/views.py", line 74, in post
    raise ObjectDoesNotExist(json.dumps(result))
django.core.exceptions.ObjectDoesNotExist: {"type": "error", "msg": "A user with this email does not exist.", "status": 404}

During handling of the above exception, another exception occurred:

Traceback (most recent call last):
  File "/Users/owner/Desktop/flixcave/venv/lib/python3.10/site-packages/django/core/handlers/exception.py", line 55, in inner
    response = get_response(request)
  File "/Users/owner/Desktop/flixcave/venv/lib/python3.10/site-packages/django/core/handlers/base.py", line 197, in _get_response
    response = wrapped_callback(request, *callback_args, **callback_kwargs)
  File "/Users/owner/Desktop/flixcave/venv/lib/python3.10/site-packages/django/views/decorators/csrf.py", line 54, in wrapped_view
    return view_func(*args, **kwargs)
  File "/Users/owner/Desktop/flixcave/venv/lib/python3.10/site-packages/django/views/generic/base.py", line 84, in view
    return self.dispatch(request, *args, **kwargs)
  File "/Users/owner/Desktop/flixcave/venv/lib/python3.10/site-packages/rest_framework/views.py", line 509, in dispatch
    response = self.handle_exception(exc)
  File "/Users/owner/Desktop/flixcave/venv/lib/python3.10/site-packages/rest_framework/views.py", line 469, in handle_exception
    self.raise_uncaught_exception(exc)
  File "/Users/owner/Desktop/flixcave/venv/lib/python3.10/site-packages/rest_framework/views.py", line 480, in raise_uncaught_exception
    raise exc
  File "/Users/owner/Desktop/flixcave/venv/lib/python3.10/site-packages/rest_framework/views.py", line 506, in dispatch
    response = handler(request, *args, **kwargs)
  File "/Users/owner/Desktop/flixcave/authentication/views.py", line 80, in post
    print(json.loads(e))
  File "/Library/Frameworks/Python.framework/Versions/3.10/lib/python3.10/json/__init__.py", line 339, in loads
    raise TypeError(f'the JSON object must be str, bytes or bytearray, '
TypeError: the JSON object must be str, bytes or bytearray, not ObjectDoesNotExist
ERROR 2022-07-24 15:35:51,656 187 basehttp.py basehttp 41343 123145414594560 "POST /api/v1/auth/login/ HTTP/1.1" 500 101280
ERROR 2022-07-24 15:35:52,408 241 log.py log 41343 123145414594560 Internal Server Error: /api/v1/auth/login/
Traceback (most recent call last):
  File "/Users/owner/Desktop/flixcave/authentication/views.py", line 74, in post
    raise ObjectDoesNotExist(json.dumps(result))
django.core.exceptions.ObjectDoesNotExist: {"type": "error", "msg": "A user with this email does not exist.", "status": 404}

During handling of the above exception, another exception occurred:

Traceback (most recent call last):
  File "/Users/owner/Desktop/flixcave/venv/lib/python3.10/site-packages/django/core/handlers/exception.py", line 55, in inner
    response = get_response(request)
  File "/Users/owner/Desktop/flixcave/venv/lib/python3.10/site-packages/django/core/handlers/base.py", line 197, in _get_response
    response = wrapped_callback(request, *callback_args, **callback_kwargs)
  File "/Users/owner/Desktop/flixcave/venv/lib/python3.10/site-packages/django/views/decorators/csrf.py", line 54, in wrapped_view
    return view_func(*args, **kwargs)
  File "/Users/owner/Desktop/flixcave/venv/lib/python3.10/site-packages/django/views/generic/base.py", line 84, in view
    return self.dispatch(request, *args, **kwargs)
  File "/Users/owner/Desktop/flixcave/venv/lib/python3.10/site-packages/rest_framework/views.py", line 509, in dispatch
    response = self.handle_exception(exc)
  File "/Users/owner/Desktop/flixcave/venv/lib/python3.10/site-packages/rest_framework/views.py", line 469, in handle_exception
    self.raise_uncaught_exception(exc)
  File "/Users/owner/Desktop/flixcave/venv/lib/python3.10/site-packages/rest_framework/views.py", line 480, in raise_uncaught_exception
    raise exc
  File "/Users/owner/Desktop/flixcave/venv/lib/python3.10/site-packages/rest_framework/views.py", line 506, in dispatch
    response = handler(request, *args, **kwargs)
  File "/Users/owner/Desktop/flixcave/authentication/views.py", line 80, in post
    print(json.loads(e))
  File "/Library/Frameworks/Python.framework/Versions/3.10/lib/python3.10/json/__init__.py", line 339, in loads
    raise TypeError(f'the JSON object must be str, bytes or bytearray, '
TypeError: the JSON object must be str, bytes or bytearray, not ObjectDoesNotExist
ERROR 2022-07-24 15:35:52,409 187 basehttp.py basehttp 41343 123145414594560 "POST /api/v1/auth/login/ HTTP/1.1" 500 101280
ERROR 2022-07-24 15:36:50,377 241 log.py log 41357 123145590616064 Internal Server Error: /api/v1/auth/login/
Traceback (most recent call last):
  File "/Users/owner/Desktop/flixcave/authentication/views.py", line 74, in post
    raise Exception(json.dumps(result))
Exception: {"type": "error", "msg": "A user with this email does not exist.", "status": 404}

During handling of the above exception, another exception occurred:

Traceback (most recent call last):
  File "/Users/owner/Desktop/flixcave/venv/lib/python3.10/site-packages/django/core/handlers/exception.py", line 55, in inner
    response = get_response(request)
  File "/Users/owner/Desktop/flixcave/venv/lib/python3.10/site-packages/django/core/handlers/base.py", line 197, in _get_response
    response = wrapped_callback(request, *callback_args, **callback_kwargs)
  File "/Users/owner/Desktop/flixcave/venv/lib/python3.10/site-packages/django/views/decorators/csrf.py", line 54, in wrapped_view
    return view_func(*args, **kwargs)
  File "/Users/owner/Desktop/flixcave/venv/lib/python3.10/site-packages/django/views/generic/base.py", line 84, in view
    return self.dispatch(request, *args, **kwargs)
  File "/Users/owner/Desktop/flixcave/venv/lib/python3.10/site-packages/rest_framework/views.py", line 509, in dispatch
    response = self.handle_exception(exc)
  File "/Users/owner/Desktop/flixcave/venv/lib/python3.10/site-packages/rest_framework/views.py", line 469, in handle_exception
    self.raise_uncaught_exception(exc)
  File "/Users/owner/Desktop/flixcave/venv/lib/python3.10/site-packages/rest_framework/views.py", line 480, in raise_uncaught_exception
    raise exc
  File "/Users/owner/Desktop/flixcave/venv/lib/python3.10/site-packages/rest_framework/views.py", line 506, in dispatch
    response = handler(request, *args, **kwargs)
  File "/Users/owner/Desktop/flixcave/authentication/views.py", line 80, in post
    print(json.loads(e))
  File "/Library/Frameworks/Python.framework/Versions/3.10/lib/python3.10/json/__init__.py", line 339, in loads
    raise TypeError(f'the JSON object must be str, bytes or bytearray, '
TypeError: the JSON object must be str, bytes or bytearray, not Exception
ERROR 2022-07-24 15:36:50,380 187 basehttp.py basehttp 41357 123145590616064 "POST /api/v1/auth/login/ HTTP/1.1" 500 101160
ERROR 2022-07-24 16:45:23,362 241 log.py log 42854 123145561505792 Internal Server Error: /api/v1/auth/resend-verify
Traceback (most recent call last):
  File "/Users/owner/Desktop/flixcave/venv/lib/python3.10/site-packages/django/core/handlers/exception.py", line 55, in inner
    response = get_response(request)
  File "/Users/owner/Desktop/flixcave/venv/lib/python3.10/site-packages/django/utils/deprecation.py", line 133, in __call__
    response = self.process_request(request)
  File "/Users/owner/Desktop/flixcave/venv/lib/python3.10/site-packages/django/middleware/common.py", line 54, in process_request
    path = self.get_full_path_with_slash(request)
  File "/Users/owner/Desktop/flixcave/venv/lib/python3.10/site-packages/django/middleware/common.py", line 88, in get_full_path_with_slash
    raise RuntimeError(
RuntimeError: You called this URL via POST, but the URL doesn't end in a slash and you have APPEND_SLASH set. Django can't redirect to the slash URL while maintaining POST data. Change your form to point to localhost:8000/api/v1/auth/resend-verify/ (note the trailing slash), or set APPEND_SLASH=False in your Django settings.
ERROR 2022-07-24 16:45:23,468 187 basehttp.py basehttp 42854 123145561505792 "POST /api/v1/auth/resend-verify HTTP/1.1" 500 70642
ERROR 2022-07-24 16:45:23,718 241 log.py log 42854 123145561505792 Internal Server Error: /api/v1/auth/resend-verify
Traceback (most recent call last):
  File "/Users/owner/Desktop/flixcave/venv/lib/python3.10/site-packages/django/core/handlers/exception.py", line 55, in inner
    response = get_response(request)
  File "/Users/owner/Desktop/flixcave/venv/lib/python3.10/site-packages/django/utils/deprecation.py", line 133, in __call__
    response = self.process_request(request)
  File "/Users/owner/Desktop/flixcave/venv/lib/python3.10/site-packages/django/middleware/common.py", line 54, in process_request
    path = self.get_full_path_with_slash(request)
  File "/Users/owner/Desktop/flixcave/venv/lib/python3.10/site-packages/django/middleware/common.py", line 88, in get_full_path_with_slash
    raise RuntimeError(
RuntimeError: You called this URL via POST, but the URL doesn't end in a slash and you have APPEND_SLASH set. Django can't redirect to the slash URL while maintaining POST data. Change your form to point to localhost:8000/api/v1/auth/resend-verify/ (note the trailing slash), or set APPEND_SLASH=False in your Django settings.
ERROR 2022-07-24 16:45:23,720 187 basehttp.py basehttp 42854 123145561505792 "POST /api/v1/auth/resend-verify HTTP/1.1" 500 70642
ERROR 2022-07-24 16:45:25,482 241 log.py log 42854 123145561505792 Internal Server Error: /api/v1/auth/resend-verify
Traceback (most recent call last):
  File "/Users/owner/Desktop/flixcave/venv/lib/python3.10/site-packages/django/core/handlers/exception.py", line 55, in inner
    response = get_response(request)
  File "/Users/owner/Desktop/flixcave/venv/lib/python3.10/site-packages/django/utils/deprecation.py", line 133, in __call__
    response = self.process_request(request)
  File "/Users/owner/Desktop/flixcave/venv/lib/python3.10/site-packages/django/middleware/common.py", line 54, in process_request
    path = self.get_full_path_with_slash(request)
  File "/Users/owner/Desktop/flixcave/venv/lib/python3.10/site-packages/django/middleware/common.py", line 88, in get_full_path_with_slash
    raise RuntimeError(
RuntimeError: You called this URL via POST, but the URL doesn't end in a slash and you have APPEND_SLASH set. Django can't redirect to the slash URL while maintaining POST data. Change your form to point to localhost:8000/api/v1/auth/resend-verify/ (note the trailing slash), or set APPEND_SLASH=False in your Django settings.
ERROR 2022-07-24 16:45:25,483 187 basehttp.py basehttp 42854 123145561505792 "POST /api/v1/auth/resend-verify HTTP/1.1" 500 70642
ERROR 2022-07-24 16:45:44,563 241 log.py log 42854 123145561505792 Internal Server Error: /api/v1/auth/resend-verify
Traceback (most recent call last):
  File "/Users/owner/Desktop/flixcave/venv/lib/python3.10/site-packages/django/core/handlers/exception.py", line 55, in inner
    response = get_response(request)
  File "/Users/owner/Desktop/flixcave/venv/lib/python3.10/site-packages/django/utils/deprecation.py", line 133, in __call__
    response = self.process_request(request)
  File "/Users/owner/Desktop/flixcave/venv/lib/python3.10/site-packages/django/middleware/common.py", line 54, in process_request
    path = self.get_full_path_with_slash(request)
  File "/Users/owner/Desktop/flixcave/venv/lib/python3.10/site-packages/django/middleware/common.py", line 88, in get_full_path_with_slash
    raise RuntimeError(
RuntimeError: You called this URL via POST, but the URL doesn't end in a slash and you have APPEND_SLASH set. Django can't redirect to the slash URL while maintaining POST data. Change your form to point to localhost:8000/api/v1/auth/resend-verify/ (note the trailing slash), or set APPEND_SLASH=False in your Django settings.
ERROR 2022-07-24 16:45:44,564 187 basehttp.py basehttp 42854 123145561505792 "POST /api/v1/auth/resend-verify HTTP/1.1" 500 70642
ERROR 2022-07-24 16:45:47,162 241 log.py log 42854 123145561505792 Internal Server Error: /api/v1/auth/resend-verify
Traceback (most recent call last):
  File "/Users/owner/Desktop/flixcave/venv/lib/python3.10/site-packages/django/core/handlers/exception.py", line 55, in inner
    response = get_response(request)
  File "/Users/owner/Desktop/flixcave/venv/lib/python3.10/site-packages/django/utils/deprecation.py", line 133, in __call__
    response = self.process_request(request)
  File "/Users/owner/Desktop/flixcave/venv/lib/python3.10/site-packages/django/middleware/common.py", line 54, in process_request
    path = self.get_full_path_with_slash(request)
  File "/Users/owner/Desktop/flixcave/venv/lib/python3.10/site-packages/django/middleware/common.py", line 88, in get_full_path_with_slash
    raise RuntimeError(
RuntimeError: You called this URL via POST, but the URL doesn't end in a slash and you have APPEND_SLASH set. Django can't redirect to the slash URL while maintaining POST data. Change your form to point to localhost:8000/api/v1/auth/resend-verify/ (note the trailing slash), or set APPEND_SLASH=False in your Django settings.
ERROR 2022-07-24 16:45:47,163 187 basehttp.py basehttp 42854 123145561505792 "POST /api/v1/auth/resend-verify HTTP/1.1" 500 70642
ERROR 2022-07-24 16:46:14,325 241 log.py log 42854 123145561505792 Internal Server Error: /api/v1/auth/resend-verify
Traceback (most recent call last):
  File "/Users/owner/Desktop/flixcave/venv/lib/python3.10/site-packages/django/core/handlers/exception.py", line 55, in inner
    response = get_response(request)
  File "/Users/owner/Desktop/flixcave/venv/lib/python3.10/site-packages/django/utils/deprecation.py", line 133, in __call__
    response = self.process_request(request)
  File "/Users/owner/Desktop/flixcave/venv/lib/python3.10/site-packages/django/middleware/common.py", line 54, in process_request
    path = self.get_full_path_with_slash(request)
  File "/Users/owner/Desktop/flixcave/venv/lib/python3.10/site-packages/django/middleware/common.py", line 88, in get_full_path_with_slash
    raise RuntimeError(
RuntimeError: You called this URL via POST, but the URL doesn't end in a slash and you have APPEND_SLASH set. Django can't redirect to the slash URL while maintaining POST data. Change your form to point to localhost:8000/api/v1/auth/resend-verify/ (note the trailing slash), or set APPEND_SLASH=False in your Django settings.
ERROR 2022-07-24 16:46:14,325 187 basehttp.py basehttp 42854 123145561505792 "POST /api/v1/auth/resend-verify HTTP/1.1" 500 70642
ERROR 2022-07-24 16:48:47,665 241 log.py log 42949 123145437798400 Internal Server Error: /api/v1/auth/resend-verify/
Traceback (most recent call last):
  File "/Users/owner/Desktop/flixcave/venv/lib/python3.10/site-packages/django/core/handlers/exception.py", line 55, in inner
    response = get_response(request)
  File "/Users/owner/Desktop/flixcave/venv/lib/python3.10/site-packages/django/core/handlers/base.py", line 197, in _get_response
    response = wrapped_callback(request, *callback_args, **callback_kwargs)
  File "/Users/owner/Desktop/flixcave/venv/lib/python3.10/site-packages/django/views/decorators/csrf.py", line 54, in wrapped_view
    return view_func(*args, **kwargs)
  File "/Users/owner/Desktop/flixcave/venv/lib/python3.10/site-packages/django/views/generic/base.py", line 84, in view
    return self.dispatch(request, *args, **kwargs)
  File "/Users/owner/Desktop/flixcave/venv/lib/python3.10/site-packages/rest_framework/views.py", line 509, in dispatch
    response = self.handle_exception(exc)
  File "/Users/owner/Desktop/flixcave/venv/lib/python3.10/site-packages/rest_framework/views.py", line 469, in handle_exception
    self.raise_uncaught_exception(exc)
  File "/Users/owner/Desktop/flixcave/venv/lib/python3.10/site-packages/rest_framework/views.py", line 480, in raise_uncaught_exception
    raise exc
  File "/Users/owner/Desktop/flixcave/venv/lib/python3.10/site-packages/rest_framework/views.py", line 506, in dispatch
    response = handler(request, *args, **kwargs)
  File "/Users/owner/Desktop/flixcave/authentication/views.py", line 25, in post
    user = CustomUser.objects.all().filter(email=request.data.email).first()
AttributeError: 'dict' object has no attribute 'email'
ERROR 2022-07-24 16:48:47,667 187 basehttp.py basehttp 42949 123145437798400 "POST /api/v1/auth/resend-verify/ HTTP/1.1" 500 91148
ERROR 2022-07-24 17:09:28,465 241 log.py log 43354 123145558929408 Internal Server Error: /api/v1/auth/verify/
Traceback (most recent call last):
  File "/Users/owner/Desktop/flixcave/venv/lib/python3.10/site-packages/django/core/handlers/exception.py", line 55, in inner
    response = get_response(request)
  File "/Users/owner/Desktop/flixcave/venv/lib/python3.10/site-packages/django/core/handlers/base.py", line 197, in _get_response
    response = wrapped_callback(request, *callback_args, **callback_kwargs)
  File "/Users/owner/Desktop/flixcave/venv/lib/python3.10/site-packages/django/views/decorators/csrf.py", line 54, in wrapped_view
    return view_func(*args, **kwargs)
  File "/Users/owner/Desktop/flixcave/venv/lib/python3.10/site-packages/django/views/generic/base.py", line 84, in view
    return self.dispatch(request, *args, **kwargs)
  File "/Users/owner/Desktop/flixcave/venv/lib/python3.10/site-packages/rest_framework/views.py", line 509, in dispatch
    response = self.handle_exception(exc)
  File "/Users/owner/Desktop/flixcave/venv/lib/python3.10/site-packages/rest_framework/views.py", line 469, in handle_exception
    self.raise_uncaught_exception(exc)
  File "/Users/owner/Desktop/flixcave/venv/lib/python3.10/site-packages/rest_framework/views.py", line 480, in raise_uncaught_exception
    raise exc
  File "/Users/owner/Desktop/flixcave/venv/lib/python3.10/site-packages/rest_framework/views.py", line 506, in dispatch
    response = handler(request, *args, **kwargs)
  File "/Users/owner/Desktop/flixcave/authentication/views.py", line 50, in post
    CustomUser.objects.verify_account(serializer.validated_data)
  File "/Users/owner/Desktop/flixcave/account/models.py", line 32, in verify_account
    user = CustomUser.objects.get(pk=decoded_token['user_id'])
  File "/Users/owner/Desktop/flixcave/venv/lib/python3.10/site-packages/django/db/models/manager.py", line 85, in manager_method
    return getattr(self.get_queryset(), name)(*args, **kwargs)
  File "/Users/owner/Desktop/flixcave/venv/lib/python3.10/site-packages/django/db/models/query.py", line 496, in get
    raise self.model.DoesNotExist(
account.models.CustomUser.DoesNotExist: CustomUser matching query does not exist.
ERROR 2022-07-24 17:09:28,466 187 basehttp.py basehttp 43354 123145558929408 "POST /api/v1/auth/verify/ HTTP/1.1" 500 104695
ERROR 2022-07-24 17:32:05,991 241 log.py log 43761 123145491111936 Internal Server Error: /api/v1/auth/login/
Traceback (most recent call last):
  File "/Users/owner/Desktop/flixcave/venv/lib/python3.10/site-packages/rest_framework/fields.py", line 457, in get_attribute
    return get_attribute(instance, self.source_attrs)
  File "/Users/owner/Desktop/flixcave/venv/lib/python3.10/site-packages/rest_framework/fields.py", line 97, in get_attribute
    instance = getattr(instance, attr)
AttributeError: 'CustomUser' object has no attribute 'initials'

During handling of the above exception, another exception occurred:

Traceback (most recent call last):
  File "/Users/owner/Desktop/flixcave/venv/lib/python3.10/site-packages/django/core/handlers/exception.py", line 55, in inner
    response = get_response(request)
  File "/Users/owner/Desktop/flixcave/venv/lib/python3.10/site-packages/django/core/handlers/base.py", line 197, in _get_response
    response = wrapped_callback(request, *callback_args, **callback_kwargs)
  File "/Users/owner/Desktop/flixcave/venv/lib/python3.10/site-packages/django/views/decorators/csrf.py", line 54, in wrapped_view
    return view_func(*args, **kwargs)
  File "/Users/owner/Desktop/flixcave/venv/lib/python3.10/site-packages/django/views/generic/base.py", line 84, in view
    return self.dispatch(request, *args, **kwargs)
  File "/Users/owner/Desktop/flixcave/venv/lib/python3.10/site-packages/rest_framework/views.py", line 509, in dispatch
    response = self.handle_exception(exc)
  File "/Users/owner/Desktop/flixcave/venv/lib/python3.10/site-packages/rest_framework/views.py", line 469, in handle_exception
    self.raise_uncaught_exception(exc)
  File "/Users/owner/Desktop/flixcave/venv/lib/python3.10/site-packages/rest_framework/views.py", line 480, in raise_uncaught_exception
    raise exc
  File "/Users/owner/Desktop/flixcave/venv/lib/python3.10/site-packages/rest_framework/views.py", line 506, in dispatch
    response = handler(request, *args, **kwargs)
  File "/Users/owner/Desktop/flixcave/authentication/views.py", line 114, in post
    'user': user_serializer.data,
  File "/Users/owner/Desktop/flixcave/venv/lib/python3.10/site-packages/rest_framework/serializers.py", line 555, in data
    ret = super().data
  File "/Users/owner/Desktop/flixcave/venv/lib/python3.10/site-packages/rest_framework/serializers.py", line 253, in data
    self._data = self.to_representation(self.instance)
  File "/Users/owner/Desktop/flixcave/venv/lib/python3.10/site-packages/rest_framework/serializers.py", line 509, in to_representation
    attribute = field.get_attribute(instance)
  File "/Users/owner/Desktop/flixcave/venv/lib/python3.10/site-packages/rest_framework/fields.py", line 490, in get_attribute
    raise type(exc)(msg)
AttributeError: Got AttributeError when attempting to get a value for field `initials` on serializer `UserSerializer`.
The serializer field might be named incorrectly and not match any attribute or key on the `CustomUser` instance.
Original exception text was: 'CustomUser' object has no attribute 'initials'.
ERROR 2022-07-24 17:32:05,995 187 basehttp.py basehttp 43761 123145491111936 "POST /api/v1/auth/login/ HTTP/1.1" 500 121059
ERROR 2022-07-24 17:34:26,446 241 log.py log 43831 123145419075584 Internal Server Error: /api/v1/auth/login/
Traceback (most recent call last):
  File "/Users/owner/Desktop/flixcave/venv/lib/python3.10/site-packages/django/core/handlers/exception.py", line 55, in inner
    response = get_response(request)
  File "/Users/owner/Desktop/flixcave/venv/lib/python3.10/site-packages/django/core/handlers/base.py", line 197, in _get_response
    response = wrapped_callback(request, *callback_args, **callback_kwargs)
  File "/Users/owner/Desktop/flixcave/venv/lib/python3.10/site-packages/django/views/decorators/csrf.py", line 54, in wrapped_view
    return view_func(*args, **kwargs)
  File "/Users/owner/Desktop/flixcave/venv/lib/python3.10/site-packages/django/views/generic/base.py", line 84, in view
    return self.dispatch(request, *args, **kwargs)
  File "/Users/owner/Desktop/flixcave/venv/lib/python3.10/site-packages/rest_framework/views.py", line 509, in dispatch
    response = self.handle_exception(exc)
  File "/Users/owner/Desktop/flixcave/venv/lib/python3.10/site-packages/rest_framework/views.py", line 469, in handle_exception
    self.raise_uncaught_exception(exc)
  File "/Users/owner/Desktop/flixcave/venv/lib/python3.10/site-packages/rest_framework/views.py", line 480, in raise_uncaught_exception
    raise exc
  File "/Users/owner/Desktop/flixcave/venv/lib/python3.10/site-packages/rest_framework/views.py", line 506, in dispatch
    response = handler(request, *args, **kwargs)
  File "/Users/owner/Desktop/flixcave/authentication/views.py", line 114, in post
    'user': user_serializer.data,
  File "/Users/owner/Desktop/flixcave/venv/lib/python3.10/site-packages/rest_framework/serializers.py", line 555, in data
    ret = super().data
  File "/Users/owner/Desktop/flixcave/venv/lib/python3.10/site-packages/rest_framework/serializers.py", line 253, in data
    self._data = self.to_representation(self.instance)
  File "/Users/owner/Desktop/flixcave/venv/lib/python3.10/site-packages/rest_framework/serializers.py", line 509, in to_representation
    attribute = field.get_attribute(instance)
  File "/Users/owner/Desktop/flixcave/venv/lib/python3.10/site-packages/rest_framework/fields.py", line 457, in get_attribute
    return get_attribute(instance, self.source_attrs)
  File "/Users/owner/Desktop/flixcave/venv/lib/python3.10/site-packages/rest_framework/fields.py", line 97, in get_attribute
    instance = getattr(instance, attr)
  File "/Users/owner/Desktop/flixcave/account/models.py", line 145, in initials
    print(self.first_name.split('')[0:1])
ValueError: empty separator
ERROR 2022-07-24 17:34:26,450 187 basehttp.py basehttp 43831 123145419075584 "POST /api/v1/auth/login/ HTTP/1.1" 500 116457
ERROR 2022-07-25 17:21:08,311 241 log.py log 53554 123145402318848 Internal Server Error: /api/v1/auth/logout/
Traceback (most recent call last):
  File "/Users/owner/Desktop/flixcave/venv/lib/python3.10/site-packages/django/core/handlers/exception.py", line 55, in inner
    response = get_response(request)
  File "/Users/owner/Desktop/flixcave/venv/lib/python3.10/site-packages/django/core/handlers/base.py", line 197, in _get_response
    response = wrapped_callback(request, *callback_args, **callback_kwargs)
  File "/Users/owner/Desktop/flixcave/venv/lib/python3.10/site-packages/django/views/decorators/csrf.py", line 54, in wrapped_view
    return view_func(*args, **kwargs)
  File "/Users/owner/Desktop/flixcave/venv/lib/python3.10/site-packages/django/views/generic/base.py", line 84, in view
    return self.dispatch(request, *args, **kwargs)
  File "/Users/owner/Desktop/flixcave/venv/lib/python3.10/site-packages/rest_framework/views.py", line 509, in dispatch
    response = self.handle_exception(exc)
  File "/Users/owner/Desktop/flixcave/venv/lib/python3.10/site-packages/rest_framework/views.py", line 469, in handle_exception
    self.raise_uncaught_exception(exc)
  File "/Users/owner/Desktop/flixcave/venv/lib/python3.10/site-packages/rest_framework/views.py", line 480, in raise_uncaught_exception
    raise exc
  File "/Users/owner/Desktop/flixcave/venv/lib/python3.10/site-packages/rest_framework/views.py", line 506, in dispatch
    response = handler(request, *args, **kwargs)
  File "/Users/owner/Desktop/flixcave/authentication/views.py", line 24, in post
    serializer.is_valid(raise_exception=True)
  File "/Users/owner/Desktop/flixcave/venv/lib/python3.10/site-packages/rest_framework/serializers.py", line 227, in is_valid
    self._validated_data = self.run_validation(self.initial_data)
  File "/Users/owner/Desktop/flixcave/venv/lib/python3.10/site-packages/rest_framework/serializers.py", line 426, in run_validation
    value = self.to_internal_value(data)
  File "/Users/owner/Desktop/flixcave/venv/lib/python3.10/site-packages/rest_framework/serializers.py", line 479, in to_internal_value
    for field in fields:
  File "/Users/owner/Desktop/flixcave/venv/lib/python3.10/site-packages/rest_framework/serializers.py", line 362, in _writable_fields
    for field in self.fields.values():
  File "/Users/owner/Desktop/flixcave/venv/lib/python3.10/site-packages/django/utils/functional.py", line 49, in __get__
    res = instance.__dict__[self.name] = self.func(instance)
  File "/Users/owner/Desktop/flixcave/venv/lib/python3.10/site-packages/rest_framework/serializers.py", line 356, in fields
    for key, value in self.get_fields().items():
  File "/Users/owner/Desktop/flixcave/venv/lib/python3.10/site-packages/rest_framework/serializers.py", line 1076, in get_fields
    field_class, field_kwargs = self.build_field(
  File "/Users/owner/Desktop/flixcave/venv/lib/python3.10/site-packages/rest_framework/serializers.py", line 1222, in build_field
    return self.build_unknown_field(field_name, model_class)
  File "/Users/owner/Desktop/flixcave/venv/lib/python3.10/site-packages/rest_framework/serializers.py", line 1340, in build_unknown_field
    raise ImproperlyConfigured(
django.core.exceptions.ImproperlyConfigured: Field name `user` is not valid for model `CustomUser`.
ERROR 2022-07-25 17:21:08,332 187 basehttp.py basehttp 53554 123145402318848 "POST /api/v1/auth/logout/ HTTP/1.1" 500 139356
ERROR 2022-07-25 17:26:56,484 33 models.py models 53689 123145408925696 Trouble blacklisting token from logging out.
ERROR 2022-07-25 17:33:38,276 34 models.py models 53703 123145557434368 Trouble blacklisting token from logging out.
ERROR 2022-07-25 17:33:40,709 34 models.py models 53703 123145557434368 Trouble blacklisting token from logging out.
ERROR 2022-07-25 17:33:48,250 34 models.py models 53703 123145557434368 Trouble blacklisting token from logging out.
ERROR 2022-07-25 17:33:48,675 34 models.py models 53703 123145557434368 Trouble blacklisting token from logging out.
ERROR 2022-07-25 17:33:48,894 34 models.py models 53703 123145557434368 Trouble blacklisting token from logging out.
ERROR 2022-07-25 17:33:49,075 34 models.py models 53703 123145557434368 Trouble blacklisting token from logging out.
ERROR 2022-07-25 17:33:49,240 34 models.py models 53703 123145557434368 Trouble blacklisting token from logging out.
ERROR 2022-07-25 17:33:49,442 34 models.py models 53703 123145557434368 Trouble blacklisting token from logging out.
ERROR 2022-07-25 17:33:49,610 34 models.py models 53703 123145557434368 Trouble blacklisting token from logging out.
ERROR 2022-07-25 17:33:49,808 34 models.py models 53703 123145557434368 Trouble blacklisting token from logging out.
ERROR 2022-07-25 17:33:50,008 34 models.py models 53703 123145557434368 Trouble blacklisting token from logging out.
ERROR 2022-07-25 17:33:50,211 34 models.py models 53703 123145557434368 Trouble blacklisting token from logging out.
ERROR 2022-07-25 17:34:12,436 34 models.py models 53703 123145557434368 Trouble blacklisting token from logging out.
ERROR 2022-07-25 17:34:13,408 34 models.py models 53703 123145557434368 Trouble blacklisting token from logging out.
ERROR 2022-07-25 17:36:36,490 34 models.py models 53703 123145557434368 Trouble blacklisting token from logging out.
ERROR 2022-08-06 16:12:44,259 241 log.py log 7288 123145460826112 Internal Server Error: /api/v1/search/
Traceback (most recent call last):
  File "/Users/owner/Desktop/flixcave/venv/lib/python3.10/site-packages/django/utils/datastructures.py", line 84, in __getitem__
    list_ = super().__getitem__(key)
KeyError: 'page'

During handling of the above exception, another exception occurred:

Traceback (most recent call last):
  File "/Users/owner/Desktop/flixcave/venv/lib/python3.10/site-packages/django/core/handlers/exception.py", line 55, in inner
    response = get_response(request)
  File "/Users/owner/Desktop/flixcave/venv/lib/python3.10/site-packages/django/core/handlers/base.py", line 197, in _get_response
    response = wrapped_callback(request, *callback_args, **callback_kwargs)
  File "/Users/owner/Desktop/flixcave/venv/lib/python3.10/site-packages/django/views/decorators/csrf.py", line 54, in wrapped_view
    return view_func(*args, **kwargs)
  File "/Users/owner/Desktop/flixcave/venv/lib/python3.10/site-packages/django/views/generic/base.py", line 84, in view
    return self.dispatch(request, *args, **kwargs)
  File "/Users/owner/Desktop/flixcave/venv/lib/python3.10/site-packages/rest_framework/views.py", line 509, in dispatch
    response = self.handle_exception(exc)
  File "/Users/owner/Desktop/flixcave/venv/lib/python3.10/site-packages/rest_framework/views.py", line 469, in handle_exception
    self.raise_uncaught_exception(exc)
  File "/Users/owner/Desktop/flixcave/venv/lib/python3.10/site-packages/rest_framework/views.py", line 480, in raise_uncaught_exception
    raise exc
  File "/Users/owner/Desktop/flixcave/venv/lib/python3.10/site-packages/rest_framework/views.py", line 506, in dispatch
    response = handler(request, *args, **kwargs)
  File "/Users/owner/Desktop/flixcave/movie/views.py", line 16, in get
    page = int(request.query_params['page'])
  File "/Users/owner/Desktop/flixcave/venv/lib/python3.10/site-packages/django/utils/datastructures.py", line 86, in __getitem__
    raise MultiValueDictKeyError(key)
django.utils.datastructures.MultiValueDictKeyError: 'page'
ERROR 2022-08-06 16:12:44,302 187 basehttp.py basehttp 7288 123145460826112 "GET /api/v1/search/?q=james%20bond HTTP/1.1" 500 99745
ERROR 2022-08-06 17:54:46,067 241 log.py log 9005 123145527480320 Internal Server Error: /api/v1/search/
Traceback (most recent call last):
  File "/Users/owner/Desktop/flixcave/venv/lib/python3.10/site-packages/django/core/handlers/exception.py", line 55, in inner
    response = get_response(request)
  File "/Users/owner/Desktop/flixcave/venv/lib/python3.10/site-packages/django/core/handlers/base.py", line 197, in _get_response
    response = wrapped_callback(request, *callback_args, **callback_kwargs)
  File "/Users/owner/Desktop/flixcave/venv/lib/python3.10/site-packages/django/views/decorators/csrf.py", line 54, in wrapped_view
    return view_func(*args, **kwargs)
  File "/Users/owner/Desktop/flixcave/venv/lib/python3.10/site-packages/django/views/generic/base.py", line 84, in view
    return self.dispatch(request, *args, **kwargs)
  File "/Users/owner/Desktop/flixcave/venv/lib/python3.10/site-packages/rest_framework/views.py", line 509, in dispatch
    response = self.handle_exception(exc)
  File "/Users/owner/Desktop/flixcave/venv/lib/python3.10/site-packages/rest_framework/views.py", line 469, in handle_exception
    self.raise_uncaught_exception(exc)
  File "/Users/owner/Desktop/flixcave/venv/lib/python3.10/site-packages/rest_framework/views.py", line 480, in raise_uncaught_exception
    raise exc
  File "/Users/owner/Desktop/flixcave/venv/lib/python3.10/site-packages/rest_framework/views.py", line 506, in dispatch
    response = handler(request, *args, **kwargs)
  File "/Users/owner/Desktop/flixcave/movie/views.py", line 28, in get
    'page': results['page']
KeyError: 'page'
ERROR 2022-08-06 17:54:46,085 187 basehttp.py basehttp 9005 123145527480320 "GET /api/v1/search/?query=james%20bond&page=0 HTTP/1.1" 500 92451
ERROR 2022-08-06 18:07:41,775 21 services.py services 9329 123145359785984 Unable to fetch resources from TMDB.
ERROR 2022-08-06 18:13:08,305 241 log.py log 9329 123145359785984 Internal Server Error: /api/v1/search/
Traceback (most recent call last):
  File "/Users/owner/Desktop/flixcave/venv/lib/python3.10/site-packages/django/utils/datastructures.py", line 84, in __getitem__
    list_ = super().__getitem__(key)
KeyError: 'page'

During handling of the above exception, another exception occurred:

Traceback (most recent call last):
  File "/Users/owner/Desktop/flixcave/venv/lib/python3.10/site-packages/django/core/handlers/exception.py", line 55, in inner
    response = get_response(request)
  File "/Users/owner/Desktop/flixcave/venv/lib/python3.10/site-packages/django/core/handlers/base.py", line 197, in _get_response
    response = wrapped_callback(request, *callback_args, **callback_kwargs)
  File "/Users/owner/Desktop/flixcave/venv/lib/python3.10/site-packages/django/views/decorators/csrf.py", line 54, in wrapped_view
    return view_func(*args, **kwargs)
  File "/Users/owner/Desktop/flixcave/venv/lib/python3.10/site-packages/django/views/generic/base.py", line 84, in view
    return self.dispatch(request, *args, **kwargs)
  File "/Users/owner/Desktop/flixcave/venv/lib/python3.10/site-packages/rest_framework/views.py", line 509, in dispatch
    response = self.handle_exception(exc)
  File "/Users/owner/Desktop/flixcave/venv/lib/python3.10/site-packages/rest_framework/views.py", line 469, in handle_exception
    self.raise_uncaught_exception(exc)
  File "/Users/owner/Desktop/flixcave/venv/lib/python3.10/site-packages/rest_framework/views.py", line 480, in raise_uncaught_exception
    raise exc
  File "/Users/owner/Desktop/flixcave/venv/lib/python3.10/site-packages/rest_framework/views.py", line 506, in dispatch
    response = handler(request, *args, **kwargs)
  File "/Users/owner/Desktop/flixcave/movie/views.py", line 17, in get
    page = int(request.query_params['page'])
  File "/Users/owner/Desktop/flixcave/venv/lib/python3.10/site-packages/django/utils/datastructures.py", line 86, in __getitem__
    raise MultiValueDictKeyError(key)
django.utils.datastructures.MultiValueDictKeyError: 'page'
ERROR 2022-08-06 18:13:08,380 187 basehttp.py basehttp 9329 123145359785984 "GET /api/v1/search/?query=james%20bond HTTP/1.1" 500 99756
ERROR 2022-08-06 18:14:42,142 241 log.py log 9462 123145405001728 Internal Server Error: /api/v1/search/
Traceback (most recent call last):
  File "/Users/owner/Desktop/flixcave/venv/lib/python3.10/site-packages/django/utils/datastructures.py", line 84, in __getitem__
    list_ = super().__getitem__(key)
KeyError: 'page'

During handling of the above exception, another exception occurred:

Traceback (most recent call last):
  File "/Users/owner/Desktop/flixcave/venv/lib/python3.10/site-packages/django/core/handlers/exception.py", line 55, in inner
    response = get_response(request)
  File "/Users/owner/Desktop/flixcave/venv/lib/python3.10/site-packages/django/core/handlers/base.py", line 197, in _get_response
    response = wrapped_callback(request, *callback_args, **callback_kwargs)
  File "/Users/owner/Desktop/flixcave/venv/lib/python3.10/site-packages/django/views/decorators/csrf.py", line 54, in wrapped_view
    return view_func(*args, **kwargs)
  File "/Users/owner/Desktop/flixcave/venv/lib/python3.10/site-packages/django/views/generic/base.py", line 84, in view
    return self.dispatch(request, *args, **kwargs)
  File "/Users/owner/Desktop/flixcave/venv/lib/python3.10/site-packages/rest_framework/views.py", line 509, in dispatch
    response = self.handle_exception(exc)
  File "/Users/owner/Desktop/flixcave/venv/lib/python3.10/site-packages/rest_framework/views.py", line 469, in handle_exception
    self.raise_uncaught_exception(exc)
  File "/Users/owner/Desktop/flixcave/venv/lib/python3.10/site-packages/rest_framework/views.py", line 480, in raise_uncaught_exception
    raise exc
  File "/Users/owner/Desktop/flixcave/venv/lib/python3.10/site-packages/rest_framework/views.py", line 506, in dispatch
    response = handler(request, *args, **kwargs)
  File "/Users/owner/Desktop/flixcave/movie/views.py", line 17, in get
    page = int(request.query_params['page'])
  File "/Users/owner/Desktop/flixcave/venv/lib/python3.10/site-packages/django/utils/datastructures.py", line 86, in __getitem__
    raise MultiValueDictKeyError(key)
django.utils.datastructures.MultiValueDictKeyError: 'page'
ERROR 2022-08-06 18:14:42,251 187 basehttp.py basehttp 9462 123145405001728 "GET /api/v1/search/?query=james%20bond HTTP/1.1" 500 99756
ERROR 2022-08-06 18:15:20,312 241 log.py log 9462 123145405001728 Internal Server Error: /api/v1/search/
Traceback (most recent call last):
  File "/Users/owner/Desktop/flixcave/venv/lib/python3.10/site-packages/django/utils/datastructures.py", line 84, in __getitem__
    list_ = super().__getitem__(key)
KeyError: 'page'

During handling of the above exception, another exception occurred:

Traceback (most recent call last):
  File "/Users/owner/Desktop/flixcave/venv/lib/python3.10/site-packages/django/core/handlers/exception.py", line 55, in inner
    response = get_response(request)
  File "/Users/owner/Desktop/flixcave/venv/lib/python3.10/site-packages/django/core/handlers/base.py", line 197, in _get_response
    response = wrapped_callback(request, *callback_args, **callback_kwargs)
  File "/Users/owner/Desktop/flixcave/venv/lib/python3.10/site-packages/django/views/decorators/csrf.py", line 54, in wrapped_view
    return view_func(*args, **kwargs)
  File "/Users/owner/Desktop/flixcave/venv/lib/python3.10/site-packages/django/views/generic/base.py", line 84, in view
    return self.dispatch(request, *args, **kwargs)
  File "/Users/owner/Desktop/flixcave/venv/lib/python3.10/site-packages/rest_framework/views.py", line 509, in dispatch
    response = self.handle_exception(exc)
  File "/Users/owner/Desktop/flixcave/venv/lib/python3.10/site-packages/rest_framework/views.py", line 469, in handle_exception
    self.raise_uncaught_exception(exc)
  File "/Users/owner/Desktop/flixcave/venv/lib/python3.10/site-packages/rest_framework/views.py", line 480, in raise_uncaught_exception
    raise exc
  File "/Users/owner/Desktop/flixcave/venv/lib/python3.10/site-packages/rest_framework/views.py", line 506, in dispatch
    response = handler(request, *args, **kwargs)
  File "/Users/owner/Desktop/flixcave/movie/views.py", line 17, in get
    page = int(request.query_params['page'])
  File "/Users/owner/Desktop/flixcave/venv/lib/python3.10/site-packages/django/utils/datastructures.py", line 86, in __getitem__
    raise MultiValueDictKeyError(key)
django.utils.datastructures.MultiValueDictKeyError: 'page'
ERROR 2022-08-06 18:15:20,329 187 basehttp.py basehttp 9462 123145405001728 "GET /api/v1/search/?query=james%20bondpage=1 HTTP/1.1" 500 99846
ERROR 2022-08-07 18:18:24,649 34 models.py models 22927 123145546338304 Trouble blacklisting token from logging out.
ERROR 2022-08-07 19:00:29,907 40 services.py services 24741 123145528819712 Unable to fetch resources from TMDB.
ERROR 2022-08-07 19:00:30,606 40 services.py services 24741 123145528819712 Unable to fetch resources from TMDB.
ERROR 2022-08-07 19:00:49,851 40 services.py services 24741 123145528819712 Unable to fetch resources from TMDB.
ERROR 2022-08-07 19:58:52,436 45 services.py services 26044 123145492795392 Unable to fetch resources from TMDB.
ERROR 2022-08-07 19:58:54,018 45 services.py services 26044 123145492795392 Unable to fetch resources from TMDB.
ERROR 2022-08-07 20:05:35,816 45 services.py services 26299 123145546305536 Unable to fetch resources from TMDB.
ERROR 2022-08-07 20:08:30,471 241 log.py log 26369 123145499398144 Internal Server Error: /api/v1/search/movie/
Traceback (most recent call last):
  File "/Users/owner/Desktop/flixcave/venv/lib/python3.10/site-packages/django/core/handlers/exception.py", line 55, in inner
    response = get_response(request)
  File "/Users/owner/Desktop/flixcave/venv/lib/python3.10/site-packages/django/core/handlers/base.py", line 197, in _get_response
    response = wrapped_callback(request, *callback_args, **callback_kwargs)
  File "/Users/owner/Desktop/flixcave/venv/lib/python3.10/site-packages/django/views/decorators/csrf.py", line 54, in wrapped_view
    return view_func(*args, **kwargs)
  File "/Users/owner/Desktop/flixcave/venv/lib/python3.10/site-packages/django/views/generic/base.py", line 84, in view
    return self.dispatch(request, *args, **kwargs)
  File "/Users/owner/Desktop/flixcave/venv/lib/python3.10/site-packages/rest_framework/views.py", line 509, in dispatch
    response = self.handle_exception(exc)
  File "/Users/owner/Desktop/flixcave/venv/lib/python3.10/site-packages/rest_framework/views.py", line 469, in handle_exception
    self.raise_uncaught_exception(exc)
  File "/Users/owner/Desktop/flixcave/venv/lib/python3.10/site-packages/rest_framework/views.py", line 480, in raise_uncaught_exception
    raise exc
  File "/Users/owner/Desktop/flixcave/venv/lib/python3.10/site-packages/rest_framework/views.py", line 506, in dispatch
    response = handler(request, *args, **kwargs)
  File "/Users/owner/Desktop/flixcave/movie/views.py", line 23, in get
    page = int(request.query_params['page'])
ValueError: invalid literal for int() with base 10: 'null'
ERROR 2022-08-07 20:08:30,518 187 basehttp.py basehttp 26369 123145499398144 "GET /api/v1/search/movie/?page=null&query=james%20bond&direction=next HTTP/1.1" 500 92884
ERROR 2022-08-07 20:08:32,874 241 log.py log 26369 123145499398144 Internal Server Error: /api/v1/search/movie/
Traceback (most recent call last):
  File "/Users/owner/Desktop/flixcave/venv/lib/python3.10/site-packages/django/core/handlers/exception.py", line 55, in inner
    response = get_response(request)
  File "/Users/owner/Desktop/flixcave/venv/lib/python3.10/site-packages/django/core/handlers/base.py", line 197, in _get_response
    response = wrapped_callback(request, *callback_args, **callback_kwargs)
  File "/Users/owner/Desktop/flixcave/venv/lib/python3.10/site-packages/django/views/decorators/csrf.py", line 54, in wrapped_view
    return view_func(*args, **kwargs)
  File "/Users/owner/Desktop/flixcave/venv/lib/python3.10/site-packages/django/views/generic/base.py", line 84, in view
    return self.dispatch(request, *args, **kwargs)
  File "/Users/owner/Desktop/flixcave/venv/lib/python3.10/site-packages/rest_framework/views.py", line 509, in dispatch
    response = self.handle_exception(exc)
  File "/Users/owner/Desktop/flixcave/venv/lib/python3.10/site-packages/rest_framework/views.py", line 469, in handle_exception
    self.raise_uncaught_exception(exc)
  File "/Users/owner/Desktop/flixcave/venv/lib/python3.10/site-packages/rest_framework/views.py", line 480, in raise_uncaught_exception
    raise exc
  File "/Users/owner/Desktop/flixcave/venv/lib/python3.10/site-packages/rest_framework/views.py", line 506, in dispatch
    response = handler(request, *args, **kwargs)
  File "/Users/owner/Desktop/flixcave/movie/views.py", line 23, in get
    page = int(request.query_params['page'])
ValueError: invalid literal for int() with base 10: 'null'
ERROR 2022-08-07 20:08:32,876 187 basehttp.py basehttp 26369 123145499398144 "GET /api/v1/search/movie/?page=null&query=james%20bond&direction=next HTTP/1.1" 500 92884
ERROR 2022-08-07 20:12:44,231 241 log.py log 26369 123145499398144 Internal Server Error: /api/v1/search/movie/
Traceback (most recent call last):
  File "/Users/owner/Desktop/flixcave/venv/lib/python3.10/site-packages/django/core/handlers/exception.py", line 55, in inner
    response = get_response(request)
  File "/Users/owner/Desktop/flixcave/venv/lib/python3.10/site-packages/django/core/handlers/base.py", line 197, in _get_response
    response = wrapped_callback(request, *callback_args, **callback_kwargs)
  File "/Users/owner/Desktop/flixcave/venv/lib/python3.10/site-packages/django/views/decorators/csrf.py", line 54, in wrapped_view
    return view_func(*args, **kwargs)
  File "/Users/owner/Desktop/flixcave/venv/lib/python3.10/site-packages/django/views/generic/base.py", line 84, in view
    return self.dispatch(request, *args, **kwargs)
  File "/Users/owner/Desktop/flixcave/venv/lib/python3.10/site-packages/rest_framework/views.py", line 509, in dispatch
    response = self.handle_exception(exc)
  File "/Users/owner/Desktop/flixcave/venv/lib/python3.10/site-packages/rest_framework/views.py", line 469, in handle_exception
    self.raise_uncaught_exception(exc)
  File "/Users/owner/Desktop/flixcave/venv/lib/python3.10/site-packages/rest_framework/views.py", line 480, in raise_uncaught_exception
    raise exc
  File "/Users/owner/Desktop/flixcave/venv/lib/python3.10/site-packages/rest_framework/views.py", line 506, in dispatch
    response = handler(request, *args, **kwargs)
  File "/Users/owner/Desktop/flixcave/movie/views.py", line 23, in get
    page = int(request.query_params['page'])
ValueError: invalid literal for int() with base 10: 'null'
ERROR 2022-08-07 20:12:44,234 187 basehttp.py basehttp 26369 123145499398144 "GET /api/v1/search/movie/?page=null&query=james%20bond&direction=next HTTP/1.1" 500 92884
ERROR 2022-08-07 20:13:03,376 241 log.py log 26369 123145499398144 Internal Server Error: /api/v1/search/movie/
Traceback (most recent call last):
  File "/Users/owner/Desktop/flixcave/venv/lib/python3.10/site-packages/django/core/handlers/exception.py", line 55, in inner
    response = get_response(request)
  File "/Users/owner/Desktop/flixcave/venv/lib/python3.10/site-packages/django/core/handlers/base.py", line 197, in _get_response
    response = wrapped_callback(request, *callback_args, **callback_kwargs)
  File "/Users/owner/Desktop/flixcave/venv/lib/python3.10/site-packages/django/views/decorators/csrf.py", line 54, in wrapped_view
    return view_func(*args, **kwargs)
  File "/Users/owner/Desktop/flixcave/venv/lib/python3.10/site-packages/django/views/generic/base.py", line 84, in view
    return self.dispatch(request, *args, **kwargs)
  File "/Users/owner/Desktop/flixcave/venv/lib/python3.10/site-packages/rest_framework/views.py", line 509, in dispatch
    response = self.handle_exception(exc)
  File "/Users/owner/Desktop/flixcave/venv/lib/python3.10/site-packages/rest_framework/views.py", line 469, in handle_exception
    self.raise_uncaught_exception(exc)
  File "/Users/owner/Desktop/flixcave/venv/lib/python3.10/site-packages/rest_framework/views.py", line 480, in raise_uncaught_exception
    raise exc
  File "/Users/owner/Desktop/flixcave/venv/lib/python3.10/site-packages/rest_framework/views.py", line 506, in dispatch
    response = handler(request, *args, **kwargs)
  File "/Users/owner/Desktop/flixcave/movie/views.py", line 23, in get
    page = int(request.query_params['page'])
ValueError: invalid literal for int() with base 10: 'null'
ERROR 2022-08-07 20:13:03,378 187 basehttp.py basehttp 26369 123145499398144 "GET /api/v1/search/movie/?page=null&query=james%20bond&direction=next HTTP/1.1" 500 92884
ERROR 2022-08-07 20:14:29,207 241 log.py log 26369 123145499398144 Internal Server Error: /api/v1/search/movie/
Traceback (most recent call last):
  File "/Users/owner/Desktop/flixcave/venv/lib/python3.10/site-packages/django/core/handlers/exception.py", line 55, in inner
    response = get_response(request)
  File "/Users/owner/Desktop/flixcave/venv/lib/python3.10/site-packages/django/core/handlers/base.py", line 197, in _get_response
    response = wrapped_callback(request, *callback_args, **callback_kwargs)
  File "/Users/owner/Desktop/flixcave/venv/lib/python3.10/site-packages/django/views/decorators/csrf.py", line 54, in wrapped_view
    return view_func(*args, **kwargs)
  File "/Users/owner/Desktop/flixcave/venv/lib/python3.10/site-packages/django/views/generic/base.py", line 84, in view
    return self.dispatch(request, *args, **kwargs)
  File "/Users/owner/Desktop/flixcave/venv/lib/python3.10/site-packages/rest_framework/views.py", line 509, in dispatch
    response = self.handle_exception(exc)
  File "/Users/owner/Desktop/flixcave/venv/lib/python3.10/site-packages/rest_framework/views.py", line 469, in handle_exception
    self.raise_uncaught_exception(exc)
  File "/Users/owner/Desktop/flixcave/venv/lib/python3.10/site-packages/rest_framework/views.py", line 480, in raise_uncaught_exception
    raise exc
  File "/Users/owner/Desktop/flixcave/venv/lib/python3.10/site-packages/rest_framework/views.py", line 506, in dispatch
    response = handler(request, *args, **kwargs)
  File "/Users/owner/Desktop/flixcave/movie/views.py", line 23, in get
    page = int(request.query_params['page'])
ValueError: invalid literal for int() with base 10: 'null'
ERROR 2022-08-07 20:14:29,209 187 basehttp.py basehttp 26369 123145499398144 "GET /api/v1/search/movie/?page=null&query=james%20bond&direction=next HTTP/1.1" 500 92884
ERROR 2022-08-07 20:15:01,544 241 log.py log 26369 123145499398144 Internal Server Error: /api/v1/search/movie/
Traceback (most recent call last):
  File "/Users/owner/Desktop/flixcave/venv/lib/python3.10/site-packages/django/core/handlers/exception.py", line 55, in inner
    response = get_response(request)
  File "/Users/owner/Desktop/flixcave/venv/lib/python3.10/site-packages/django/core/handlers/base.py", line 197, in _get_response
    response = wrapped_callback(request, *callback_args, **callback_kwargs)
  File "/Users/owner/Desktop/flixcave/venv/lib/python3.10/site-packages/django/views/decorators/csrf.py", line 54, in wrapped_view
    return view_func(*args, **kwargs)
  File "/Users/owner/Desktop/flixcave/venv/lib/python3.10/site-packages/django/views/generic/base.py", line 84, in view
    return self.dispatch(request, *args, **kwargs)
  File "/Users/owner/Desktop/flixcave/venv/lib/python3.10/site-packages/rest_framework/views.py", line 509, in dispatch
    response = self.handle_exception(exc)
  File "/Users/owner/Desktop/flixcave/venv/lib/python3.10/site-packages/rest_framework/views.py", line 469, in handle_exception
    self.raise_uncaught_exception(exc)
  File "/Users/owner/Desktop/flixcave/venv/lib/python3.10/site-packages/rest_framework/views.py", line 480, in raise_uncaught_exception
    raise exc
  File "/Users/owner/Desktop/flixcave/venv/lib/python3.10/site-packages/rest_framework/views.py", line 506, in dispatch
    response = handler(request, *args, **kwargs)
  File "/Users/owner/Desktop/flixcave/movie/views.py", line 23, in get
    page = int(request.query_params['page'])
ValueError: invalid literal for int() with base 10: 'null'
ERROR 2022-08-07 20:15:01,545 187 basehttp.py basehttp 26369 123145499398144 "GET /api/v1/search/movie/?page=null&query=james%20bond&direction=next HTTP/1.1" 500 92884
ERROR 2022-08-07 20:16:34,548 241 log.py log 26369 123145499398144 Internal Server Error: /api/v1/search/movie/
Traceback (most recent call last):
  File "/Users/owner/Desktop/flixcave/venv/lib/python3.10/site-packages/django/core/handlers/exception.py", line 55, in inner
    response = get_response(request)
  File "/Users/owner/Desktop/flixcave/venv/lib/python3.10/site-packages/django/core/handlers/base.py", line 197, in _get_response
    response = wrapped_callback(request, *callback_args, **callback_kwargs)
  File "/Users/owner/Desktop/flixcave/venv/lib/python3.10/site-packages/django/views/decorators/csrf.py", line 54, in wrapped_view
    return view_func(*args, **kwargs)
  File "/Users/owner/Desktop/flixcave/venv/lib/python3.10/site-packages/django/views/generic/base.py", line 84, in view
    return self.dispatch(request, *args, **kwargs)
  File "/Users/owner/Desktop/flixcave/venv/lib/python3.10/site-packages/rest_framework/views.py", line 509, in dispatch
    response = self.handle_exception(exc)
  File "/Users/owner/Desktop/flixcave/venv/lib/python3.10/site-packages/rest_framework/views.py", line 469, in handle_exception
    self.raise_uncaught_exception(exc)
  File "/Users/owner/Desktop/flixcave/venv/lib/python3.10/site-packages/rest_framework/views.py", line 480, in raise_uncaught_exception
    raise exc
  File "/Users/owner/Desktop/flixcave/venv/lib/python3.10/site-packages/rest_framework/views.py", line 506, in dispatch
    response = handler(request, *args, **kwargs)
  File "/Users/owner/Desktop/flixcave/movie/views.py", line 23, in get
    page = int(request.query_params['page'])
ValueError: invalid literal for int() with base 10: 'null'
ERROR 2022-08-07 20:16:34,549 187 basehttp.py basehttp 26369 123145499398144 "GET /api/v1/search/movie/?page=null&query=james%20bond&direction=next HTTP/1.1" 500 92884
ERROR 2022-08-07 20:20:54,464 241 log.py log 26369 123145499398144 Internal Server Error: /api/v1/search/movie/
Traceback (most recent call last):
  File "/Users/owner/Desktop/flixcave/venv/lib/python3.10/site-packages/django/core/handlers/exception.py", line 55, in inner
    response = get_response(request)
  File "/Users/owner/Desktop/flixcave/venv/lib/python3.10/site-packages/django/core/handlers/base.py", line 197, in _get_response
    response = wrapped_callback(request, *callback_args, **callback_kwargs)
  File "/Users/owner/Desktop/flixcave/venv/lib/python3.10/site-packages/django/views/decorators/csrf.py", line 54, in wrapped_view
    return view_func(*args, **kwargs)
  File "/Users/owner/Desktop/flixcave/venv/lib/python3.10/site-packages/django/views/generic/base.py", line 84, in view
    return self.dispatch(request, *args, **kwargs)
  File "/Users/owner/Desktop/flixcave/venv/lib/python3.10/site-packages/rest_framework/views.py", line 509, in dispatch
    response = self.handle_exception(exc)
  File "/Users/owner/Desktop/flixcave/venv/lib/python3.10/site-packages/rest_framework/views.py", line 469, in handle_exception
    self.raise_uncaught_exception(exc)
  File "/Users/owner/Desktop/flixcave/venv/lib/python3.10/site-packages/rest_framework/views.py", line 480, in raise_uncaught_exception
    raise exc
  File "/Users/owner/Desktop/flixcave/venv/lib/python3.10/site-packages/rest_framework/views.py", line 506, in dispatch
    response = handler(request, *args, **kwargs)
  File "/Users/owner/Desktop/flixcave/movie/views.py", line 23, in get
    page = int(request.query_params['page'])
ValueError: invalid literal for int() with base 10: 'null'
ERROR 2022-08-07 20:20:54,529 187 basehttp.py basehttp 26369 123145499398144 "GET /api/v1/search/movie/?page=null&query=james%20bond&direction=next HTTP/1.1" 500 92884
ERROR 2022-08-07 20:24:42,379 241 log.py log 26369 123145516724224 Internal Server Error: /api/v1/search/movie/
Traceback (most recent call last):
  File "/Users/owner/Desktop/flixcave/venv/lib/python3.10/site-packages/django/core/handlers/exception.py", line 55, in inner
    response = get_response(request)
  File "/Users/owner/Desktop/flixcave/venv/lib/python3.10/site-packages/django/core/handlers/base.py", line 197, in _get_response
    response = wrapped_callback(request, *callback_args, **callback_kwargs)
  File "/Users/owner/Desktop/flixcave/venv/lib/python3.10/site-packages/django/views/decorators/csrf.py", line 54, in wrapped_view
    return view_func(*args, **kwargs)
  File "/Users/owner/Desktop/flixcave/venv/lib/python3.10/site-packages/django/views/generic/base.py", line 84, in view
    return self.dispatch(request, *args, **kwargs)
  File "/Users/owner/Desktop/flixcave/venv/lib/python3.10/site-packages/rest_framework/views.py", line 509, in dispatch
    response = self.handle_exception(exc)
  File "/Users/owner/Desktop/flixcave/venv/lib/python3.10/site-packages/rest_framework/views.py", line 469, in handle_exception
    self.raise_uncaught_exception(exc)
  File "/Users/owner/Desktop/flixcave/venv/lib/python3.10/site-packages/rest_framework/views.py", line 480, in raise_uncaught_exception
    raise exc
  File "/Users/owner/Desktop/flixcave/venv/lib/python3.10/site-packages/rest_framework/views.py", line 506, in dispatch
    response = handler(request, *args, **kwargs)
  File "/Users/owner/Desktop/flixcave/movie/views.py", line 23, in get
    page = int(request.query_params['page'])
ValueError: invalid literal for int() with base 10: 'null'
ERROR 2022-08-07 20:24:42,383 241 log.py log 26369 123145499398144 Internal Server Error: /api/v1/search/movie/
Traceback (most recent call last):
  File "/Users/owner/Desktop/flixcave/venv/lib/python3.10/site-packages/django/core/handlers/exception.py", line 55, in inner
    response = get_response(request)
  File "/Users/owner/Desktop/flixcave/venv/lib/python3.10/site-packages/django/core/handlers/base.py", line 197, in _get_response
    response = wrapped_callback(request, *callback_args, **callback_kwargs)
  File "/Users/owner/Desktop/flixcave/venv/lib/python3.10/site-packages/django/views/decorators/csrf.py", line 54, in wrapped_view
    return view_func(*args, **kwargs)
  File "/Users/owner/Desktop/flixcave/venv/lib/python3.10/site-packages/django/views/generic/base.py", line 84, in view
    return self.dispatch(request, *args, **kwargs)
  File "/Users/owner/Desktop/flixcave/venv/lib/python3.10/site-packages/rest_framework/views.py", line 509, in dispatch
    response = self.handle_exception(exc)
  File "/Users/owner/Desktop/flixcave/venv/lib/python3.10/site-packages/rest_framework/views.py", line 469, in handle_exception
    self.raise_uncaught_exception(exc)
  File "/Users/owner/Desktop/flixcave/venv/lib/python3.10/site-packages/rest_framework/views.py", line 480, in raise_uncaught_exception
    raise exc
  File "/Users/owner/Desktop/flixcave/venv/lib/python3.10/site-packages/rest_framework/views.py", line 506, in dispatch
    response = handler(request, *args, **kwargs)
  File "/Users/owner/Desktop/flixcave/movie/views.py", line 23, in get
    page = int(request.query_params['page'])
ValueError: invalid literal for int() with base 10: 'null'
ERROR 2022-08-07 20:24:42,538 187 basehttp.py basehttp 26369 123145516724224 "GET /api/v1/search/movie/?page=null&query=james%20bond&direction=next HTTP/1.1" 500 92884
ERROR 2022-08-07 20:24:42,538 187 basehttp.py basehttp 26369 123145499398144 "GET /api/v1/search/movie/?page=null&query=james%20bond&direction=prev HTTP/1.1" 500 92884
ERROR 2022-08-07 20:24:43,427 241 log.py log 26369 123145499398144 Internal Server Error: /api/v1/search/movie/
Traceback (most recent call last):
  File "/Users/owner/Desktop/flixcave/venv/lib/python3.10/site-packages/django/core/handlers/exception.py", line 55, in inner
    response = get_response(request)
  File "/Users/owner/Desktop/flixcave/venv/lib/python3.10/site-packages/django/core/handlers/base.py", line 197, in _get_response
    response = wrapped_callback(request, *callback_args, **callback_kwargs)
  File "/Users/owner/Desktop/flixcave/venv/lib/python3.10/site-packages/django/views/decorators/csrf.py", line 54, in wrapped_view
    return view_func(*args, **kwargs)
  File "/Users/owner/Desktop/flixcave/venv/lib/python3.10/site-packages/django/views/generic/base.py", line 84, in view
    return self.dispatch(request, *args, **kwargs)
  File "/Users/owner/Desktop/flixcave/venv/lib/python3.10/site-packages/rest_framework/views.py", line 509, in dispatch
    response = self.handle_exception(exc)
  File "/Users/owner/Desktop/flixcave/venv/lib/python3.10/site-packages/rest_framework/views.py", line 469, in handle_exception
    self.raise_uncaught_exception(exc)
  File "/Users/owner/Desktop/flixcave/venv/lib/python3.10/site-packages/rest_framework/views.py", line 480, in raise_uncaught_exception
    raise exc
  File "/Users/owner/Desktop/flixcave/venv/lib/python3.10/site-packages/rest_framework/views.py", line 506, in dispatch
    response = handler(request, *args, **kwargs)
  File "/Users/owner/Desktop/flixcave/movie/views.py", line 23, in get
    page = int(request.query_params['page'])
ValueError: invalid literal for int() with base 10: 'null'
ERROR 2022-08-07 20:24:43,428 187 basehttp.py basehttp 26369 123145499398144 "GET /api/v1/search/movie/?page=null&query=james%20bond&direction=next HTTP/1.1" 500 92884
ERROR 2022-08-07 20:24:44,346 241 log.py log 26369 123145499398144 Internal Server Error: /api/v1/search/movie/
Traceback (most recent call last):
  File "/Users/owner/Desktop/flixcave/venv/lib/python3.10/site-packages/django/core/handlers/exception.py", line 55, in inner
    response = get_response(request)
  File "/Users/owner/Desktop/flixcave/venv/lib/python3.10/site-packages/django/core/handlers/base.py", line 197, in _get_response
    response = wrapped_callback(request, *callback_args, **callback_kwargs)
  File "/Users/owner/Desktop/flixcave/venv/lib/python3.10/site-packages/django/views/decorators/csrf.py", line 54, in wrapped_view
    return view_func(*args, **kwargs)
  File "/Users/owner/Desktop/flixcave/venv/lib/python3.10/site-packages/django/views/generic/base.py", line 84, in view
    return self.dispatch(request, *args, **kwargs)
  File "/Users/owner/Desktop/flixcave/venv/lib/python3.10/site-packages/rest_framework/views.py", line 509, in dispatch
    response = self.handle_exception(exc)
  File "/Users/owner/Desktop/flixcave/venv/lib/python3.10/site-packages/rest_framework/views.py", line 469, in handle_exception
    self.raise_uncaught_exception(exc)
  File "/Users/owner/Desktop/flixcave/venv/lib/python3.10/site-packages/rest_framework/views.py", line 480, in raise_uncaught_exception
    raise exc
  File "/Users/owner/Desktop/flixcave/venv/lib/python3.10/site-packages/rest_framework/views.py", line 506, in dispatch
    response = handler(request, *args, **kwargs)
  File "/Users/owner/Desktop/flixcave/movie/views.py", line 23, in get
    page = int(request.query_params['page'])
ValueError: invalid literal for int() with base 10: 'null'
ERROR 2022-08-07 20:24:44,346 187 basehttp.py basehttp 26369 123145499398144 "GET /api/v1/search/movie/?page=null&query=james%20bond&direction=next HTTP/1.1" 500 92884
ERROR 2022-08-07 20:24:45,246 241 log.py log 26369 123145499398144 Internal Server Error: /api/v1/search/movie/
Traceback (most recent call last):
  File "/Users/owner/Desktop/flixcave/venv/lib/python3.10/site-packages/django/core/handlers/exception.py", line 55, in inner
    response = get_response(request)
  File "/Users/owner/Desktop/flixcave/venv/lib/python3.10/site-packages/django/core/handlers/base.py", line 197, in _get_response
    response = wrapped_callback(request, *callback_args, **callback_kwargs)
  File "/Users/owner/Desktop/flixcave/venv/lib/python3.10/site-packages/django/views/decorators/csrf.py", line 54, in wrapped_view
    return view_func(*args, **kwargs)
  File "/Users/owner/Desktop/flixcave/venv/lib/python3.10/site-packages/django/views/generic/base.py", line 84, in view
    return self.dispatch(request, *args, **kwargs)
  File "/Users/owner/Desktop/flixcave/venv/lib/python3.10/site-packages/rest_framework/views.py", line 509, in dispatch
    response = self.handle_exception(exc)
  File "/Users/owner/Desktop/flixcave/venv/lib/python3.10/site-packages/rest_framework/views.py", line 469, in handle_exception
    self.raise_uncaught_exception(exc)
  File "/Users/owner/Desktop/flixcave/venv/lib/python3.10/site-packages/rest_framework/views.py", line 480, in raise_uncaught_exception
    raise exc
  File "/Users/owner/Desktop/flixcave/venv/lib/python3.10/site-packages/rest_framework/views.py", line 506, in dispatch
    response = handler(request, *args, **kwargs)
  File "/Users/owner/Desktop/flixcave/movie/views.py", line 23, in get
    page = int(request.query_params['page'])
ValueError: invalid literal for int() with base 10: 'null'
ERROR 2022-08-07 20:24:45,247 187 basehttp.py basehttp 26369 123145499398144 "GET /api/v1/search/movie/?page=null&query=james%20bond&direction=prev HTTP/1.1" 500 92884
ERROR 2022-08-07 20:24:45,854 241 log.py log 26369 123145499398144 Internal Server Error: /api/v1/search/movie/
Traceback (most recent call last):
  File "/Users/owner/Desktop/flixcave/venv/lib/python3.10/site-packages/django/core/handlers/exception.py", line 55, in inner
    response = get_response(request)
  File "/Users/owner/Desktop/flixcave/venv/lib/python3.10/site-packages/django/core/handlers/base.py", line 197, in _get_response
    response = wrapped_callback(request, *callback_args, **callback_kwargs)
  File "/Users/owner/Desktop/flixcave/venv/lib/python3.10/site-packages/django/views/decorators/csrf.py", line 54, in wrapped_view
    return view_func(*args, **kwargs)
  File "/Users/owner/Desktop/flixcave/venv/lib/python3.10/site-packages/django/views/generic/base.py", line 84, in view
    return self.dispatch(request, *args, **kwargs)
  File "/Users/owner/Desktop/flixcave/venv/lib/python3.10/site-packages/rest_framework/views.py", line 509, in dispatch
    response = self.handle_exception(exc)
  File "/Users/owner/Desktop/flixcave/venv/lib/python3.10/site-packages/rest_framework/views.py", line 469, in handle_exception
    self.raise_uncaught_exception(exc)
  File "/Users/owner/Desktop/flixcave/venv/lib/python3.10/site-packages/rest_framework/views.py", line 480, in raise_uncaught_exception
    raise exc
  File "/Users/owner/Desktop/flixcave/venv/lib/python3.10/site-packages/rest_framework/views.py", line 506, in dispatch
    response = handler(request, *args, **kwargs)
  File "/Users/owner/Desktop/flixcave/movie/views.py", line 23, in get
    page = int(request.query_params['page'])
ValueError: invalid literal for int() with base 10: 'null'
ERROR 2022-08-07 20:24:45,855 187 basehttp.py basehttp 26369 123145499398144 "GET /api/v1/search/movie/?page=null&query=james%20bond&direction=next HTTP/1.1" 500 92884
ERROR 2022-08-07 20:24:46,528 241 log.py log 26369 123145499398144 Internal Server Error: /api/v1/search/movie/
Traceback (most recent call last):
  File "/Users/owner/Desktop/flixcave/venv/lib/python3.10/site-packages/django/core/handlers/exception.py", line 55, in inner
    response = get_response(request)
  File "/Users/owner/Desktop/flixcave/venv/lib/python3.10/site-packages/django/core/handlers/base.py", line 197, in _get_response
    response = wrapped_callback(request, *callback_args, **callback_kwargs)
  File "/Users/owner/Desktop/flixcave/venv/lib/python3.10/site-packages/django/views/decorators/csrf.py", line 54, in wrapped_view
    return view_func(*args, **kwargs)
  File "/Users/owner/Desktop/flixcave/venv/lib/python3.10/site-packages/django/views/generic/base.py", line 84, in view
    return self.dispatch(request, *args, **kwargs)
  File "/Users/owner/Desktop/flixcave/venv/lib/python3.10/site-packages/rest_framework/views.py", line 509, in dispatch
    response = self.handle_exception(exc)
  File "/Users/owner/Desktop/flixcave/venv/lib/python3.10/site-packages/rest_framework/views.py", line 469, in handle_exception
    self.raise_uncaught_exception(exc)
  File "/Users/owner/Desktop/flixcave/venv/lib/python3.10/site-packages/rest_framework/views.py", line 480, in raise_uncaught_exception
    raise exc
  File "/Users/owner/Desktop/flixcave/venv/lib/python3.10/site-packages/rest_framework/views.py", line 506, in dispatch
    response = handler(request, *args, **kwargs)
  File "/Users/owner/Desktop/flixcave/movie/views.py", line 23, in get
    page = int(request.query_params['page'])
ValueError: invalid literal for int() with base 10: 'null'
ERROR 2022-08-07 20:24:46,529 187 basehttp.py basehttp 26369 123145499398144 "GET /api/v1/search/movie/?page=null&query=james%20bond&direction=prev HTTP/1.1" 500 92884
ERROR 2022-08-07 20:24:46,786 241 log.py log 26369 123145499398144 Internal Server Error: /api/v1/search/movie/
Traceback (most recent call last):
  File "/Users/owner/Desktop/flixcave/venv/lib/python3.10/site-packages/django/core/handlers/exception.py", line 55, in inner
    response = get_response(request)
  File "/Users/owner/Desktop/flixcave/venv/lib/python3.10/site-packages/django/core/handlers/base.py", line 197, in _get_response
    response = wrapped_callback(request, *callback_args, **callback_kwargs)
  File "/Users/owner/Desktop/flixcave/venv/lib/python3.10/site-packages/django/views/decorators/csrf.py", line 54, in wrapped_view
    return view_func(*args, **kwargs)
  File "/Users/owner/Desktop/flixcave/venv/lib/python3.10/site-packages/django/views/generic/base.py", line 84, in view
    return self.dispatch(request, *args, **kwargs)
  File "/Users/owner/Desktop/flixcave/venv/lib/python3.10/site-packages/rest_framework/views.py", line 509, in dispatch
    response = self.handle_exception(exc)
  File "/Users/owner/Desktop/flixcave/venv/lib/python3.10/site-packages/rest_framework/views.py", line 469, in handle_exception
    self.raise_uncaught_exception(exc)
  File "/Users/owner/Desktop/flixcave/venv/lib/python3.10/site-packages/rest_framework/views.py", line 480, in raise_uncaught_exception
    raise exc
  File "/Users/owner/Desktop/flixcave/venv/lib/python3.10/site-packages/rest_framework/views.py", line 506, in dispatch
    response = handler(request, *args, **kwargs)
  File "/Users/owner/Desktop/flixcave/movie/views.py", line 23, in get
    page = int(request.query_params['page'])
ValueError: invalid literal for int() with base 10: 'null'
ERROR 2022-08-07 20:24:46,787 187 basehttp.py basehttp 26369 123145499398144 "GET /api/v1/search/movie/?page=null&query=james%20bond&direction=prev HTTP/1.1" 500 92884
ERROR 2022-08-07 20:24:47,342 241 log.py log 26369 123145499398144 Internal Server Error: /api/v1/search/movie/
Traceback (most recent call last):
  File "/Users/owner/Desktop/flixcave/venv/lib/python3.10/site-packages/django/core/handlers/exception.py", line 55, in inner
    response = get_response(request)
  File "/Users/owner/Desktop/flixcave/venv/lib/python3.10/site-packages/django/core/handlers/base.py", line 197, in _get_response
    response = wrapped_callback(request, *callback_args, **callback_kwargs)
  File "/Users/owner/Desktop/flixcave/venv/lib/python3.10/site-packages/django/views/decorators/csrf.py", line 54, in wrapped_view
    return view_func(*args, **kwargs)
  File "/Users/owner/Desktop/flixcave/venv/lib/python3.10/site-packages/django/views/generic/base.py", line 84, in view
    return self.dispatch(request, *args, **kwargs)
  File "/Users/owner/Desktop/flixcave/venv/lib/python3.10/site-packages/rest_framework/views.py", line 509, in dispatch
    response = self.handle_exception(exc)
  File "/Users/owner/Desktop/flixcave/venv/lib/python3.10/site-packages/rest_framework/views.py", line 469, in handle_exception
    self.raise_uncaught_exception(exc)
  File "/Users/owner/Desktop/flixcave/venv/lib/python3.10/site-packages/rest_framework/views.py", line 480, in raise_uncaught_exception
    raise exc
  File "/Users/owner/Desktop/flixcave/venv/lib/python3.10/site-packages/rest_framework/views.py", line 506, in dispatch
    response = handler(request, *args, **kwargs)
  File "/Users/owner/Desktop/flixcave/movie/views.py", line 23, in get
    page = int(request.query_params['page'])
ValueError: invalid literal for int() with base 10: 'null'
ERROR 2022-08-07 20:24:47,343 187 basehttp.py basehttp 26369 123145499398144 "GET /api/v1/search/movie/?page=null&query=james%20bond&direction=next HTTP/1.1" 500 92884
ERROR 2022-08-08 11:53:15,262 241 log.py log 28264 123145500606464 Internal Server Error: /api/v1/search/movie/
Traceback (most recent call last):
  File "/Users/owner/Desktop/flixcave/venv/lib/python3.10/site-packages/django/core/handlers/exception.py", line 55, in inner
    response = get_response(request)
  File "/Users/owner/Desktop/flixcave/venv/lib/python3.10/site-packages/django/core/handlers/base.py", line 197, in _get_response
    response = wrapped_callback(request, *callback_args, **callback_kwargs)
  File "/Users/owner/Desktop/flixcave/venv/lib/python3.10/site-packages/django/views/decorators/csrf.py", line 54, in wrapped_view
    return view_func(*args, **kwargs)
  File "/Users/owner/Desktop/flixcave/venv/lib/python3.10/site-packages/django/views/generic/base.py", line 84, in view
    return self.dispatch(request, *args, **kwargs)
  File "/Users/owner/Desktop/flixcave/venv/lib/python3.10/site-packages/rest_framework/views.py", line 509, in dispatch
    response = self.handle_exception(exc)
  File "/Users/owner/Desktop/flixcave/venv/lib/python3.10/site-packages/rest_framework/views.py", line 469, in handle_exception
    self.raise_uncaught_exception(exc)
  File "/Users/owner/Desktop/flixcave/venv/lib/python3.10/site-packages/rest_framework/views.py", line 480, in raise_uncaught_exception
    raise exc
  File "/Users/owner/Desktop/flixcave/venv/lib/python3.10/site-packages/rest_framework/views.py", line 506, in dispatch
    response = handler(request, *args, **kwargs)
  File "/Users/owner/Desktop/flixcave/movie/views.py", line 23, in get
    page = int(request.query_params['page'])
ValueError: invalid literal for int() with base 10: 'null'
ERROR 2022-08-08 11:53:15,292 187 basehttp.py basehttp 28264 123145500606464 "GET /api/v1/search/movie/?page=null&query=james%20bond&direction=prev HTTP/1.1" 500 92884
ERROR 2022-08-08 11:53:15,339 241 log.py log 28264 123145500606464 Internal Server Error: /api/v1/search/movie/
Traceback (most recent call last):
  File "/Users/owner/Desktop/flixcave/venv/lib/python3.10/site-packages/django/core/handlers/exception.py", line 55, in inner
    response = get_response(request)
  File "/Users/owner/Desktop/flixcave/venv/lib/python3.10/site-packages/django/core/handlers/base.py", line 197, in _get_response
    response = wrapped_callback(request, *callback_args, **callback_kwargs)
  File "/Users/owner/Desktop/flixcave/venv/lib/python3.10/site-packages/django/views/decorators/csrf.py", line 54, in wrapped_view
    return view_func(*args, **kwargs)
  File "/Users/owner/Desktop/flixcave/venv/lib/python3.10/site-packages/django/views/generic/base.py", line 84, in view
    return self.dispatch(request, *args, **kwargs)
  File "/Users/owner/Desktop/flixcave/venv/lib/python3.10/site-packages/rest_framework/views.py", line 509, in dispatch
    response = self.handle_exception(exc)
  File "/Users/owner/Desktop/flixcave/venv/lib/python3.10/site-packages/rest_framework/views.py", line 469, in handle_exception
    self.raise_uncaught_exception(exc)
  File "/Users/owner/Desktop/flixcave/venv/lib/python3.10/site-packages/rest_framework/views.py", line 480, in raise_uncaught_exception
    raise exc
  File "/Users/owner/Desktop/flixcave/venv/lib/python3.10/site-packages/rest_framework/views.py", line 506, in dispatch
    response = handler(request, *args, **kwargs)
  File "/Users/owner/Desktop/flixcave/movie/views.py", line 23, in get
    page = int(request.query_params['page'])
ValueError: invalid literal for int() with base 10: 'null'
ERROR 2022-08-08 11:53:15,341 187 basehttp.py basehttp 28264 123145500606464 "GET /api/v1/search/movie/?page=null&query=james%20bond&direction=prev HTTP/1.1" 500 92884
ERROR 2022-08-08 11:53:16,246 241 log.py log 28264 123145500606464 Internal Server Error: /api/v1/search/movie/
Traceback (most recent call last):
  File "/Users/owner/Desktop/flixcave/venv/lib/python3.10/site-packages/django/core/handlers/exception.py", line 55, in inner
    response = get_response(request)
  File "/Users/owner/Desktop/flixcave/venv/lib/python3.10/site-packages/django/core/handlers/base.py", line 197, in _get_response
    response = wrapped_callback(request, *callback_args, **callback_kwargs)
  File "/Users/owner/Desktop/flixcave/venv/lib/python3.10/site-packages/django/views/decorators/csrf.py", line 54, in wrapped_view
    return view_func(*args, **kwargs)
  File "/Users/owner/Desktop/flixcave/venv/lib/python3.10/site-packages/django/views/generic/base.py", line 84, in view
    return self.dispatch(request, *args, **kwargs)
  File "/Users/owner/Desktop/flixcave/venv/lib/python3.10/site-packages/rest_framework/views.py", line 509, in dispatch
    response = self.handle_exception(exc)
  File "/Users/owner/Desktop/flixcave/venv/lib/python3.10/site-packages/rest_framework/views.py", line 469, in handle_exception
    self.raise_uncaught_exception(exc)
  File "/Users/owner/Desktop/flixcave/venv/lib/python3.10/site-packages/rest_framework/views.py", line 480, in raise_uncaught_exception
    raise exc
  File "/Users/owner/Desktop/flixcave/venv/lib/python3.10/site-packages/rest_framework/views.py", line 506, in dispatch
    response = handler(request, *args, **kwargs)
  File "/Users/owner/Desktop/flixcave/movie/views.py", line 23, in get
    page = int(request.query_params['page'])
ValueError: invalid literal for int() with base 10: 'null'
ERROR 2022-08-08 11:53:16,247 187 basehttp.py basehttp 28264 123145500606464 "GET /api/v1/search/movie/?page=null&query=james%20bond&direction=prev HTTP/1.1" 500 92884
ERROR 2022-08-08 11:53:16,878 241 log.py log 28264 123145500606464 Internal Server Error: /api/v1/search/movie/
Traceback (most recent call last):
  File "/Users/owner/Desktop/flixcave/venv/lib/python3.10/site-packages/django/core/handlers/exception.py", line 55, in inner
    response = get_response(request)
  File "/Users/owner/Desktop/flixcave/venv/lib/python3.10/site-packages/django/core/handlers/base.py", line 197, in _get_response
    response = wrapped_callback(request, *callback_args, **callback_kwargs)
  File "/Users/owner/Desktop/flixcave/venv/lib/python3.10/site-packages/django/views/decorators/csrf.py", line 54, in wrapped_view
    return view_func(*args, **kwargs)
  File "/Users/owner/Desktop/flixcave/venv/lib/python3.10/site-packages/django/views/generic/base.py", line 84, in view
    return self.dispatch(request, *args, **kwargs)
  File "/Users/owner/Desktop/flixcave/venv/lib/python3.10/site-packages/rest_framework/views.py", line 509, in dispatch
    response = self.handle_exception(exc)
  File "/Users/owner/Desktop/flixcave/venv/lib/python3.10/site-packages/rest_framework/views.py", line 469, in handle_exception
    self.raise_uncaught_exception(exc)
  File "/Users/owner/Desktop/flixcave/venv/lib/python3.10/site-packages/rest_framework/views.py", line 480, in raise_uncaught_exception
    raise exc
  File "/Users/owner/Desktop/flixcave/venv/lib/python3.10/site-packages/rest_framework/views.py", line 506, in dispatch
    response = handler(request, *args, **kwargs)
  File "/Users/owner/Desktop/flixcave/movie/views.py", line 23, in get
    page = int(request.query_params['page'])
ValueError: invalid literal for int() with base 10: 'null'
ERROR 2022-08-08 11:53:16,879 187 basehttp.py basehttp 28264 123145500606464 "GET /api/v1/search/movie/?page=null&query=james%20bond&direction=prev HTTP/1.1" 500 92884
ERROR 2022-08-08 11:53:19,874 241 log.py log 28264 123145500606464 Internal Server Error: /api/v1/search/movie/
Traceback (most recent call last):
  File "/Users/owner/Desktop/flixcave/venv/lib/python3.10/site-packages/django/core/handlers/exception.py", line 55, in inner
    response = get_response(request)
  File "/Users/owner/Desktop/flixcave/venv/lib/python3.10/site-packages/django/core/handlers/base.py", line 197, in _get_response
    response = wrapped_callback(request, *callback_args, **callback_kwargs)
  File "/Users/owner/Desktop/flixcave/venv/lib/python3.10/site-packages/django/views/decorators/csrf.py", line 54, in wrapped_view
    return view_func(*args, **kwargs)
  File "/Users/owner/Desktop/flixcave/venv/lib/python3.10/site-packages/django/views/generic/base.py", line 84, in view
    return self.dispatch(request, *args, **kwargs)
  File "/Users/owner/Desktop/flixcave/venv/lib/python3.10/site-packages/rest_framework/views.py", line 509, in dispatch
    response = self.handle_exception(exc)
  File "/Users/owner/Desktop/flixcave/venv/lib/python3.10/site-packages/rest_framework/views.py", line 469, in handle_exception
    self.raise_uncaught_exception(exc)
  File "/Users/owner/Desktop/flixcave/venv/lib/python3.10/site-packages/rest_framework/views.py", line 480, in raise_uncaught_exception
    raise exc
  File "/Users/owner/Desktop/flixcave/venv/lib/python3.10/site-packages/rest_framework/views.py", line 506, in dispatch
    response = handler(request, *args, **kwargs)
  File "/Users/owner/Desktop/flixcave/movie/views.py", line 23, in get
    page = int(request.query_params['page'])
ValueError: invalid literal for int() with base 10: 'null'
ERROR 2022-08-08 11:53:19,875 187 basehttp.py basehttp 28264 123145500606464 "GET /api/v1/search/movie/?page=null&query=james%20bond&direction=next HTTP/1.1" 500 92884
ERROR 2022-08-08 11:53:20,433 241 log.py log 28264 123145500606464 Internal Server Error: /api/v1/search/movie/
Traceback (most recent call last):
  File "/Users/owner/Desktop/flixcave/venv/lib/python3.10/site-packages/django/core/handlers/exception.py", line 55, in inner
    response = get_response(request)
  File "/Users/owner/Desktop/flixcave/venv/lib/python3.10/site-packages/django/core/handlers/base.py", line 197, in _get_response
    response = wrapped_callback(request, *callback_args, **callback_kwargs)
  File "/Users/owner/Desktop/flixcave/venv/lib/python3.10/site-packages/django/views/decorators/csrf.py", line 54, in wrapped_view
    return view_func(*args, **kwargs)
  File "/Users/owner/Desktop/flixcave/venv/lib/python3.10/site-packages/django/views/generic/base.py", line 84, in view
    return self.dispatch(request, *args, **kwargs)
  File "/Users/owner/Desktop/flixcave/venv/lib/python3.10/site-packages/rest_framework/views.py", line 509, in dispatch
    response = self.handle_exception(exc)
  File "/Users/owner/Desktop/flixcave/venv/lib/python3.10/site-packages/rest_framework/views.py", line 469, in handle_exception
    self.raise_uncaught_exception(exc)
  File "/Users/owner/Desktop/flixcave/venv/lib/python3.10/site-packages/rest_framework/views.py", line 480, in raise_uncaught_exception
    raise exc
  File "/Users/owner/Desktop/flixcave/venv/lib/python3.10/site-packages/rest_framework/views.py", line 506, in dispatch
    response = handler(request, *args, **kwargs)
  File "/Users/owner/Desktop/flixcave/movie/views.py", line 23, in get
    page = int(request.query_params['page'])
ValueError: invalid literal for int() with base 10: 'null'
ERROR 2022-08-08 11:53:20,434 187 basehttp.py basehttp 28264 123145500606464 "GET /api/v1/search/movie/?page=null&query=james%20bond&direction=next HTTP/1.1" 500 92884
ERROR 2022-08-08 11:53:20,900 241 log.py log 28264 123145500606464 Internal Server Error: /api/v1/search/movie/
Traceback (most recent call last):
  File "/Users/owner/Desktop/flixcave/venv/lib/python3.10/site-packages/django/core/handlers/exception.py", line 55, in inner
    response = get_response(request)
  File "/Users/owner/Desktop/flixcave/venv/lib/python3.10/site-packages/django/core/handlers/base.py", line 197, in _get_response
    response = wrapped_callback(request, *callback_args, **callback_kwargs)
  File "/Users/owner/Desktop/flixcave/venv/lib/python3.10/site-packages/django/views/decorators/csrf.py", line 54, in wrapped_view
    return view_func(*args, **kwargs)
  File "/Users/owner/Desktop/flixcave/venv/lib/python3.10/site-packages/django/views/generic/base.py", line 84, in view
    return self.dispatch(request, *args, **kwargs)
  File "/Users/owner/Desktop/flixcave/venv/lib/python3.10/site-packages/rest_framework/views.py", line 509, in dispatch
    response = self.handle_exception(exc)
  File "/Users/owner/Desktop/flixcave/venv/lib/python3.10/site-packages/rest_framework/views.py", line 469, in handle_exception
    self.raise_uncaught_exception(exc)
  File "/Users/owner/Desktop/flixcave/venv/lib/python3.10/site-packages/rest_framework/views.py", line 480, in raise_uncaught_exception
    raise exc
  File "/Users/owner/Desktop/flixcave/venv/lib/python3.10/site-packages/rest_framework/views.py", line 506, in dispatch
    response = handler(request, *args, **kwargs)
  File "/Users/owner/Desktop/flixcave/movie/views.py", line 23, in get
    page = int(request.query_params['page'])
ValueError: invalid literal for int() with base 10: 'null'
ERROR 2022-08-08 11:53:20,901 187 basehttp.py basehttp 28264 123145500606464 "GET /api/v1/search/movie/?page=null&query=james%20bond&direction=next HTTP/1.1" 500 92884
ERROR 2022-08-08 11:53:21,100 241 log.py log 28264 123145500606464 Internal Server Error: /api/v1/search/movie/
Traceback (most recent call last):
  File "/Users/owner/Desktop/flixcave/venv/lib/python3.10/site-packages/django/core/handlers/exception.py", line 55, in inner
    response = get_response(request)
  File "/Users/owner/Desktop/flixcave/venv/lib/python3.10/site-packages/django/core/handlers/base.py", line 197, in _get_response
    response = wrapped_callback(request, *callback_args, **callback_kwargs)
  File "/Users/owner/Desktop/flixcave/venv/lib/python3.10/site-packages/django/views/decorators/csrf.py", line 54, in wrapped_view
    return view_func(*args, **kwargs)
  File "/Users/owner/Desktop/flixcave/venv/lib/python3.10/site-packages/django/views/generic/base.py", line 84, in view
    return self.dispatch(request, *args, **kwargs)
  File "/Users/owner/Desktop/flixcave/venv/lib/python3.10/site-packages/rest_framework/views.py", line 509, in dispatch
    response = self.handle_exception(exc)
  File "/Users/owner/Desktop/flixcave/venv/lib/python3.10/site-packages/rest_framework/views.py", line 469, in handle_exception
    self.raise_uncaught_exception(exc)
  File "/Users/owner/Desktop/flixcave/venv/lib/python3.10/site-packages/rest_framework/views.py", line 480, in raise_uncaught_exception
    raise exc
  File "/Users/owner/Desktop/flixcave/venv/lib/python3.10/site-packages/rest_framework/views.py", line 506, in dispatch
    response = handler(request, *args, **kwargs)
  File "/Users/owner/Desktop/flixcave/movie/views.py", line 23, in get
    page = int(request.query_params['page'])
ValueError: invalid literal for int() with base 10: 'null'
ERROR 2022-08-08 11:53:21,101 187 basehttp.py basehttp 28264 123145500606464 "GET /api/v1/search/movie/?page=null&query=james%20bond&direction=next HTTP/1.1" 500 92884
ERROR 2022-08-08 11:53:21,323 241 log.py log 28264 123145500606464 Internal Server Error: /api/v1/search/movie/
Traceback (most recent call last):
  File "/Users/owner/Desktop/flixcave/venv/lib/python3.10/site-packages/django/core/handlers/exception.py", line 55, in inner
    response = get_response(request)
  File "/Users/owner/Desktop/flixcave/venv/lib/python3.10/site-packages/django/core/handlers/base.py", line 197, in _get_response
    response = wrapped_callback(request, *callback_args, **callback_kwargs)
  File "/Users/owner/Desktop/flixcave/venv/lib/python3.10/site-packages/django/views/decorators/csrf.py", line 54, in wrapped_view
    return view_func(*args, **kwargs)
  File "/Users/owner/Desktop/flixcave/venv/lib/python3.10/site-packages/django/views/generic/base.py", line 84, in view
    return self.dispatch(request, *args, **kwargs)
  File "/Users/owner/Desktop/flixcave/venv/lib/python3.10/site-packages/rest_framework/views.py", line 509, in dispatch
    response = self.handle_exception(exc)
  File "/Users/owner/Desktop/flixcave/venv/lib/python3.10/site-packages/rest_framework/views.py", line 469, in handle_exception
    self.raise_uncaught_exception(exc)
  File "/Users/owner/Desktop/flixcave/venv/lib/python3.10/site-packages/rest_framework/views.py", line 480, in raise_uncaught_exception
    raise exc
  File "/Users/owner/Desktop/flixcave/venv/lib/python3.10/site-packages/rest_framework/views.py", line 506, in dispatch
    response = handler(request, *args, **kwargs)
  File "/Users/owner/Desktop/flixcave/movie/views.py", line 23, in get
    page = int(request.query_params['page'])
ValueError: invalid literal for int() with base 10: 'null'
ERROR 2022-08-08 11:53:21,324 187 basehttp.py basehttp 28264 123145500606464 "GET /api/v1/search/movie/?page=null&query=james%20bond&direction=next HTTP/1.1" 500 92884
ERROR 2022-08-08 11:53:21,468 241 log.py log 28264 123145500606464 Internal Server Error: /api/v1/search/movie/
Traceback (most recent call last):
  File "/Users/owner/Desktop/flixcave/venv/lib/python3.10/site-packages/django/core/handlers/exception.py", line 55, in inner
    response = get_response(request)
  File "/Users/owner/Desktop/flixcave/venv/lib/python3.10/site-packages/django/core/handlers/base.py", line 197, in _get_response
    response = wrapped_callback(request, *callback_args, **callback_kwargs)
  File "/Users/owner/Desktop/flixcave/venv/lib/python3.10/site-packages/django/views/decorators/csrf.py", line 54, in wrapped_view
    return view_func(*args, **kwargs)
  File "/Users/owner/Desktop/flixcave/venv/lib/python3.10/site-packages/django/views/generic/base.py", line 84, in view
    return self.dispatch(request, *args, **kwargs)
  File "/Users/owner/Desktop/flixcave/venv/lib/python3.10/site-packages/rest_framework/views.py", line 509, in dispatch
    response = self.handle_exception(exc)
  File "/Users/owner/Desktop/flixcave/venv/lib/python3.10/site-packages/rest_framework/views.py", line 469, in handle_exception
    self.raise_uncaught_exception(exc)
  File "/Users/owner/Desktop/flixcave/venv/lib/python3.10/site-packages/rest_framework/views.py", line 480, in raise_uncaught_exception
    raise exc
  File "/Users/owner/Desktop/flixcave/venv/lib/python3.10/site-packages/rest_framework/views.py", line 506, in dispatch
    response = handler(request, *args, **kwargs)
  File "/Users/owner/Desktop/flixcave/movie/views.py", line 23, in get
    page = int(request.query_params['page'])
ValueError: invalid literal for int() with base 10: 'null'
ERROR 2022-08-08 11:53:21,469 187 basehttp.py basehttp 28264 123145500606464 "GET /api/v1/search/movie/?page=null&query=james%20bond&direction=next HTTP/1.1" 500 92884
ERROR 2022-08-08 11:53:21,634 241 log.py log 28264 123145500606464 Internal Server Error: /api/v1/search/movie/
Traceback (most recent call last):
  File "/Users/owner/Desktop/flixcave/venv/lib/python3.10/site-packages/django/core/handlers/exception.py", line 55, in inner
    response = get_response(request)
  File "/Users/owner/Desktop/flixcave/venv/lib/python3.10/site-packages/django/core/handlers/base.py", line 197, in _get_response
    response = wrapped_callback(request, *callback_args, **callback_kwargs)
  File "/Users/owner/Desktop/flixcave/venv/lib/python3.10/site-packages/django/views/decorators/csrf.py", line 54, in wrapped_view
    return view_func(*args, **kwargs)
  File "/Users/owner/Desktop/flixcave/venv/lib/python3.10/site-packages/django/views/generic/base.py", line 84, in view
    return self.dispatch(request, *args, **kwargs)
  File "/Users/owner/Desktop/flixcave/venv/lib/python3.10/site-packages/rest_framework/views.py", line 509, in dispatch
    response = self.handle_exception(exc)
  File "/Users/owner/Desktop/flixcave/venv/lib/python3.10/site-packages/rest_framework/views.py", line 469, in handle_exception
    self.raise_uncaught_exception(exc)
  File "/Users/owner/Desktop/flixcave/venv/lib/python3.10/site-packages/rest_framework/views.py", line 480, in raise_uncaught_exception
    raise exc
  File "/Users/owner/Desktop/flixcave/venv/lib/python3.10/site-packages/rest_framework/views.py", line 506, in dispatch
    response = handler(request, *args, **kwargs)
  File "/Users/owner/Desktop/flixcave/movie/views.py", line 23, in get
    page = int(request.query_params['page'])
ValueError: invalid literal for int() with base 10: 'null'
ERROR 2022-08-08 11:53:21,635 187 basehttp.py basehttp 28264 123145500606464 "GET /api/v1/search/movie/?page=null&query=james%20bond&direction=next HTTP/1.1" 500 92884
ERROR 2022-08-08 11:53:21,832 241 log.py log 28264 123145500606464 Internal Server Error: /api/v1/search/movie/
Traceback (most recent call last):
  File "/Users/owner/Desktop/flixcave/venv/lib/python3.10/site-packages/django/core/handlers/exception.py", line 55, in inner
    response = get_response(request)
  File "/Users/owner/Desktop/flixcave/venv/lib/python3.10/site-packages/django/core/handlers/base.py", line 197, in _get_response
    response = wrapped_callback(request, *callback_args, **callback_kwargs)
  File "/Users/owner/Desktop/flixcave/venv/lib/python3.10/site-packages/django/views/decorators/csrf.py", line 54, in wrapped_view
    return view_func(*args, **kwargs)
  File "/Users/owner/Desktop/flixcave/venv/lib/python3.10/site-packages/django/views/generic/base.py", line 84, in view
    return self.dispatch(request, *args, **kwargs)
  File "/Users/owner/Desktop/flixcave/venv/lib/python3.10/site-packages/rest_framework/views.py", line 509, in dispatch
    response = self.handle_exception(exc)
  File "/Users/owner/Desktop/flixcave/venv/lib/python3.10/site-packages/rest_framework/views.py", line 469, in handle_exception
    self.raise_uncaught_exception(exc)
  File "/Users/owner/Desktop/flixcave/venv/lib/python3.10/site-packages/rest_framework/views.py", line 480, in raise_uncaught_exception
    raise exc
  File "/Users/owner/Desktop/flixcave/venv/lib/python3.10/site-packages/rest_framework/views.py", line 506, in dispatch
    response = handler(request, *args, **kwargs)
  File "/Users/owner/Desktop/flixcave/movie/views.py", line 23, in get
    page = int(request.query_params['page'])
ValueError: invalid literal for int() with base 10: 'null'
ERROR 2022-08-08 11:53:21,833 187 basehttp.py basehttp 28264 123145500606464 "GET /api/v1/search/movie/?page=null&query=james%20bond&direction=next HTTP/1.1" 500 92884
ERROR 2022-08-09 15:08:38,555 30 services.py services 41684 123145583939584 Unable to fetch movie details from TMDB.
ERROR 2022-08-09 20:03:58,673 30 services.py services 49056 123145378193408 Unable to fetch tv details from TMDB
ERROR 2022-08-09 20:04:02,803 30 services.py services 49056 123145378193408 Unable to fetch tv details from TMDB
ERROR 2022-08-11 15:42:15,149 106 services.py services 55668 123145469427712 Unable to fetch resources with parameter from TMDB.
ERROR 2022-08-11 15:42:16,626 106 services.py services 55668 123145469427712 Unable to fetch resources with parameter from TMDB.
ERROR 2022-08-11 15:42:36,774 106 services.py services 55679 123145429139456 Unable to fetch resources with parameter from TMDB.
ERROR 2022-08-11 15:48:12,458 104 services.py services 55795 123145450975232 Unable to fetch resources with parameter from TMDB.
ERROR 2022-08-11 15:52:45,332 107 services.py services 55856 123145479856128 Unable to fetch resources with parameter from TMDB.
ERROR 2022-08-11 15:54:09,643 106 services.py services 55904 123145508675584 Unable to fetch resources with parameter from TMDB.
ERROR 2022-08-11 15:55:16,123 107 services.py services 55936 123145384759296 Unable to fetch resources with parameter from TMDB.
ERROR 2022-08-11 16:09:20,009 109 services.py services 56202 123145493139456 Unable to fetch resources with parameter from TMDB.
ERROR 2022-08-11 20:33:47,591 241 log.py log 60638 123145474846720 Internal Server Error: /api/v1/lists/
Traceback (most recent call last):
  File "/Users/owner/Desktop/flixcave/venv/lib/python3.10/site-packages/django/core/handlers/exception.py", line 55, in inner
    response = get_response(request)
  File "/Users/owner/Desktop/flixcave/venv/lib/python3.10/site-packages/django/core/handlers/base.py", line 197, in _get_response
    response = wrapped_callback(request, *callback_args, **callback_kwargs)
  File "/Users/owner/Desktop/flixcave/venv/lib/python3.10/site-packages/django/views/decorators/csrf.py", line 54, in wrapped_view
    return view_func(*args, **kwargs)
  File "/Users/owner/Desktop/flixcave/venv/lib/python3.10/site-packages/django/views/generic/base.py", line 84, in view
    return self.dispatch(request, *args, **kwargs)
  File "/Users/owner/Desktop/flixcave/venv/lib/python3.10/site-packages/rest_framework/views.py", line 509, in dispatch
    response = self.handle_exception(exc)
  File "/Users/owner/Desktop/flixcave/venv/lib/python3.10/site-packages/rest_framework/views.py", line 469, in handle_exception
    self.raise_uncaught_exception(exc)
  File "/Users/owner/Desktop/flixcave/venv/lib/python3.10/site-packages/rest_framework/views.py", line 480, in raise_uncaught_exception
    raise exc
  File "/Users/owner/Desktop/flixcave/venv/lib/python3.10/site-packages/rest_framework/views.py", line 506, in dispatch
    response = handler(request, *args, **kwargs)
  File "/Users/owner/Desktop/flixcave/list/views.py", line 15, in post
    serializer.is_valid(raise_exception=True)
  File "/Users/owner/Desktop/flixcave/venv/lib/python3.10/site-packages/rest_framework/serializers.py", line 227, in is_valid
    self._validated_data = self.run_validation(self.initial_data)
  File "/Users/owner/Desktop/flixcave/venv/lib/python3.10/site-packages/rest_framework/serializers.py", line 426, in run_validation
    value = self.to_internal_value(data)
  File "/Users/owner/Desktop/flixcave/venv/lib/python3.10/site-packages/rest_framework/serializers.py", line 479, in to_internal_value
    for field in fields:
  File "/Users/owner/Desktop/flixcave/venv/lib/python3.10/site-packages/rest_framework/serializers.py", line 362, in _writable_fields
    for field in self.fields.values():
  File "/Users/owner/Desktop/flixcave/venv/lib/python3.10/site-packages/django/utils/functional.py", line 49, in __get__
    res = instance.__dict__[self.name] = self.func(instance)
  File "/Users/owner/Desktop/flixcave/venv/lib/python3.10/site-packages/rest_framework/serializers.py", line 356, in fields
    for key, value in self.get_fields().items():
  File "/Users/owner/Desktop/flixcave/venv/lib/python3.10/site-packages/rest_framework/serializers.py", line 1076, in get_fields
    field_class, field_kwargs = self.build_field(
  File "/Users/owner/Desktop/flixcave/venv/lib/python3.10/site-packages/rest_framework/serializers.py", line 1222, in build_field
    return self.build_unknown_field(field_name, model_class)
  File "/Users/owner/Desktop/flixcave/venv/lib/python3.10/site-packages/rest_framework/serializers.py", line 1340, in build_unknown_field
    raise ImproperlyConfigured(
django.core.exceptions.ImproperlyConfigured: Field name `title` is not valid for model `List`.
ERROR 2022-08-11 20:33:47,604 187 basehttp.py basehttp 60638 123145474846720 "POST /api/v1/lists/ HTTP/1.1" 500 133318
ERROR 2022-08-11 20:34:26,901 241 log.py log 60654 123145366982656 Internal Server Error: /api/v1/lists/
Traceback (most recent call last):
  File "/Users/owner/Desktop/flixcave/venv/lib/python3.10/site-packages/django/core/handlers/exception.py", line 55, in inner
    response = get_response(request)
  File "/Users/owner/Desktop/flixcave/venv/lib/python3.10/site-packages/django/core/handlers/base.py", line 197, in _get_response
    response = wrapped_callback(request, *callback_args, **callback_kwargs)
  File "/Users/owner/Desktop/flixcave/venv/lib/python3.10/site-packages/django/views/decorators/csrf.py", line 54, in wrapped_view
    return view_func(*args, **kwargs)
  File "/Users/owner/Desktop/flixcave/venv/lib/python3.10/site-packages/django/views/generic/base.py", line 84, in view
    return self.dispatch(request, *args, **kwargs)
  File "/Users/owner/Desktop/flixcave/venv/lib/python3.10/site-packages/rest_framework/views.py", line 509, in dispatch
    response = self.handle_exception(exc)
  File "/Users/owner/Desktop/flixcave/venv/lib/python3.10/site-packages/rest_framework/views.py", line 469, in handle_exception
    self.raise_uncaught_exception(exc)
  File "/Users/owner/Desktop/flixcave/venv/lib/python3.10/site-packages/rest_framework/views.py", line 480, in raise_uncaught_exception
    raise exc
  File "/Users/owner/Desktop/flixcave/venv/lib/python3.10/site-packages/rest_framework/views.py", line 506, in dispatch
    response = handler(request, *args, **kwargs)
  File "/Users/owner/Desktop/flixcave/list/views.py", line 15, in post
    serializer.is_valid(raise_exception=True)
  File "/Users/owner/Desktop/flixcave/venv/lib/python3.10/site-packages/rest_framework/serializers.py", line 227, in is_valid
    self._validated_data = self.run_validation(self.initial_data)
  File "/Users/owner/Desktop/flixcave/venv/lib/python3.10/site-packages/rest_framework/serializers.py", line 426, in run_validation
    value = self.to_internal_value(data)
  File "/Users/owner/Desktop/flixcave/venv/lib/python3.10/site-packages/rest_framework/serializers.py", line 479, in to_internal_value
    for field in fields:
  File "/Users/owner/Desktop/flixcave/venv/lib/python3.10/site-packages/rest_framework/serializers.py", line 362, in _writable_fields
    for field in self.fields.values():
  File "/Users/owner/Desktop/flixcave/venv/lib/python3.10/site-packages/django/utils/functional.py", line 49, in __get__
    res = instance.__dict__[self.name] = self.func(instance)
  File "/Users/owner/Desktop/flixcave/venv/lib/python3.10/site-packages/rest_framework/serializers.py", line 356, in fields
    for key, value in self.get_fields().items():
  File "/Users/owner/Desktop/flixcave/venv/lib/python3.10/site-packages/rest_framework/serializers.py", line 1076, in get_fields
    field_class, field_kwargs = self.build_field(
  File "/Users/owner/Desktop/flixcave/venv/lib/python3.10/site-packages/rest_framework/serializers.py", line 1222, in build_field
    return self.build_unknown_field(field_name, model_class)
  File "/Users/owner/Desktop/flixcave/venv/lib/python3.10/site-packages/rest_framework/serializers.py", line 1340, in build_unknown_field
    raise ImproperlyConfigured(
django.core.exceptions.ImproperlyConfigured: Field name `backdrop_path` is not valid for model `List`.
ERROR 2022-08-11 20:34:26,903 187 basehttp.py basehttp 60654 123145366982656 "POST /api/v1/lists/ HTTP/1.1" 500 133881
ERROR 2022-08-11 21:53:54,668 241 log.py log 61200 123145533607936 Internal Server Error: /api/v1/lists/
Traceback (most recent call last):
  File "/Users/owner/Desktop/flixcave/venv/lib/python3.10/site-packages/django/core/handlers/exception.py", line 55, in inner
    response = get_response(request)
  File "/Users/owner/Desktop/flixcave/venv/lib/python3.10/site-packages/django/core/handlers/base.py", line 197, in _get_response
    response = wrapped_callback(request, *callback_args, **callback_kwargs)
  File "/Users/owner/Desktop/flixcave/venv/lib/python3.10/site-packages/django/views/decorators/csrf.py", line 54, in wrapped_view
    return view_func(*args, **kwargs)
  File "/Users/owner/Desktop/flixcave/venv/lib/python3.10/site-packages/django/views/generic/base.py", line 84, in view
    return self.dispatch(request, *args, **kwargs)
  File "/Users/owner/Desktop/flixcave/venv/lib/python3.10/site-packages/rest_framework/views.py", line 509, in dispatch
    response = self.handle_exception(exc)
  File "/Users/owner/Desktop/flixcave/venv/lib/python3.10/site-packages/rest_framework/views.py", line 469, in handle_exception
    self.raise_uncaught_exception(exc)
  File "/Users/owner/Desktop/flixcave/venv/lib/python3.10/site-packages/rest_framework/views.py", line 480, in raise_uncaught_exception
    raise exc
  File "/Users/owner/Desktop/flixcave/venv/lib/python3.10/site-packages/rest_framework/views.py", line 506, in dispatch
    response = handler(request, *args, **kwargs)
  File "/Users/owner/Desktop/flixcave/list/views.py", line 15, in post
    serializer.is_valid(raise_exception=True)
  File "/Users/owner/Desktop/flixcave/venv/lib/python3.10/site-packages/rest_framework/serializers.py", line 227, in is_valid
    self._validated_data = self.run_validation(self.initial_data)
  File "/Users/owner/Desktop/flixcave/venv/lib/python3.10/site-packages/rest_framework/serializers.py", line 430, in run_validation
    assert value is not None, '.validate() should return the validated data'
AssertionError: .validate() should return the validated data
ERROR 2022-08-11 21:53:54,683 187 basehttp.py basehttp 61200 123145533607936 "POST /api/v1/lists/ HTTP/1.1" 500 100697
ERROR 2022-08-12 14:11:44,370 241 log.py log 62888 123145542467584 Internal Server Error: /api/v1/lists/
Traceback (most recent call last):
  File "/Users/owner/Desktop/flixcave/venv/lib/python3.10/site-packages/django/db/models/fields/__init__.py", line 1988, in get_prep_value
    return int(value)
TypeError: int() argument must be a string, a bytes-like object or a real number, not 'CustomUser'

The above exception was the direct cause of the following exception:

Traceback (most recent call last):
  File "/Users/owner/Desktop/flixcave/venv/lib/python3.10/site-packages/django/core/handlers/exception.py", line 55, in inner
    response = get_response(request)
  File "/Users/owner/Desktop/flixcave/venv/lib/python3.10/site-packages/django/core/handlers/base.py", line 197, in _get_response
    response = wrapped_callback(request, *callback_args, **callback_kwargs)
  File "/Users/owner/Desktop/flixcave/venv/lib/python3.10/site-packages/django/views/decorators/csrf.py", line 54, in wrapped_view
    return view_func(*args, **kwargs)
  File "/Users/owner/Desktop/flixcave/venv/lib/python3.10/site-packages/django/views/generic/base.py", line 84, in view
    return self.dispatch(request, *args, **kwargs)
  File "/Users/owner/Desktop/flixcave/venv/lib/python3.10/site-packages/rest_framework/views.py", line 509, in dispatch
    response = self.handle_exception(exc)
  File "/Users/owner/Desktop/flixcave/venv/lib/python3.10/site-packages/rest_framework/views.py", line 469, in handle_exception
    self.raise_uncaught_exception(exc)
  File "/Users/owner/Desktop/flixcave/venv/lib/python3.10/site-packages/rest_framework/views.py", line 480, in raise_uncaught_exception
    raise exc
  File "/Users/owner/Desktop/flixcave/venv/lib/python3.10/site-packages/rest_framework/views.py", line 506, in dispatch
    response = handler(request, *args, **kwargs)
  File "/Users/owner/Desktop/flixcave/list/views.py", line 23, in post
    list = List.objects.create(serializer.validated_data, user)
  File "/Users/owner/Desktop/flixcave/list/models.py", line 15, in create
    list.save()
  File "/Users/owner/Desktop/flixcave/venv/lib/python3.10/site-packages/django/db/models/base.py", line 806, in save
    self.save_base(
  File "/Users/owner/Desktop/flixcave/venv/lib/python3.10/site-packages/django/db/models/base.py", line 857, in save_base
    updated = self._save_table(
  File "/Users/owner/Desktop/flixcave/venv/lib/python3.10/site-packages/django/db/models/base.py", line 1000, in _save_table
    results = self._do_insert(
  File "/Users/owner/Desktop/flixcave/venv/lib/python3.10/site-packages/django/db/models/base.py", line 1041, in _do_insert
    return manager._insert(
  File "/Users/owner/Desktop/flixcave/venv/lib/python3.10/site-packages/django/db/models/manager.py", line 85, in manager_method
    return getattr(self.get_queryset(), name)(*args, **kwargs)
  File "/Users/owner/Desktop/flixcave/venv/lib/python3.10/site-packages/django/db/models/query.py", line 1434, in _insert
    return query.get_compiler(using=using).execute_sql(returning_fields)
  File "/Users/owner/Desktop/flixcave/venv/lib/python3.10/site-packages/django/db/models/sql/compiler.py", line 1620, in execute_sql
    for sql, params in self.as_sql():
  File "/Users/owner/Desktop/flixcave/venv/lib/python3.10/site-packages/django/db/models/sql/compiler.py", line 1547, in as_sql
    value_rows = [
  File "/Users/owner/Desktop/flixcave/venv/lib/python3.10/site-packages/django/db/models/sql/compiler.py", line 1548, in <listcomp>
    [
  File "/Users/owner/Desktop/flixcave/venv/lib/python3.10/site-packages/django/db/models/sql/compiler.py", line 1549, in <listcomp>
    self.prepare_value(field, self.pre_save_val(field, obj))
  File "/Users/owner/Desktop/flixcave/venv/lib/python3.10/site-packages/django/db/models/sql/compiler.py", line 1487, in prepare_value
    value = field.get_db_prep_save(value, connection=self.connection)
  File "/Users/owner/Desktop/flixcave/venv/lib/python3.10/site-packages/django/db/models/fields/related.py", line 1126, in get_db_prep_save
    return self.target_field.get_db_prep_save(value, connection=connection)
  File "/Users/owner/Desktop/flixcave/venv/lib/python3.10/site-packages/django/db/models/fields/__init__.py", line 910, in get_db_prep_save
    return self.get_db_prep_value(value, connection=connection, prepared=False)
  File "/Users/owner/Desktop/flixcave/venv/lib/python3.10/site-packages/django/db/models/fields/__init__.py", line 2668, in get_db_prep_value
    value = self.get_prep_value(value)
  File "/Users/owner/Desktop/flixcave/venv/lib/python3.10/site-packages/django/db/models/fields/__init__.py", line 1990, in get_prep_value
    raise e.__class__(
TypeError: Field 'id' expected a number but got <CustomUser: edabitphp@aol.com>.
ERROR 2022-08-12 14:11:44,422 187 basehttp.py basehttp 62888 123145542467584 "POST /api/v1/lists/ HTTP/1.1" 500 169122
ERROR 2022-08-12 16:40:53,198 241 log.py log 64604 123145350811648 Internal Server Error: /api/v1/lists/populate/
Traceback (most recent call last):
  File "/Users/owner/Desktop/flixcave/venv/lib/python3.10/site-packages/django/core/handlers/exception.py", line 55, in inner
    response = get_response(request)
  File "/Users/owner/Desktop/flixcave/venv/lib/python3.10/site-packages/django/core/handlers/base.py", line 197, in _get_response
    response = wrapped_callback(request, *callback_args, **callback_kwargs)
  File "/Users/owner/Desktop/flixcave/venv/lib/python3.10/site-packages/django/views/decorators/csrf.py", line 54, in wrapped_view
    return view_func(*args, **kwargs)
  File "/Users/owner/Desktop/flixcave/venv/lib/python3.10/site-packages/django/views/generic/base.py", line 84, in view
    return self.dispatch(request, *args, **kwargs)
  File "/Users/owner/Desktop/flixcave/venv/lib/python3.10/site-packages/rest_framework/views.py", line 509, in dispatch
    response = self.handle_exception(exc)
  File "/Users/owner/Desktop/flixcave/venv/lib/python3.10/site-packages/rest_framework/views.py", line 469, in handle_exception
    self.raise_uncaught_exception(exc)
  File "/Users/owner/Desktop/flixcave/venv/lib/python3.10/site-packages/rest_framework/views.py", line 480, in raise_uncaught_exception
    raise exc
  File "/Users/owner/Desktop/flixcave/venv/lib/python3.10/site-packages/rest_framework/views.py", line 506, in dispatch
    response = handler(request, *args, **kwargs)
  File "/Users/owner/Desktop/flixcave/list/views.py", line 20, in post
    List.objects.populate(serializer.validated_data)
  File "/Users/owner/Desktop/flixcave/list/models.py", line 15, in populate
    lists = List.objects.all().filter(title__icontains=title)
  File "/Users/owner/Desktop/flixcave/venv/lib/python3.10/site-packages/django/db/models/query.py", line 1071, in filter
    return self._filter_or_exclude(False, args, kwargs)
  File "/Users/owner/Desktop/flixcave/venv/lib/python3.10/site-packages/django/db/models/query.py", line 1089, in _filter_or_exclude
    clone._filter_or_exclude_inplace(negate, args, kwargs)
  File "/Users/owner/Desktop/flixcave/venv/lib/python3.10/site-packages/django/db/models/query.py", line 1096, in _filter_or_exclude_inplace
    self._query.add_q(Q(*args, **kwargs))
  File "/Users/owner/Desktop/flixcave/venv/lib/python3.10/site-packages/django/db/models/sql/query.py", line 1502, in add_q
    clause, _ = self._add_q(q_object, self.used_aliases)
  File "/Users/owner/Desktop/flixcave/venv/lib/python3.10/site-packages/django/db/models/sql/query.py", line 1532, in _add_q
    child_clause, needed_inner = self.build_filter(
  File "/Users/owner/Desktop/flixcave/venv/lib/python3.10/site-packages/django/db/models/sql/query.py", line 1377, in build_filter
    lookups, parts, reffed_expression = self.solve_lookup_type(arg)
  File "/Users/owner/Desktop/flixcave/venv/lib/python3.10/site-packages/django/db/models/sql/query.py", line 1187, in solve_lookup_type
    _, field, _, lookup_parts = self.names_to_path(lookup_splitted, self.get_meta())
  File "/Users/owner/Desktop/flixcave/venv/lib/python3.10/site-packages/django/db/models/sql/query.py", line 1677, in names_to_path
    raise FieldError(
django.core.exceptions.FieldError: Cannot resolve keyword 'title' into field. Choices are: created_at, id, list_list_item, name, updated_at, user, user_id
ERROR 2022-08-12 16:40:53,290 187 basehttp.py basehttp 64604 123145350811648 "POST /api/v1/lists/populate/ HTTP/1.1" 500 134999
ERROR 2022-08-12 16:51:44,056 241 log.py log 64799 123145506906112 Internal Server Error: /api/v1/lists/populate/
Traceback (most recent call last):
  File "/Users/owner/Desktop/flixcave/venv/lib/python3.10/site-packages/django/core/handlers/exception.py", line 55, in inner
    response = get_response(request)
  File "/Users/owner/Desktop/flixcave/venv/lib/python3.10/site-packages/django/core/handlers/base.py", line 197, in _get_response
    response = wrapped_callback(request, *callback_args, **callback_kwargs)
  File "/Users/owner/Desktop/flixcave/venv/lib/python3.10/site-packages/django/views/decorators/csrf.py", line 54, in wrapped_view
    return view_func(*args, **kwargs)
  File "/Users/owner/Desktop/flixcave/venv/lib/python3.10/site-packages/django/views/generic/base.py", line 84, in view
    return self.dispatch(request, *args, **kwargs)
  File "/Users/owner/Desktop/flixcave/venv/lib/python3.10/site-packages/rest_framework/views.py", line 509, in dispatch
    response = self.handle_exception(exc)
  File "/Users/owner/Desktop/flixcave/venv/lib/python3.10/site-packages/rest_framework/views.py", line 469, in handle_exception
    self.raise_uncaught_exception(exc)
  File "/Users/owner/Desktop/flixcave/venv/lib/python3.10/site-packages/rest_framework/views.py", line 480, in raise_uncaught_exception
    raise exc
  File "/Users/owner/Desktop/flixcave/venv/lib/python3.10/site-packages/rest_framework/views.py", line 506, in dispatch
    response = handler(request, *args, **kwargs)
  File "/Users/owner/Desktop/flixcave/list/views.py", line 20, in post
    List.objects.populate(serializer.validated_data)
  File "/Users/owner/Desktop/flixcave/list/models.py", line 20, in populate
    print(result.list_items)
AttributeError: 'List' object has no attribute 'list_items'
ERROR 2022-08-12 16:51:44,117 187 basehttp.py basehttp 64799 123145506906112 "POST /api/v1/lists/populate/ HTTP/1.1" 500 97190
ERROR 2022-08-12 18:24:59,409 241 log.py log 66694 123145539596288 Internal Server Error: /api/v1/lists/populate/
Traceback (most recent call last):
  File "/Users/owner/Desktop/flixcave/venv/lib/python3.10/site-packages/django/core/handlers/exception.py", line 55, in inner
    response = get_response(request)
  File "/Users/owner/Desktop/flixcave/venv/lib/python3.10/site-packages/django/core/handlers/base.py", line 197, in _get_response
    response = wrapped_callback(request, *callback_args, **callback_kwargs)
  File "/Users/owner/Desktop/flixcave/venv/lib/python3.10/site-packages/django/views/decorators/csrf.py", line 54, in wrapped_view
    return view_func(*args, **kwargs)
  File "/Users/owner/Desktop/flixcave/venv/lib/python3.10/site-packages/django/views/generic/base.py", line 84, in view
    return self.dispatch(request, *args, **kwargs)
  File "/Users/owner/Desktop/flixcave/venv/lib/python3.10/site-packages/rest_framework/views.py", line 509, in dispatch
    response = self.handle_exception(exc)
  File "/Users/owner/Desktop/flixcave/venv/lib/python3.10/site-packages/rest_framework/views.py", line 469, in handle_exception
    self.raise_uncaught_exception(exc)
  File "/Users/owner/Desktop/flixcave/venv/lib/python3.10/site-packages/rest_framework/views.py", line 480, in raise_uncaught_exception
    raise exc
  File "/Users/owner/Desktop/flixcave/venv/lib/python3.10/site-packages/rest_framework/views.py", line 506, in dispatch
    response = handler(request, *args, **kwargs)
  File "/Users/owner/Desktop/flixcave/list/views.py", line 20, in post
    lists = List.objects.populate(create_serializer.validated_data, request.user.id)
TypeError: ListManager.populate() missing 1 required positional argument: 'user_id'
ERROR 2022-08-12 18:24:59,410 187 basehttp.py basehttp 66694 123145539596288 "POST /api/v1/lists/populate/ HTTP/1.1" 500 92618
ERROR 2022-08-12 18:25:02,756 241 log.py log 66694 123145539596288 Internal Server Error: /api/v1/lists/populate/
Traceback (most recent call last):
  File "/Users/owner/Desktop/flixcave/venv/lib/python3.10/site-packages/django/core/handlers/exception.py", line 55, in inner
    response = get_response(request)
  File "/Users/owner/Desktop/flixcave/venv/lib/python3.10/site-packages/django/core/handlers/base.py", line 197, in _get_response
    response = wrapped_callback(request, *callback_args, **callback_kwargs)
  File "/Users/owner/Desktop/flixcave/venv/lib/python3.10/site-packages/django/views/decorators/csrf.py", line 54, in wrapped_view
    return view_func(*args, **kwargs)
  File "/Users/owner/Desktop/flixcave/venv/lib/python3.10/site-packages/django/views/generic/base.py", line 84, in view
    return self.dispatch(request, *args, **kwargs)
  File "/Users/owner/Desktop/flixcave/venv/lib/python3.10/site-packages/rest_framework/views.py", line 509, in dispatch
    response = self.handle_exception(exc)
  File "/Users/owner/Desktop/flixcave/venv/lib/python3.10/site-packages/rest_framework/views.py", line 469, in handle_exception
    self.raise_uncaught_exception(exc)
  File "/Users/owner/Desktop/flixcave/venv/lib/python3.10/site-packages/rest_framework/views.py", line 480, in raise_uncaught_exception
    raise exc
  File "/Users/owner/Desktop/flixcave/venv/lib/python3.10/site-packages/rest_framework/views.py", line 506, in dispatch
    response = handler(request, *args, **kwargs)
  File "/Users/owner/Desktop/flixcave/list/views.py", line 20, in post
    lists = List.objects.populate(create_serializer.validated_data, request.user.id)
TypeError: ListManager.populate() missing 1 required positional argument: 'user_id'
ERROR 2022-08-12 18:25:02,757 187 basehttp.py basehttp 66694 123145539596288 "POST /api/v1/lists/populate/ HTTP/1.1" 500 92619
ERROR 2022-08-12 18:25:04,294 241 log.py log 66694 123145539596288 Internal Server Error: /api/v1/lists/populate/
Traceback (most recent call last):
  File "/Users/owner/Desktop/flixcave/venv/lib/python3.10/site-packages/django/core/handlers/exception.py", line 55, in inner
    response = get_response(request)
  File "/Users/owner/Desktop/flixcave/venv/lib/python3.10/site-packages/django/core/handlers/base.py", line 197, in _get_response
    response = wrapped_callback(request, *callback_args, **callback_kwargs)
  File "/Users/owner/Desktop/flixcave/venv/lib/python3.10/site-packages/django/views/decorators/csrf.py", line 54, in wrapped_view
    return view_func(*args, **kwargs)
  File "/Users/owner/Desktop/flixcave/venv/lib/python3.10/site-packages/django/views/generic/base.py", line 84, in view
    return self.dispatch(request, *args, **kwargs)
  File "/Users/owner/Desktop/flixcave/venv/lib/python3.10/site-packages/rest_framework/views.py", line 509, in dispatch
    response = self.handle_exception(exc)
  File "/Users/owner/Desktop/flixcave/venv/lib/python3.10/site-packages/rest_framework/views.py", line 469, in handle_exception
    self.raise_uncaught_exception(exc)
  File "/Users/owner/Desktop/flixcave/venv/lib/python3.10/site-packages/rest_framework/views.py", line 480, in raise_uncaught_exception
    raise exc
  File "/Users/owner/Desktop/flixcave/venv/lib/python3.10/site-packages/rest_framework/views.py", line 506, in dispatch
    response = handler(request, *args, **kwargs)
  File "/Users/owner/Desktop/flixcave/list/views.py", line 20, in post
    lists = List.objects.populate(create_serializer.validated_data, request.user.id)
TypeError: ListManager.populate() missing 1 required positional argument: 'user_id'
ERROR 2022-08-12 18:25:04,295 187 basehttp.py basehttp 66694 123145539596288 "POST /api/v1/lists/populate/ HTTP/1.1" 500 92618
ERROR 2022-08-12 18:25:05,120 241 log.py log 66694 123145539596288 Internal Server Error: /api/v1/lists/populate/
Traceback (most recent call last):
  File "/Users/owner/Desktop/flixcave/venv/lib/python3.10/site-packages/django/core/handlers/exception.py", line 55, in inner
    response = get_response(request)
  File "/Users/owner/Desktop/flixcave/venv/lib/python3.10/site-packages/django/core/handlers/base.py", line 197, in _get_response
    response = wrapped_callback(request, *callback_args, **callback_kwargs)
  File "/Users/owner/Desktop/flixcave/venv/lib/python3.10/site-packages/django/views/decorators/csrf.py", line 54, in wrapped_view
    return view_func(*args, **kwargs)
  File "/Users/owner/Desktop/flixcave/venv/lib/python3.10/site-packages/django/views/generic/base.py", line 84, in view
    return self.dispatch(request, *args, **kwargs)
  File "/Users/owner/Desktop/flixcave/venv/lib/python3.10/site-packages/rest_framework/views.py", line 509, in dispatch
    response = self.handle_exception(exc)
  File "/Users/owner/Desktop/flixcave/venv/lib/python3.10/site-packages/rest_framework/views.py", line 469, in handle_exception
    self.raise_uncaught_exception(exc)
  File "/Users/owner/Desktop/flixcave/venv/lib/python3.10/site-packages/rest_framework/views.py", line 480, in raise_uncaught_exception
    raise exc
  File "/Users/owner/Desktop/flixcave/venv/lib/python3.10/site-packages/rest_framework/views.py", line 506, in dispatch
    response = handler(request, *args, **kwargs)
  File "/Users/owner/Desktop/flixcave/list/views.py", line 20, in post
    lists = List.objects.populate(create_serializer.validated_data, request.user.id)
TypeError: ListManager.populate() missing 1 required positional argument: 'user_id'
ERROR 2022-08-12 18:25:05,121 187 basehttp.py basehttp 66694 123145539596288 "POST /api/v1/lists/populate/ HTTP/1.1" 500 92620
ERROR 2022-08-12 18:25:05,903 241 log.py log 66694 123145539596288 Internal Server Error: /api/v1/lists/populate/
Traceback (most recent call last):
  File "/Users/owner/Desktop/flixcave/venv/lib/python3.10/site-packages/django/core/handlers/exception.py", line 55, in inner
    response = get_response(request)
  File "/Users/owner/Desktop/flixcave/venv/lib/python3.10/site-packages/django/core/handlers/base.py", line 197, in _get_response
    response = wrapped_callback(request, *callback_args, **callback_kwargs)
  File "/Users/owner/Desktop/flixcave/venv/lib/python3.10/site-packages/django/views/decorators/csrf.py", line 54, in wrapped_view
    return view_func(*args, **kwargs)
  File "/Users/owner/Desktop/flixcave/venv/lib/python3.10/site-packages/django/views/generic/base.py", line 84, in view
    return self.dispatch(request, *args, **kwargs)
  File "/Users/owner/Desktop/flixcave/venv/lib/python3.10/site-packages/rest_framework/views.py", line 509, in dispatch
    response = self.handle_exception(exc)
  File "/Users/owner/Desktop/flixcave/venv/lib/python3.10/site-packages/rest_framework/views.py", line 469, in handle_exception
    self.raise_uncaught_exception(exc)
  File "/Users/owner/Desktop/flixcave/venv/lib/python3.10/site-packages/rest_framework/views.py", line 480, in raise_uncaught_exception
    raise exc
  File "/Users/owner/Desktop/flixcave/venv/lib/python3.10/site-packages/rest_framework/views.py", line 506, in dispatch
    response = handler(request, *args, **kwargs)
  File "/Users/owner/Desktop/flixcave/list/views.py", line 20, in post
    lists = List.objects.populate(create_serializer.validated_data, request.user.id)
TypeError: ListManager.populate() missing 1 required positional argument: 'user_id'
ERROR 2022-08-12 18:25:05,911 187 basehttp.py basehttp 66694 123145539596288 "POST /api/v1/lists/populate/ HTTP/1.1" 500 92619
ERROR 2022-08-12 18:25:06,617 241 log.py log 66694 123145539596288 Internal Server Error: /api/v1/lists/populate/
Traceback (most recent call last):
  File "/Users/owner/Desktop/flixcave/venv/lib/python3.10/site-packages/django/core/handlers/exception.py", line 55, in inner
    response = get_response(request)
  File "/Users/owner/Desktop/flixcave/venv/lib/python3.10/site-packages/django/core/handlers/base.py", line 197, in _get_response
    response = wrapped_callback(request, *callback_args, **callback_kwargs)
  File "/Users/owner/Desktop/flixcave/venv/lib/python3.10/site-packages/django/views/decorators/csrf.py", line 54, in wrapped_view
    return view_func(*args, **kwargs)
  File "/Users/owner/Desktop/flixcave/venv/lib/python3.10/site-packages/django/views/generic/base.py", line 84, in view
    return self.dispatch(request, *args, **kwargs)
  File "/Users/owner/Desktop/flixcave/venv/lib/python3.10/site-packages/rest_framework/views.py", line 509, in dispatch
    response = self.handle_exception(exc)
  File "/Users/owner/Desktop/flixcave/venv/lib/python3.10/site-packages/rest_framework/views.py", line 469, in handle_exception
    self.raise_uncaught_exception(exc)
  File "/Users/owner/Desktop/flixcave/venv/lib/python3.10/site-packages/rest_framework/views.py", line 480, in raise_uncaught_exception
    raise exc
  File "/Users/owner/Desktop/flixcave/venv/lib/python3.10/site-packages/rest_framework/views.py", line 506, in dispatch
    response = handler(request, *args, **kwargs)
  File "/Users/owner/Desktop/flixcave/list/views.py", line 20, in post
    lists = List.objects.populate(create_serializer.validated_data, request.user.id)
TypeError: ListManager.populate() missing 1 required positional argument: 'user_id'
ERROR 2022-08-12 18:25:06,618 187 basehttp.py basehttp 66694 123145539596288 "POST /api/v1/lists/populate/ HTTP/1.1" 500 92618
ERROR 2022-08-12 18:25:08,128 241 log.py log 66694 123145539596288 Internal Server Error: /api/v1/lists/populate/
Traceback (most recent call last):
  File "/Users/owner/Desktop/flixcave/venv/lib/python3.10/site-packages/django/core/handlers/exception.py", line 55, in inner
    response = get_response(request)
  File "/Users/owner/Desktop/flixcave/venv/lib/python3.10/site-packages/django/core/handlers/base.py", line 197, in _get_response
    response = wrapped_callback(request, *callback_args, **callback_kwargs)
  File "/Users/owner/Desktop/flixcave/venv/lib/python3.10/site-packages/django/views/decorators/csrf.py", line 54, in wrapped_view
    return view_func(*args, **kwargs)
  File "/Users/owner/Desktop/flixcave/venv/lib/python3.10/site-packages/django/views/generic/base.py", line 84, in view
    return self.dispatch(request, *args, **kwargs)
  File "/Users/owner/Desktop/flixcave/venv/lib/python3.10/site-packages/rest_framework/views.py", line 509, in dispatch
    response = self.handle_exception(exc)
  File "/Users/owner/Desktop/flixcave/venv/lib/python3.10/site-packages/rest_framework/views.py", line 469, in handle_exception
    self.raise_uncaught_exception(exc)
  File "/Users/owner/Desktop/flixcave/venv/lib/python3.10/site-packages/rest_framework/views.py", line 480, in raise_uncaught_exception
    raise exc
  File "/Users/owner/Desktop/flixcave/venv/lib/python3.10/site-packages/rest_framework/views.py", line 506, in dispatch
    response = handler(request, *args, **kwargs)
  File "/Users/owner/Desktop/flixcave/list/views.py", line 20, in post
    lists = List.objects.populate(create_serializer.validated_data, request.user.id)
TypeError: ListManager.populate() missing 1 required positional argument: 'user_id'
ERROR 2022-08-12 18:25:08,129 187 basehttp.py basehttp 66694 123145539596288 "POST /api/v1/lists/populate/ HTTP/1.1" 500 92619
ERROR 2022-08-12 18:25:08,835 241 log.py log 66694 123145539596288 Internal Server Error: /api/v1/lists/populate/
Traceback (most recent call last):
  File "/Users/owner/Desktop/flixcave/venv/lib/python3.10/site-packages/django/core/handlers/exception.py", line 55, in inner
    response = get_response(request)
  File "/Users/owner/Desktop/flixcave/venv/lib/python3.10/site-packages/django/core/handlers/base.py", line 197, in _get_response
    response = wrapped_callback(request, *callback_args, **callback_kwargs)
  File "/Users/owner/Desktop/flixcave/venv/lib/python3.10/site-packages/django/views/decorators/csrf.py", line 54, in wrapped_view
    return view_func(*args, **kwargs)
  File "/Users/owner/Desktop/flixcave/venv/lib/python3.10/site-packages/django/views/generic/base.py", line 84, in view
    return self.dispatch(request, *args, **kwargs)
  File "/Users/owner/Desktop/flixcave/venv/lib/python3.10/site-packages/rest_framework/views.py", line 509, in dispatch
    response = self.handle_exception(exc)
  File "/Users/owner/Desktop/flixcave/venv/lib/python3.10/site-packages/rest_framework/views.py", line 469, in handle_exception
    self.raise_uncaught_exception(exc)
  File "/Users/owner/Desktop/flixcave/venv/lib/python3.10/site-packages/rest_framework/views.py", line 480, in raise_uncaught_exception
    raise exc
  File "/Users/owner/Desktop/flixcave/venv/lib/python3.10/site-packages/rest_framework/views.py", line 506, in dispatch
    response = handler(request, *args, **kwargs)
  File "/Users/owner/Desktop/flixcave/list/views.py", line 20, in post
    lists = List.objects.populate(create_serializer.validated_data, request.user.id)
TypeError: ListManager.populate() missing 1 required positional argument: 'user_id'
ERROR 2022-08-12 18:25:08,836 187 basehttp.py basehttp 66694 123145539596288 "POST /api/v1/lists/populate/ HTTP/1.1" 500 92620
ERROR 2022-08-12 18:25:09,296 241 log.py log 66694 123145539596288 Internal Server Error: /api/v1/lists/populate/
Traceback (most recent call last):
  File "/Users/owner/Desktop/flixcave/venv/lib/python3.10/site-packages/django/core/handlers/exception.py", line 55, in inner
    response = get_response(request)
  File "/Users/owner/Desktop/flixcave/venv/lib/python3.10/site-packages/django/core/handlers/base.py", line 197, in _get_response
    response = wrapped_callback(request, *callback_args, **callback_kwargs)
  File "/Users/owner/Desktop/flixcave/venv/lib/python3.10/site-packages/django/views/decorators/csrf.py", line 54, in wrapped_view
    return view_func(*args, **kwargs)
  File "/Users/owner/Desktop/flixcave/venv/lib/python3.10/site-packages/django/views/generic/base.py", line 84, in view
    return self.dispatch(request, *args, **kwargs)
  File "/Users/owner/Desktop/flixcave/venv/lib/python3.10/site-packages/rest_framework/views.py", line 509, in dispatch
    response = self.handle_exception(exc)
  File "/Users/owner/Desktop/flixcave/venv/lib/python3.10/site-packages/rest_framework/views.py", line 469, in handle_exception
    self.raise_uncaught_exception(exc)
  File "/Users/owner/Desktop/flixcave/venv/lib/python3.10/site-packages/rest_framework/views.py", line 480, in raise_uncaught_exception
    raise exc
  File "/Users/owner/Desktop/flixcave/venv/lib/python3.10/site-packages/rest_framework/views.py", line 506, in dispatch
    response = handler(request, *args, **kwargs)
  File "/Users/owner/Desktop/flixcave/list/views.py", line 20, in post
    lists = List.objects.populate(create_serializer.validated_data, request.user.id)
TypeError: ListManager.populate() missing 1 required positional argument: 'user_id'
ERROR 2022-08-12 18:25:09,297 187 basehttp.py basehttp 66694 123145539596288 "POST /api/v1/lists/populate/ HTTP/1.1" 500 92621
