ERROR 2022-07-23 19:12:25,124 241 log.py log 34020 123145567297536 Internal Server Error: /api/v1/auth/register/
Traceback (most recent call last):
  File "/Users/owner/Desktop/flixcave/venv/lib/python3.10/site-packages/django/core/handlers/exception.py", line 55, in inner
    response = get_response(request)
  File "/Users/owner/Desktop/flixcave/venv/lib/python3.10/site-packages/django/core/handlers/base.py", line 197, in _get_response
    response = wrapped_callback(request, *callback_args, **callback_kwargs)
  File "/Users/owner/Desktop/flixcave/venv/lib/python3.10/site-packages/django/views/decorators/csrf.py", line 54, in wrapped_view
    return view_func(*args, **kwargs)
  File "/Users/owner/Desktop/flixcave/venv/lib/python3.10/site-packages/django/views/generic/base.py", line 84, in view
    return self.dispatch(request, *args, **kwargs)
  File "/Users/owner/Desktop/flixcave/venv/lib/python3.10/site-packages/rest_framework/views.py", line 509, in dispatch
    response = self.handle_exception(exc)
  File "/Users/owner/Desktop/flixcave/venv/lib/python3.10/site-packages/rest_framework/views.py", line 469, in handle_exception
    self.raise_uncaught_exception(exc)
  File "/Users/owner/Desktop/flixcave/venv/lib/python3.10/site-packages/rest_framework/views.py", line 480, in raise_uncaught_exception
    raise exc
  File "/Users/owner/Desktop/flixcave/venv/lib/python3.10/site-packages/rest_framework/views.py", line 506, in dispatch
    response = handler(request, *args, **kwargs)
  File "/Users/owner/Desktop/flixcave/authentication/views.py", line 24, in post
    CustomUser.objects.create(
TypeError: CustomUserManager.create() takes 3 positional arguments but 4 were given
ERROR 2022-07-23 19:12:25,127 187 basehttp.py basehttp 34020 123145567297536 "POST /api/v1/auth/register/ HTTP/1.1" 500 92456
ERROR 2022-07-23 19:32:27,723 241 log.py log 34578 123145567838208 Internal Server Error: /api/v1/auth/register/
Traceback (most recent call last):
  File "/Users/owner/Desktop/flixcave/venv/lib/python3.10/site-packages/django/core/handlers/exception.py", line 55, in inner
    response = get_response(request)
  File "/Users/owner/Desktop/flixcave/venv/lib/python3.10/site-packages/django/core/handlers/base.py", line 197, in _get_response
    response = wrapped_callback(request, *callback_args, **callback_kwargs)
  File "/Users/owner/Desktop/flixcave/venv/lib/python3.10/site-packages/django/views/decorators/csrf.py", line 54, in wrapped_view
    return view_func(*args, **kwargs)
  File "/Users/owner/Desktop/flixcave/venv/lib/python3.10/site-packages/django/views/generic/base.py", line 84, in view
    return self.dispatch(request, *args, **kwargs)
  File "/Users/owner/Desktop/flixcave/venv/lib/python3.10/site-packages/rest_framework/views.py", line 509, in dispatch
    response = self.handle_exception(exc)
  File "/Users/owner/Desktop/flixcave/venv/lib/python3.10/site-packages/rest_framework/views.py", line 469, in handle_exception
    self.raise_uncaught_exception(exc)
  File "/Users/owner/Desktop/flixcave/venv/lib/python3.10/site-packages/rest_framework/views.py", line 480, in raise_uncaught_exception
    raise exc
  File "/Users/owner/Desktop/flixcave/venv/lib/python3.10/site-packages/rest_framework/views.py", line 506, in dispatch
    response = handler(request, *args, **kwargs)
  File "/Users/owner/Desktop/flixcave/authentication/views.py", line 23, in post
    CustomUser.objects.create(data['email'], data['password'], **data)
TypeError: CustomUserManager.create() got multiple values for argument 'email'
ERROR 2022-07-23 19:32:27,730 187 basehttp.py basehttp 34578 123145567838208 "POST /api/v1/auth/register/ HTTP/1.1" 500 92566
ERROR 2022-07-23 19:36:49,830 241 log.py log 34613 123145340964864 Internal Server Error: /api/v1/auth/register/
Traceback (most recent call last):
  File "/Users/owner/Desktop/flixcave/venv/lib/python3.10/site-packages/django/core/handlers/exception.py", line 55, in inner
    response = get_response(request)
  File "/Users/owner/Desktop/flixcave/venv/lib/python3.10/site-packages/django/core/handlers/base.py", line 197, in _get_response
    response = wrapped_callback(request, *callback_args, **callback_kwargs)
  File "/Users/owner/Desktop/flixcave/venv/lib/python3.10/site-packages/django/views/decorators/csrf.py", line 54, in wrapped_view
    return view_func(*args, **kwargs)
  File "/Users/owner/Desktop/flixcave/venv/lib/python3.10/site-packages/django/views/generic/base.py", line 84, in view
    return self.dispatch(request, *args, **kwargs)
  File "/Users/owner/Desktop/flixcave/venv/lib/python3.10/site-packages/rest_framework/views.py", line 509, in dispatch
    response = self.handle_exception(exc)
  File "/Users/owner/Desktop/flixcave/venv/lib/python3.10/site-packages/rest_framework/views.py", line 469, in handle_exception
    self.raise_uncaught_exception(exc)
  File "/Users/owner/Desktop/flixcave/venv/lib/python3.10/site-packages/rest_framework/views.py", line 480, in raise_uncaught_exception
    raise exc
  File "/Users/owner/Desktop/flixcave/venv/lib/python3.10/site-packages/rest_framework/views.py", line 506, in dispatch
    response = handler(request, *args, **kwargs)
  File "/Users/owner/Desktop/flixcave/authentication/views.py", line 23, in post
    CustomUser.objects.create(
  File "/Users/owner/Desktop/flixcave/account/models.py", line 31, in create
    user = self.model(email=email, password=password, **extra_fields)
  File "/Users/owner/Desktop/flixcave/venv/lib/python3.10/site-packages/django/db/models/base.py", line 559, in __init__
    raise TypeError(
TypeError: CustomUser() got an unexpected keyword argument 'confirm_password'
ERROR 2022-07-23 19:36:49,831 187 basehttp.py basehttp 34613 123145340964864 "POST /api/v1/auth/register/ HTTP/1.1" 500 102814
ERROR 2022-07-23 19:37:52,107 241 log.py log 34678 123145515737088 Internal Server Error: /api/v1/auth/register/
Traceback (most recent call last):
  File "/Users/owner/Desktop/flixcave/venv/lib/python3.10/site-packages/django/core/handlers/exception.py", line 55, in inner
    response = get_response(request)
  File "/Users/owner/Desktop/flixcave/venv/lib/python3.10/site-packages/django/core/handlers/base.py", line 197, in _get_response
    response = wrapped_callback(request, *callback_args, **callback_kwargs)
  File "/Users/owner/Desktop/flixcave/venv/lib/python3.10/site-packages/django/views/decorators/csrf.py", line 54, in wrapped_view
    return view_func(*args, **kwargs)
  File "/Users/owner/Desktop/flixcave/venv/lib/python3.10/site-packages/django/views/generic/base.py", line 84, in view
    return self.dispatch(request, *args, **kwargs)
  File "/Users/owner/Desktop/flixcave/venv/lib/python3.10/site-packages/rest_framework/views.py", line 509, in dispatch
    response = self.handle_exception(exc)
  File "/Users/owner/Desktop/flixcave/venv/lib/python3.10/site-packages/rest_framework/views.py", line 469, in handle_exception
    self.raise_uncaught_exception(exc)
  File "/Users/owner/Desktop/flixcave/venv/lib/python3.10/site-packages/rest_framework/views.py", line 480, in raise_uncaught_exception
    raise exc
  File "/Users/owner/Desktop/flixcave/venv/lib/python3.10/site-packages/rest_framework/views.py", line 506, in dispatch
    response = handler(request, *args, **kwargs)
  File "/Users/owner/Desktop/flixcave/authentication/views.py", line 23, in post
    CustomUser.objects.create(
  File "/Users/owner/Desktop/flixcave/account/models.py", line 31, in create
    user = self.model(email=email, password=password, **extra_fields)
  File "/Users/owner/Desktop/flixcave/venv/lib/python3.10/site-packages/django/db/models/base.py", line 559, in __init__
    raise TypeError(
TypeError: CustomUser() got an unexpected keyword argument 'confirm_password'
ERROR 2022-07-23 19:37:52,109 187 basehttp.py basehttp 34678 123145515737088 "POST /api/v1/auth/register/ HTTP/1.1" 500 102842
ERROR 2022-07-23 19:39:40,647 241 log.py log 34742 123145445203968 Internal Server Error: /api/v1/auth/register/
Traceback (most recent call last):
  File "/Users/owner/Desktop/flixcave/venv/lib/python3.10/site-packages/django/core/handlers/exception.py", line 55, in inner
    response = get_response(request)
  File "/Users/owner/Desktop/flixcave/venv/lib/python3.10/site-packages/django/core/handlers/base.py", line 197, in _get_response
    response = wrapped_callback(request, *callback_args, **callback_kwargs)
  File "/Users/owner/Desktop/flixcave/venv/lib/python3.10/site-packages/django/views/decorators/csrf.py", line 54, in wrapped_view
    return view_func(*args, **kwargs)
  File "/Users/owner/Desktop/flixcave/venv/lib/python3.10/site-packages/django/views/generic/base.py", line 84, in view
    return self.dispatch(request, *args, **kwargs)
  File "/Users/owner/Desktop/flixcave/venv/lib/python3.10/site-packages/rest_framework/views.py", line 509, in dispatch
    response = self.handle_exception(exc)
  File "/Users/owner/Desktop/flixcave/venv/lib/python3.10/site-packages/rest_framework/views.py", line 469, in handle_exception
    self.raise_uncaught_exception(exc)
  File "/Users/owner/Desktop/flixcave/venv/lib/python3.10/site-packages/rest_framework/views.py", line 480, in raise_uncaught_exception
    raise exc
  File "/Users/owner/Desktop/flixcave/venv/lib/python3.10/site-packages/rest_framework/views.py", line 506, in dispatch
    response = handler(request, *args, **kwargs)
  File "/Users/owner/Desktop/flixcave/authentication/views.py", line 23, in post
    CustomUser.objects.create(
  File "/Users/owner/Desktop/flixcave/account/models.py", line 28, in create
    extra_fields = {key: val for key,
  File "/Users/owner/Desktop/flixcave/account/models.py", line 28, in <dictcomp>
    extra_fields = {key: val for key,
ValueError: too many values to unpack (expected 2)
ERROR 2022-07-23 19:39:40,648 187 basehttp.py basehttp 34742 123145445203968 "POST /api/v1/auth/register/ HTTP/1.1" 500 99895
ERROR 2022-07-23 19:39:40,955 241 log.py log 34742 123145445203968 Internal Server Error: /api/v1/auth/register/
Traceback (most recent call last):
  File "/Users/owner/Desktop/flixcave/venv/lib/python3.10/site-packages/django/core/handlers/exception.py", line 55, in inner
    response = get_response(request)
  File "/Users/owner/Desktop/flixcave/venv/lib/python3.10/site-packages/django/core/handlers/base.py", line 197, in _get_response
    response = wrapped_callback(request, *callback_args, **callback_kwargs)
  File "/Users/owner/Desktop/flixcave/venv/lib/python3.10/site-packages/django/views/decorators/csrf.py", line 54, in wrapped_view
    return view_func(*args, **kwargs)
  File "/Users/owner/Desktop/flixcave/venv/lib/python3.10/site-packages/django/views/generic/base.py", line 84, in view
    return self.dispatch(request, *args, **kwargs)
  File "/Users/owner/Desktop/flixcave/venv/lib/python3.10/site-packages/rest_framework/views.py", line 509, in dispatch
    response = self.handle_exception(exc)
  File "/Users/owner/Desktop/flixcave/venv/lib/python3.10/site-packages/rest_framework/views.py", line 469, in handle_exception
    self.raise_uncaught_exception(exc)
  File "/Users/owner/Desktop/flixcave/venv/lib/python3.10/site-packages/rest_framework/views.py", line 480, in raise_uncaught_exception
    raise exc
  File "/Users/owner/Desktop/flixcave/venv/lib/python3.10/site-packages/rest_framework/views.py", line 506, in dispatch
    response = handler(request, *args, **kwargs)
  File "/Users/owner/Desktop/flixcave/authentication/views.py", line 23, in post
    CustomUser.objects.create(
  File "/Users/owner/Desktop/flixcave/account/models.py", line 28, in create
    extra_fields = {key: val for key,
  File "/Users/owner/Desktop/flixcave/account/models.py", line 28, in <dictcomp>
    extra_fields = {key: val for key,
ValueError: too many values to unpack (expected 2)
ERROR 2022-07-23 19:39:40,956 187 basehttp.py basehttp 34742 123145445203968 "POST /api/v1/auth/register/ HTTP/1.1" 500 99895
ERROR 2022-07-23 19:50:34,866 241 log.py log 34959 123145511714816 Internal Server Error: /api/v1/auth/register/
Traceback (most recent call last):
  File "/Users/owner/Desktop/flixcave/venv/lib/python3.10/site-packages/django/core/handlers/exception.py", line 55, in inner
    response = get_response(request)
  File "/Users/owner/Desktop/flixcave/venv/lib/python3.10/site-packages/django/core/handlers/base.py", line 197, in _get_response
    response = wrapped_callback(request, *callback_args, **callback_kwargs)
  File "/Users/owner/Desktop/flixcave/venv/lib/python3.10/site-packages/django/views/decorators/csrf.py", line 54, in wrapped_view
    return view_func(*args, **kwargs)
  File "/Users/owner/Desktop/flixcave/venv/lib/python3.10/site-packages/django/views/generic/base.py", line 84, in view
    return self.dispatch(request, *args, **kwargs)
  File "/Users/owner/Desktop/flixcave/venv/lib/python3.10/site-packages/rest_framework/views.py", line 509, in dispatch
    response = self.handle_exception(exc)
  File "/Users/owner/Desktop/flixcave/venv/lib/python3.10/site-packages/rest_framework/views.py", line 469, in handle_exception
    self.raise_uncaught_exception(exc)
  File "/Users/owner/Desktop/flixcave/venv/lib/python3.10/site-packages/rest_framework/views.py", line 480, in raise_uncaught_exception
    raise exc
  File "/Users/owner/Desktop/flixcave/venv/lib/python3.10/site-packages/rest_framework/views.py", line 506, in dispatch
    response = handler(request, *args, **kwargs)
  File "/Users/owner/Desktop/flixcave/authentication/views.py", line 23, in post
    CustomUser.objects.create(
  File "/Users/owner/Desktop/flixcave/account/models.py", line 28, in create
    test = {key: val for key, val in extra_fields if key == 'confirm_password'}
  File "/Users/owner/Desktop/flixcave/account/models.py", line 28, in <dictcomp>
    test = {key: val for key, val in extra_fields if key == 'confirm_password'}
ValueError: too many values to unpack (expected 2)
ERROR 2022-07-23 19:50:34,888 187 basehttp.py basehttp 34959 123145511714816 "POST /api/v1/auth/register/ HTTP/1.1" 500 100311
ERROR 2022-07-23 19:52:27,938 241 log.py log 34980 123145551822848 Internal Server Error: /api/v1/auth/register/
Traceback (most recent call last):
  File "/Users/owner/Desktop/flixcave/venv/lib/python3.10/site-packages/django/core/handlers/exception.py", line 55, in inner
    response = get_response(request)
  File "/Users/owner/Desktop/flixcave/venv/lib/python3.10/site-packages/django/core/handlers/base.py", line 197, in _get_response
    response = wrapped_callback(request, *callback_args, **callback_kwargs)
  File "/Users/owner/Desktop/flixcave/venv/lib/python3.10/site-packages/django/views/decorators/csrf.py", line 54, in wrapped_view
    return view_func(*args, **kwargs)
  File "/Users/owner/Desktop/flixcave/venv/lib/python3.10/site-packages/django/views/generic/base.py", line 84, in view
    return self.dispatch(request, *args, **kwargs)
  File "/Users/owner/Desktop/flixcave/venv/lib/python3.10/site-packages/rest_framework/views.py", line 509, in dispatch
    response = self.handle_exception(exc)
  File "/Users/owner/Desktop/flixcave/venv/lib/python3.10/site-packages/rest_framework/views.py", line 469, in handle_exception
    self.raise_uncaught_exception(exc)
  File "/Users/owner/Desktop/flixcave/venv/lib/python3.10/site-packages/rest_framework/views.py", line 480, in raise_uncaught_exception
    raise exc
  File "/Users/owner/Desktop/flixcave/venv/lib/python3.10/site-packages/rest_framework/views.py", line 506, in dispatch
    response = handler(request, *args, **kwargs)
  File "/Users/owner/Desktop/flixcave/authentication/views.py", line 23, in post
    CustomUser.objects.create(
  File "/Users/owner/Desktop/flixcave/account/models.py", line 28, in create
    test = {key: val for key, val in extra_fields}
  File "/Users/owner/Desktop/flixcave/account/models.py", line 28, in <dictcomp>
    test = {key: val for key, val in extra_fields}
ValueError: too many values to unpack (expected 2)
ERROR 2022-07-23 19:52:27,939 187 basehttp.py basehttp 34980 123145551822848 "POST /api/v1/auth/register/ HTTP/1.1" 500 100151
ERROR 2022-07-23 21:58:38,781 241 log.py log 36422 123145565327360 Internal Server Error: /api/v1/auth/register/
Traceback (most recent call last):
  File "/Users/owner/Desktop/flixcave/venv/lib/python3.10/site-packages/django/db/backends/utils.py", line 89, in _execute
    return self.cursor.execute(sql, params)
psycopg2.errors.UndefinedTable: relation "verification_token_verificationtoken" does not exist
LINE 1: INSERT INTO "verification_token_verificationtoken" ("created...
                    ^


The above exception was the direct cause of the following exception:

Traceback (most recent call last):
  File "/Users/owner/Desktop/flixcave/venv/lib/python3.10/site-packages/django/core/handlers/exception.py", line 55, in inner
    response = get_response(request)
  File "/Users/owner/Desktop/flixcave/venv/lib/python3.10/site-packages/django/core/handlers/base.py", line 197, in _get_response
    response = wrapped_callback(request, *callback_args, **callback_kwargs)
  File "/Users/owner/Desktop/flixcave/venv/lib/python3.10/site-packages/django/views/decorators/csrf.py", line 54, in wrapped_view
    return view_func(*args, **kwargs)
  File "/Users/owner/Desktop/flixcave/venv/lib/python3.10/site-packages/django/views/generic/base.py", line 84, in view
    return self.dispatch(request, *args, **kwargs)
  File "/Users/owner/Desktop/flixcave/venv/lib/python3.10/site-packages/rest_framework/views.py", line 509, in dispatch
    response = self.handle_exception(exc)
  File "/Users/owner/Desktop/flixcave/venv/lib/python3.10/site-packages/rest_framework/views.py", line 469, in handle_exception
    self.raise_uncaught_exception(exc)
  File "/Users/owner/Desktop/flixcave/venv/lib/python3.10/site-packages/rest_framework/views.py", line 480, in raise_uncaught_exception
    raise exc
  File "/Users/owner/Desktop/flixcave/venv/lib/python3.10/site-packages/rest_framework/views.py", line 506, in dispatch
    response = handler(request, *args, **kwargs)
  File "/Users/owner/Desktop/flixcave/authentication/views.py", line 27, in post
    token = VerificationToken.objects.create(user)
  File "/Users/owner/Desktop/flixcave/verification_token/models.py", line 16, in create
    verification_token.save()
  File "/Users/owner/Desktop/flixcave/venv/lib/python3.10/site-packages/django/db/models/base.py", line 806, in save
    self.save_base(
  File "/Users/owner/Desktop/flixcave/venv/lib/python3.10/site-packages/django/db/models/base.py", line 857, in save_base
    updated = self._save_table(
  File "/Users/owner/Desktop/flixcave/venv/lib/python3.10/site-packages/django/db/models/base.py", line 1000, in _save_table
    results = self._do_insert(
  File "/Users/owner/Desktop/flixcave/venv/lib/python3.10/site-packages/django/db/models/base.py", line 1041, in _do_insert
    return manager._insert(
  File "/Users/owner/Desktop/flixcave/venv/lib/python3.10/site-packages/django/db/models/manager.py", line 85, in manager_method
    return getattr(self.get_queryset(), name)(*args, **kwargs)
  File "/Users/owner/Desktop/flixcave/venv/lib/python3.10/site-packages/django/db/models/query.py", line 1434, in _insert
    return query.get_compiler(using=using).execute_sql(returning_fields)
  File "/Users/owner/Desktop/flixcave/venv/lib/python3.10/site-packages/django/db/models/sql/compiler.py", line 1621, in execute_sql
    cursor.execute(sql, params)
  File "/Users/owner/Desktop/flixcave/venv/lib/python3.10/site-packages/django/db/backends/utils.py", line 103, in execute
    return super().execute(sql, params)
  File "/Users/owner/Desktop/flixcave/venv/lib/python3.10/site-packages/django/db/backends/utils.py", line 67, in execute
    return self._execute_with_wrappers(
  File "/Users/owner/Desktop/flixcave/venv/lib/python3.10/site-packages/django/db/backends/utils.py", line 80, in _execute_with_wrappers
    return executor(sql, params, many, context)
  File "/Users/owner/Desktop/flixcave/venv/lib/python3.10/site-packages/django/db/backends/utils.py", line 84, in _execute
    with self.db.wrap_database_errors:
  File "/Users/owner/Desktop/flixcave/venv/lib/python3.10/site-packages/django/db/utils.py", line 91, in __exit__
    raise dj_exc_value.with_traceback(traceback) from exc_value
  File "/Users/owner/Desktop/flixcave/venv/lib/python3.10/site-packages/django/db/backends/utils.py", line 89, in _execute
    return self.cursor.execute(sql, params)
django.db.utils.ProgrammingError: relation "verification_token_verificationtoken" does not exist
LINE 1: INSERT INTO "verification_token_verificationtoken" ("created...
                    ^

ERROR 2022-07-23 21:58:38,785 187 basehttp.py basehttp 36422 123145565327360 "POST /api/v1/auth/register/ HTTP/1.1" 500 169984
ERROR 2022-07-23 22:04:44,306 241 log.py log 36654 123145432305664 Internal Server Error: /api/v1/auth/register/
Traceback (most recent call last):
  File "/Users/owner/Desktop/flixcave/venv/lib/python3.10/site-packages/django/core/handlers/exception.py", line 55, in inner
    response = get_response(request)
  File "/Users/owner/Desktop/flixcave/venv/lib/python3.10/site-packages/django/core/handlers/base.py", line 197, in _get_response
    response = wrapped_callback(request, *callback_args, **callback_kwargs)
  File "/Users/owner/Desktop/flixcave/venv/lib/python3.10/site-packages/django/views/decorators/csrf.py", line 54, in wrapped_view
    return view_func(*args, **kwargs)
  File "/Users/owner/Desktop/flixcave/venv/lib/python3.10/site-packages/django/views/generic/base.py", line 84, in view
    return self.dispatch(request, *args, **kwargs)
  File "/Users/owner/Desktop/flixcave/venv/lib/python3.10/site-packages/rest_framework/views.py", line 509, in dispatch
    response = self.handle_exception(exc)
  File "/Users/owner/Desktop/flixcave/venv/lib/python3.10/site-packages/rest_framework/views.py", line 469, in handle_exception
    self.raise_uncaught_exception(exc)
  File "/Users/owner/Desktop/flixcave/venv/lib/python3.10/site-packages/rest_framework/views.py", line 480, in raise_uncaught_exception
    raise exc
  File "/Users/owner/Desktop/flixcave/venv/lib/python3.10/site-packages/rest_framework/views.py", line 506, in dispatch
    response = handler(request, *args, **kwargs)
  File "/Users/owner/Desktop/flixcave/authentication/views.py", line 29, in post
    CustomUser.verfication_email(token=token, user=user)
AttributeError: type object 'CustomUser' has no attribute 'verfication_email'
ERROR 2022-07-23 22:04:44,307 187 basehttp.py basehttp 36654 123145432305664 "POST /api/v1/auth/register/ HTTP/1.1" 500 93384
ERROR 2022-07-23 22:55:30,927 241 log.py log 37882 123145341218816 Internal Server Error: /api/v1/auth/verify/
Traceback (most recent call last):
  File "/Users/owner/Desktop/flixcave/venv/lib/python3.10/site-packages/django/core/handlers/exception.py", line 55, in inner
    response = get_response(request)
  File "/Users/owner/Desktop/flixcave/venv/lib/python3.10/site-packages/django/core/handlers/base.py", line 197, in _get_response
    response = wrapped_callback(request, *callback_args, **callback_kwargs)
  File "/Users/owner/Desktop/flixcave/venv/lib/python3.10/site-packages/django/views/decorators/csrf.py", line 54, in wrapped_view
    return view_func(*args, **kwargs)
  File "/Users/owner/Desktop/flixcave/venv/lib/python3.10/site-packages/django/views/generic/base.py", line 84, in view
    return self.dispatch(request, *args, **kwargs)
  File "/Users/owner/Desktop/flixcave/venv/lib/python3.10/site-packages/rest_framework/views.py", line 509, in dispatch
    response = self.handle_exception(exc)
  File "/Users/owner/Desktop/flixcave/venv/lib/python3.10/site-packages/rest_framework/views.py", line 469, in handle_exception
    self.raise_uncaught_exception(exc)
  File "/Users/owner/Desktop/flixcave/venv/lib/python3.10/site-packages/rest_framework/views.py", line 480, in raise_uncaught_exception
    raise exc
  File "/Users/owner/Desktop/flixcave/venv/lib/python3.10/site-packages/rest_framework/views.py", line 506, in dispatch
    response = handler(request, *args, **kwargs)
  File "/Users/owner/Desktop/flixcave/authentication/views.py", line 27, in post
    CustomUser.objects.verify_account(serializer.validated_data)
  File "/Users/owner/Desktop/flixcave/account/models.py", line 28, in verify_account
    print(decoded_token['uid'])
KeyError: 'uid'
ERROR 2022-07-23 22:55:30,930 187 basehttp.py basehttp 37882 123145341218816 "POST /api/v1/auth/verify/ HTTP/1.1" 500 95854
ERROR 2022-07-23 22:56:34,616 241 log.py log 37911 123145383260160 Internal Server Error: /api/v1/auth/verify/
Traceback (most recent call last):
  File "/Users/owner/Desktop/flixcave/venv/lib/python3.10/site-packages/jwt/api_jws.py", line 220, in _load
    signing_input, crypto_segment = jwt.rsplit(b".", 1)
ValueError: not enough values to unpack (expected 2, got 1)

The above exception was the direct cause of the following exception:

Traceback (most recent call last):
  File "/Users/owner/Desktop/flixcave/venv/lib/python3.10/site-packages/rest_framework_simplejwt/backends.py", line 105, in decode
    return jwt.decode(
  File "/Users/owner/Desktop/flixcave/venv/lib/python3.10/site-packages/jwt/api_jwt.py", line 129, in decode
    decoded = self.decode_complete(jwt, key, algorithms, options, **kwargs)
  File "/Users/owner/Desktop/flixcave/venv/lib/python3.10/site-packages/jwt/api_jwt.py", line 100, in decode_complete
    decoded = api_jws.decode_complete(
  File "/Users/owner/Desktop/flixcave/venv/lib/python3.10/site-packages/jwt/api_jws.py", line 171, in decode_complete
    payload, signing_input, header, signature = self._load(jwt)
  File "/Users/owner/Desktop/flixcave/venv/lib/python3.10/site-packages/jwt/api_jws.py", line 223, in _load
    raise DecodeError("Not enough segments") from err
jwt.exceptions.DecodeError: Not enough segments

During handling of the above exception, another exception occurred:

Traceback (most recent call last):
  File "/Users/owner/Desktop/flixcave/venv/lib/python3.10/site-packages/django/core/handlers/exception.py", line 55, in inner
    response = get_response(request)
  File "/Users/owner/Desktop/flixcave/venv/lib/python3.10/site-packages/django/core/handlers/base.py", line 197, in _get_response
    response = wrapped_callback(request, *callback_args, **callback_kwargs)
  File "/Users/owner/Desktop/flixcave/venv/lib/python3.10/site-packages/django/views/decorators/csrf.py", line 54, in wrapped_view
    return view_func(*args, **kwargs)
  File "/Users/owner/Desktop/flixcave/venv/lib/python3.10/site-packages/django/views/generic/base.py", line 84, in view
    return self.dispatch(request, *args, **kwargs)
  File "/Users/owner/Desktop/flixcave/venv/lib/python3.10/site-packages/rest_framework/views.py", line 509, in dispatch
    response = self.handle_exception(exc)
  File "/Users/owner/Desktop/flixcave/venv/lib/python3.10/site-packages/rest_framework/views.py", line 469, in handle_exception
    self.raise_uncaught_exception(exc)
  File "/Users/owner/Desktop/flixcave/venv/lib/python3.10/site-packages/rest_framework/views.py", line 480, in raise_uncaught_exception
    raise exc
  File "/Users/owner/Desktop/flixcave/venv/lib/python3.10/site-packages/rest_framework/views.py", line 506, in dispatch
    response = handler(request, *args, **kwargs)
  File "/Users/owner/Desktop/flixcave/authentication/views.py", line 27, in post
    CustomUser.objects.verify_account(serializer.validated_data)
  File "/Users/owner/Desktop/flixcave/account/models.py", line 24, in verify_account
    decoded_token = TokenBackend(
  File "/Users/owner/Desktop/flixcave/venv/lib/python3.10/site-packages/rest_framework_simplejwt/backends.py", line 120, in decode
    raise TokenBackendError(_("Token is invalid or expired"))
rest_framework_simplejwt.exceptions.TokenBackendError: Token is invalid or expired
ERROR 2022-07-23 22:56:34,619 187 basehttp.py basehttp 37911 123145383260160 "POST /api/v1/auth/verify/ HTTP/1.1" 500 125106
ERROR 2022-07-23 22:58:51,827 30 models.py models 37955 123145443766272 Invalid or malformed token.
ERROR 2022-07-23 23:02:51,082 30 models.py models 38062 123145600970752 Invalid or malformed token.
ERROR 2022-07-24 15:28:18,102 241 log.py log 41132 123145560567808 Internal Server Error: /api/v1/auth/login/
Traceback (most recent call last):
  File "/Users/owner/Desktop/flixcave/authentication/views.py", line 73, in post
    raise ObjectDoesNotExist(result)
django.core.exceptions.ObjectDoesNotExist: {'type': 'error', 'msg': 'A user with this email does not exist.', 'status': 404}

During handling of the above exception, another exception occurred:

Traceback (most recent call last):
  File "/Users/owner/Desktop/flixcave/venv/lib/python3.10/site-packages/django/core/handlers/exception.py", line 55, in inner
    response = get_response(request)
  File "/Users/owner/Desktop/flixcave/venv/lib/python3.10/site-packages/django/core/handlers/base.py", line 197, in _get_response
    response = wrapped_callback(request, *callback_args, **callback_kwargs)
  File "/Users/owner/Desktop/flixcave/venv/lib/python3.10/site-packages/django/views/decorators/csrf.py", line 54, in wrapped_view
    return view_func(*args, **kwargs)
  File "/Users/owner/Desktop/flixcave/venv/lib/python3.10/site-packages/django/views/generic/base.py", line 84, in view
    return self.dispatch(request, *args, **kwargs)
  File "/Users/owner/Desktop/flixcave/venv/lib/python3.10/site-packages/rest_framework/views.py", line 509, in dispatch
    response = self.handle_exception(exc)
  File "/Users/owner/Desktop/flixcave/venv/lib/python3.10/site-packages/rest_framework/views.py", line 469, in handle_exception
    self.raise_uncaught_exception(exc)
  File "/Users/owner/Desktop/flixcave/venv/lib/python3.10/site-packages/rest_framework/views.py", line 480, in raise_uncaught_exception
    raise exc
  File "/Users/owner/Desktop/flixcave/venv/lib/python3.10/site-packages/rest_framework/views.py", line 506, in dispatch
    response = handler(request, *args, **kwargs)
  File "/Users/owner/Desktop/flixcave/authentication/views.py", line 79, in post
    print(e['type'])
TypeError: 'ObjectDoesNotExist' object is not subscriptable
ERROR 2022-07-24 15:28:18,161 187 basehttp.py basehttp 41132 123145560567808 "POST /api/v1/auth/login/ HTTP/1.1" 500 96229
ERROR 2022-07-24 15:30:53,816 241 log.py log 41218 123145406980096 Internal Server Error: /api/v1/auth/login/
Traceback (most recent call last):
  File "/Users/owner/Desktop/flixcave/venv/lib/python3.10/site-packages/django/core/handlers/exception.py", line 55, in inner
    response = get_response(request)
  File "/Users/owner/Desktop/flixcave/venv/lib/python3.10/site-packages/django/core/handlers/base.py", line 220, in _get_response
    response = response.render()
  File "/Users/owner/Desktop/flixcave/venv/lib/python3.10/site-packages/django/template/response.py", line 114, in render
    self.content = self.rendered_content
  File "/Users/owner/Desktop/flixcave/venv/lib/python3.10/site-packages/rest_framework/response.py", line 70, in rendered_content
    ret = renderer.render(self.data, accepted_media_type, context)
  File "/Users/owner/Desktop/flixcave/venv/lib/python3.10/site-packages/rest_framework/renderers.py", line 100, in render
    ret = json.dumps(
  File "/Users/owner/Desktop/flixcave/venv/lib/python3.10/site-packages/rest_framework/utils/json.py", line 25, in dumps
    return json.dumps(*args, **kwargs)
  File "/Library/Frameworks/Python.framework/Versions/3.10/lib/python3.10/json/__init__.py", line 238, in dumps
    **kw).encode(obj)
  File "/Library/Frameworks/Python.framework/Versions/3.10/lib/python3.10/json/encoder.py", line 199, in encode
    chunks = self.iterencode(o, _one_shot=True)
  File "/Library/Frameworks/Python.framework/Versions/3.10/lib/python3.10/json/encoder.py", line 257, in iterencode
    return _iterencode(o, 0)
  File "/Users/owner/Desktop/flixcave/venv/lib/python3.10/site-packages/rest_framework/utils/encoders.py", line 67, in default
    return super().default(obj)
  File "/Library/Frameworks/Python.framework/Versions/3.10/lib/python3.10/json/encoder.py", line 179, in default
    raise TypeError(f'Object of type {o.__class__.__name__} '
TypeError: Object of type ObjectDoesNotExist is not JSON serializable
ERROR 2022-07-24 15:30:53,817 241 log.py log 41218 123145423769600 Internal Server Error: /api/v1/auth/login/
Traceback (most recent call last):
  File "/Users/owner/Desktop/flixcave/venv/lib/python3.10/site-packages/django/core/handlers/exception.py", line 55, in inner
    response = get_response(request)
  File "/Users/owner/Desktop/flixcave/venv/lib/python3.10/site-packages/django/core/handlers/base.py", line 220, in _get_response
    response = response.render()
  File "/Users/owner/Desktop/flixcave/venv/lib/python3.10/site-packages/django/template/response.py", line 114, in render
    self.content = self.rendered_content
  File "/Users/owner/Desktop/flixcave/venv/lib/python3.10/site-packages/rest_framework/response.py", line 70, in rendered_content
    ret = renderer.render(self.data, accepted_media_type, context)
  File "/Users/owner/Desktop/flixcave/venv/lib/python3.10/site-packages/rest_framework/renderers.py", line 100, in render
    ret = json.dumps(
  File "/Users/owner/Desktop/flixcave/venv/lib/python3.10/site-packages/rest_framework/utils/json.py", line 25, in dumps
    return json.dumps(*args, **kwargs)
  File "/Library/Frameworks/Python.framework/Versions/3.10/lib/python3.10/json/__init__.py", line 238, in dumps
    **kw).encode(obj)
  File "/Library/Frameworks/Python.framework/Versions/3.10/lib/python3.10/json/encoder.py", line 199, in encode
    chunks = self.iterencode(o, _one_shot=True)
  File "/Library/Frameworks/Python.framework/Versions/3.10/lib/python3.10/json/encoder.py", line 257, in iterencode
    return _iterencode(o, 0)
  File "/Users/owner/Desktop/flixcave/venv/lib/python3.10/site-packages/rest_framework/utils/encoders.py", line 67, in default
    return super().default(obj)
  File "/Library/Frameworks/Python.framework/Versions/3.10/lib/python3.10/json/encoder.py", line 179, in default
    raise TypeError(f'Object of type {o.__class__.__name__} '
TypeError: Object of type ObjectDoesNotExist is not JSON serializable
ERROR 2022-07-24 15:30:53,819 187 basehttp.py basehttp 41218 123145406980096 "POST /api/v1/auth/login/ HTTP/1.1" 500 100577
ERROR 2022-07-24 15:30:53,820 187 basehttp.py basehttp 41218 123145423769600 "POST /api/v1/auth/login/ HTTP/1.1" 500 100577
ERROR 2022-07-24 15:35:51,641 241 log.py log 41343 123145414594560 Internal Server Error: /api/v1/auth/login/
Traceback (most recent call last):
  File "/Users/owner/Desktop/flixcave/authentication/views.py", line 74, in post
    raise ObjectDoesNotExist(json.dumps(result))
django.core.exceptions.ObjectDoesNotExist: {"type": "error", "msg": "A user with this email does not exist.", "status": 404}

During handling of the above exception, another exception occurred:

Traceback (most recent call last):
  File "/Users/owner/Desktop/flixcave/venv/lib/python3.10/site-packages/django/core/handlers/exception.py", line 55, in inner
    response = get_response(request)
  File "/Users/owner/Desktop/flixcave/venv/lib/python3.10/site-packages/django/core/handlers/base.py", line 197, in _get_response
    response = wrapped_callback(request, *callback_args, **callback_kwargs)
  File "/Users/owner/Desktop/flixcave/venv/lib/python3.10/site-packages/django/views/decorators/csrf.py", line 54, in wrapped_view
    return view_func(*args, **kwargs)
  File "/Users/owner/Desktop/flixcave/venv/lib/python3.10/site-packages/django/views/generic/base.py", line 84, in view
    return self.dispatch(request, *args, **kwargs)
  File "/Users/owner/Desktop/flixcave/venv/lib/python3.10/site-packages/rest_framework/views.py", line 509, in dispatch
    response = self.handle_exception(exc)
  File "/Users/owner/Desktop/flixcave/venv/lib/python3.10/site-packages/rest_framework/views.py", line 469, in handle_exception
    self.raise_uncaught_exception(exc)
  File "/Users/owner/Desktop/flixcave/venv/lib/python3.10/site-packages/rest_framework/views.py", line 480, in raise_uncaught_exception
    raise exc
  File "/Users/owner/Desktop/flixcave/venv/lib/python3.10/site-packages/rest_framework/views.py", line 506, in dispatch
    response = handler(request, *args, **kwargs)
  File "/Users/owner/Desktop/flixcave/authentication/views.py", line 80, in post
    print(json.loads(e))
  File "/Library/Frameworks/Python.framework/Versions/3.10/lib/python3.10/json/__init__.py", line 339, in loads
    raise TypeError(f'the JSON object must be str, bytes or bytearray, '
TypeError: the JSON object must be str, bytes or bytearray, not ObjectDoesNotExist
ERROR 2022-07-24 15:35:51,656 187 basehttp.py basehttp 41343 123145414594560 "POST /api/v1/auth/login/ HTTP/1.1" 500 101280
ERROR 2022-07-24 15:35:52,408 241 log.py log 41343 123145414594560 Internal Server Error: /api/v1/auth/login/
Traceback (most recent call last):
  File "/Users/owner/Desktop/flixcave/authentication/views.py", line 74, in post
    raise ObjectDoesNotExist(json.dumps(result))
django.core.exceptions.ObjectDoesNotExist: {"type": "error", "msg": "A user with this email does not exist.", "status": 404}

During handling of the above exception, another exception occurred:

Traceback (most recent call last):
  File "/Users/owner/Desktop/flixcave/venv/lib/python3.10/site-packages/django/core/handlers/exception.py", line 55, in inner
    response = get_response(request)
  File "/Users/owner/Desktop/flixcave/venv/lib/python3.10/site-packages/django/core/handlers/base.py", line 197, in _get_response
    response = wrapped_callback(request, *callback_args, **callback_kwargs)
  File "/Users/owner/Desktop/flixcave/venv/lib/python3.10/site-packages/django/views/decorators/csrf.py", line 54, in wrapped_view
    return view_func(*args, **kwargs)
  File "/Users/owner/Desktop/flixcave/venv/lib/python3.10/site-packages/django/views/generic/base.py", line 84, in view
    return self.dispatch(request, *args, **kwargs)
  File "/Users/owner/Desktop/flixcave/venv/lib/python3.10/site-packages/rest_framework/views.py", line 509, in dispatch
    response = self.handle_exception(exc)
  File "/Users/owner/Desktop/flixcave/venv/lib/python3.10/site-packages/rest_framework/views.py", line 469, in handle_exception
    self.raise_uncaught_exception(exc)
  File "/Users/owner/Desktop/flixcave/venv/lib/python3.10/site-packages/rest_framework/views.py", line 480, in raise_uncaught_exception
    raise exc
  File "/Users/owner/Desktop/flixcave/venv/lib/python3.10/site-packages/rest_framework/views.py", line 506, in dispatch
    response = handler(request, *args, **kwargs)
  File "/Users/owner/Desktop/flixcave/authentication/views.py", line 80, in post
    print(json.loads(e))
  File "/Library/Frameworks/Python.framework/Versions/3.10/lib/python3.10/json/__init__.py", line 339, in loads
    raise TypeError(f'the JSON object must be str, bytes or bytearray, '
TypeError: the JSON object must be str, bytes or bytearray, not ObjectDoesNotExist
ERROR 2022-07-24 15:35:52,409 187 basehttp.py basehttp 41343 123145414594560 "POST /api/v1/auth/login/ HTTP/1.1" 500 101280
ERROR 2022-07-24 15:36:50,377 241 log.py log 41357 123145590616064 Internal Server Error: /api/v1/auth/login/
Traceback (most recent call last):
  File "/Users/owner/Desktop/flixcave/authentication/views.py", line 74, in post
    raise Exception(json.dumps(result))
Exception: {"type": "error", "msg": "A user with this email does not exist.", "status": 404}

During handling of the above exception, another exception occurred:

Traceback (most recent call last):
  File "/Users/owner/Desktop/flixcave/venv/lib/python3.10/site-packages/django/core/handlers/exception.py", line 55, in inner
    response = get_response(request)
  File "/Users/owner/Desktop/flixcave/venv/lib/python3.10/site-packages/django/core/handlers/base.py", line 197, in _get_response
    response = wrapped_callback(request, *callback_args, **callback_kwargs)
  File "/Users/owner/Desktop/flixcave/venv/lib/python3.10/site-packages/django/views/decorators/csrf.py", line 54, in wrapped_view
    return view_func(*args, **kwargs)
  File "/Users/owner/Desktop/flixcave/venv/lib/python3.10/site-packages/django/views/generic/base.py", line 84, in view
    return self.dispatch(request, *args, **kwargs)
  File "/Users/owner/Desktop/flixcave/venv/lib/python3.10/site-packages/rest_framework/views.py", line 509, in dispatch
    response = self.handle_exception(exc)
  File "/Users/owner/Desktop/flixcave/venv/lib/python3.10/site-packages/rest_framework/views.py", line 469, in handle_exception
    self.raise_uncaught_exception(exc)
  File "/Users/owner/Desktop/flixcave/venv/lib/python3.10/site-packages/rest_framework/views.py", line 480, in raise_uncaught_exception
    raise exc
  File "/Users/owner/Desktop/flixcave/venv/lib/python3.10/site-packages/rest_framework/views.py", line 506, in dispatch
    response = handler(request, *args, **kwargs)
  File "/Users/owner/Desktop/flixcave/authentication/views.py", line 80, in post
    print(json.loads(e))
  File "/Library/Frameworks/Python.framework/Versions/3.10/lib/python3.10/json/__init__.py", line 339, in loads
    raise TypeError(f'the JSON object must be str, bytes or bytearray, '
TypeError: the JSON object must be str, bytes or bytearray, not Exception
ERROR 2022-07-24 15:36:50,380 187 basehttp.py basehttp 41357 123145590616064 "POST /api/v1/auth/login/ HTTP/1.1" 500 101160
ERROR 2022-07-24 16:45:23,362 241 log.py log 42854 123145561505792 Internal Server Error: /api/v1/auth/resend-verify
Traceback (most recent call last):
  File "/Users/owner/Desktop/flixcave/venv/lib/python3.10/site-packages/django/core/handlers/exception.py", line 55, in inner
    response = get_response(request)
  File "/Users/owner/Desktop/flixcave/venv/lib/python3.10/site-packages/django/utils/deprecation.py", line 133, in __call__
    response = self.process_request(request)
  File "/Users/owner/Desktop/flixcave/venv/lib/python3.10/site-packages/django/middleware/common.py", line 54, in process_request
    path = self.get_full_path_with_slash(request)
  File "/Users/owner/Desktop/flixcave/venv/lib/python3.10/site-packages/django/middleware/common.py", line 88, in get_full_path_with_slash
    raise RuntimeError(
RuntimeError: You called this URL via POST, but the URL doesn't end in a slash and you have APPEND_SLASH set. Django can't redirect to the slash URL while maintaining POST data. Change your form to point to localhost:8000/api/v1/auth/resend-verify/ (note the trailing slash), or set APPEND_SLASH=False in your Django settings.
ERROR 2022-07-24 16:45:23,468 187 basehttp.py basehttp 42854 123145561505792 "POST /api/v1/auth/resend-verify HTTP/1.1" 500 70642
ERROR 2022-07-24 16:45:23,718 241 log.py log 42854 123145561505792 Internal Server Error: /api/v1/auth/resend-verify
Traceback (most recent call last):
  File "/Users/owner/Desktop/flixcave/venv/lib/python3.10/site-packages/django/core/handlers/exception.py", line 55, in inner
    response = get_response(request)
  File "/Users/owner/Desktop/flixcave/venv/lib/python3.10/site-packages/django/utils/deprecation.py", line 133, in __call__
    response = self.process_request(request)
  File "/Users/owner/Desktop/flixcave/venv/lib/python3.10/site-packages/django/middleware/common.py", line 54, in process_request
    path = self.get_full_path_with_slash(request)
  File "/Users/owner/Desktop/flixcave/venv/lib/python3.10/site-packages/django/middleware/common.py", line 88, in get_full_path_with_slash
    raise RuntimeError(
RuntimeError: You called this URL via POST, but the URL doesn't end in a slash and you have APPEND_SLASH set. Django can't redirect to the slash URL while maintaining POST data. Change your form to point to localhost:8000/api/v1/auth/resend-verify/ (note the trailing slash), or set APPEND_SLASH=False in your Django settings.
ERROR 2022-07-24 16:45:23,720 187 basehttp.py basehttp 42854 123145561505792 "POST /api/v1/auth/resend-verify HTTP/1.1" 500 70642
ERROR 2022-07-24 16:45:25,482 241 log.py log 42854 123145561505792 Internal Server Error: /api/v1/auth/resend-verify
Traceback (most recent call last):
  File "/Users/owner/Desktop/flixcave/venv/lib/python3.10/site-packages/django/core/handlers/exception.py", line 55, in inner
    response = get_response(request)
  File "/Users/owner/Desktop/flixcave/venv/lib/python3.10/site-packages/django/utils/deprecation.py", line 133, in __call__
    response = self.process_request(request)
  File "/Users/owner/Desktop/flixcave/venv/lib/python3.10/site-packages/django/middleware/common.py", line 54, in process_request
    path = self.get_full_path_with_slash(request)
  File "/Users/owner/Desktop/flixcave/venv/lib/python3.10/site-packages/django/middleware/common.py", line 88, in get_full_path_with_slash
    raise RuntimeError(
RuntimeError: You called this URL via POST, but the URL doesn't end in a slash and you have APPEND_SLASH set. Django can't redirect to the slash URL while maintaining POST data. Change your form to point to localhost:8000/api/v1/auth/resend-verify/ (note the trailing slash), or set APPEND_SLASH=False in your Django settings.
ERROR 2022-07-24 16:45:25,483 187 basehttp.py basehttp 42854 123145561505792 "POST /api/v1/auth/resend-verify HTTP/1.1" 500 70642
ERROR 2022-07-24 16:45:44,563 241 log.py log 42854 123145561505792 Internal Server Error: /api/v1/auth/resend-verify
Traceback (most recent call last):
  File "/Users/owner/Desktop/flixcave/venv/lib/python3.10/site-packages/django/core/handlers/exception.py", line 55, in inner
    response = get_response(request)
  File "/Users/owner/Desktop/flixcave/venv/lib/python3.10/site-packages/django/utils/deprecation.py", line 133, in __call__
    response = self.process_request(request)
  File "/Users/owner/Desktop/flixcave/venv/lib/python3.10/site-packages/django/middleware/common.py", line 54, in process_request
    path = self.get_full_path_with_slash(request)
  File "/Users/owner/Desktop/flixcave/venv/lib/python3.10/site-packages/django/middleware/common.py", line 88, in get_full_path_with_slash
    raise RuntimeError(
RuntimeError: You called this URL via POST, but the URL doesn't end in a slash and you have APPEND_SLASH set. Django can't redirect to the slash URL while maintaining POST data. Change your form to point to localhost:8000/api/v1/auth/resend-verify/ (note the trailing slash), or set APPEND_SLASH=False in your Django settings.
ERROR 2022-07-24 16:45:44,564 187 basehttp.py basehttp 42854 123145561505792 "POST /api/v1/auth/resend-verify HTTP/1.1" 500 70642
ERROR 2022-07-24 16:45:47,162 241 log.py log 42854 123145561505792 Internal Server Error: /api/v1/auth/resend-verify
Traceback (most recent call last):
  File "/Users/owner/Desktop/flixcave/venv/lib/python3.10/site-packages/django/core/handlers/exception.py", line 55, in inner
    response = get_response(request)
  File "/Users/owner/Desktop/flixcave/venv/lib/python3.10/site-packages/django/utils/deprecation.py", line 133, in __call__
    response = self.process_request(request)
  File "/Users/owner/Desktop/flixcave/venv/lib/python3.10/site-packages/django/middleware/common.py", line 54, in process_request
    path = self.get_full_path_with_slash(request)
  File "/Users/owner/Desktop/flixcave/venv/lib/python3.10/site-packages/django/middleware/common.py", line 88, in get_full_path_with_slash
    raise RuntimeError(
RuntimeError: You called this URL via POST, but the URL doesn't end in a slash and you have APPEND_SLASH set. Django can't redirect to the slash URL while maintaining POST data. Change your form to point to localhost:8000/api/v1/auth/resend-verify/ (note the trailing slash), or set APPEND_SLASH=False in your Django settings.
ERROR 2022-07-24 16:45:47,163 187 basehttp.py basehttp 42854 123145561505792 "POST /api/v1/auth/resend-verify HTTP/1.1" 500 70642
ERROR 2022-07-24 16:46:14,325 241 log.py log 42854 123145561505792 Internal Server Error: /api/v1/auth/resend-verify
Traceback (most recent call last):
  File "/Users/owner/Desktop/flixcave/venv/lib/python3.10/site-packages/django/core/handlers/exception.py", line 55, in inner
    response = get_response(request)
  File "/Users/owner/Desktop/flixcave/venv/lib/python3.10/site-packages/django/utils/deprecation.py", line 133, in __call__
    response = self.process_request(request)
  File "/Users/owner/Desktop/flixcave/venv/lib/python3.10/site-packages/django/middleware/common.py", line 54, in process_request
    path = self.get_full_path_with_slash(request)
  File "/Users/owner/Desktop/flixcave/venv/lib/python3.10/site-packages/django/middleware/common.py", line 88, in get_full_path_with_slash
    raise RuntimeError(
RuntimeError: You called this URL via POST, but the URL doesn't end in a slash and you have APPEND_SLASH set. Django can't redirect to the slash URL while maintaining POST data. Change your form to point to localhost:8000/api/v1/auth/resend-verify/ (note the trailing slash), or set APPEND_SLASH=False in your Django settings.
ERROR 2022-07-24 16:46:14,325 187 basehttp.py basehttp 42854 123145561505792 "POST /api/v1/auth/resend-verify HTTP/1.1" 500 70642
ERROR 2022-07-24 16:48:47,665 241 log.py log 42949 123145437798400 Internal Server Error: /api/v1/auth/resend-verify/
Traceback (most recent call last):
  File "/Users/owner/Desktop/flixcave/venv/lib/python3.10/site-packages/django/core/handlers/exception.py", line 55, in inner
    response = get_response(request)
  File "/Users/owner/Desktop/flixcave/venv/lib/python3.10/site-packages/django/core/handlers/base.py", line 197, in _get_response
    response = wrapped_callback(request, *callback_args, **callback_kwargs)
  File "/Users/owner/Desktop/flixcave/venv/lib/python3.10/site-packages/django/views/decorators/csrf.py", line 54, in wrapped_view
    return view_func(*args, **kwargs)
  File "/Users/owner/Desktop/flixcave/venv/lib/python3.10/site-packages/django/views/generic/base.py", line 84, in view
    return self.dispatch(request, *args, **kwargs)
  File "/Users/owner/Desktop/flixcave/venv/lib/python3.10/site-packages/rest_framework/views.py", line 509, in dispatch
    response = self.handle_exception(exc)
  File "/Users/owner/Desktop/flixcave/venv/lib/python3.10/site-packages/rest_framework/views.py", line 469, in handle_exception
    self.raise_uncaught_exception(exc)
  File "/Users/owner/Desktop/flixcave/venv/lib/python3.10/site-packages/rest_framework/views.py", line 480, in raise_uncaught_exception
    raise exc
  File "/Users/owner/Desktop/flixcave/venv/lib/python3.10/site-packages/rest_framework/views.py", line 506, in dispatch
    response = handler(request, *args, **kwargs)
  File "/Users/owner/Desktop/flixcave/authentication/views.py", line 25, in post
    user = CustomUser.objects.all().filter(email=request.data.email).first()
AttributeError: 'dict' object has no attribute 'email'
ERROR 2022-07-24 16:48:47,667 187 basehttp.py basehttp 42949 123145437798400 "POST /api/v1/auth/resend-verify/ HTTP/1.1" 500 91148
ERROR 2022-07-24 17:09:28,465 241 log.py log 43354 123145558929408 Internal Server Error: /api/v1/auth/verify/
Traceback (most recent call last):
  File "/Users/owner/Desktop/flixcave/venv/lib/python3.10/site-packages/django/core/handlers/exception.py", line 55, in inner
    response = get_response(request)
  File "/Users/owner/Desktop/flixcave/venv/lib/python3.10/site-packages/django/core/handlers/base.py", line 197, in _get_response
    response = wrapped_callback(request, *callback_args, **callback_kwargs)
  File "/Users/owner/Desktop/flixcave/venv/lib/python3.10/site-packages/django/views/decorators/csrf.py", line 54, in wrapped_view
    return view_func(*args, **kwargs)
  File "/Users/owner/Desktop/flixcave/venv/lib/python3.10/site-packages/django/views/generic/base.py", line 84, in view
    return self.dispatch(request, *args, **kwargs)
  File "/Users/owner/Desktop/flixcave/venv/lib/python3.10/site-packages/rest_framework/views.py", line 509, in dispatch
    response = self.handle_exception(exc)
  File "/Users/owner/Desktop/flixcave/venv/lib/python3.10/site-packages/rest_framework/views.py", line 469, in handle_exception
    self.raise_uncaught_exception(exc)
  File "/Users/owner/Desktop/flixcave/venv/lib/python3.10/site-packages/rest_framework/views.py", line 480, in raise_uncaught_exception
    raise exc
  File "/Users/owner/Desktop/flixcave/venv/lib/python3.10/site-packages/rest_framework/views.py", line 506, in dispatch
    response = handler(request, *args, **kwargs)
  File "/Users/owner/Desktop/flixcave/authentication/views.py", line 50, in post
    CustomUser.objects.verify_account(serializer.validated_data)
  File "/Users/owner/Desktop/flixcave/account/models.py", line 32, in verify_account
    user = CustomUser.objects.get(pk=decoded_token['user_id'])
  File "/Users/owner/Desktop/flixcave/venv/lib/python3.10/site-packages/django/db/models/manager.py", line 85, in manager_method
    return getattr(self.get_queryset(), name)(*args, **kwargs)
  File "/Users/owner/Desktop/flixcave/venv/lib/python3.10/site-packages/django/db/models/query.py", line 496, in get
    raise self.model.DoesNotExist(
account.models.CustomUser.DoesNotExist: CustomUser matching query does not exist.
ERROR 2022-07-24 17:09:28,466 187 basehttp.py basehttp 43354 123145558929408 "POST /api/v1/auth/verify/ HTTP/1.1" 500 104695
ERROR 2022-07-24 17:32:05,991 241 log.py log 43761 123145491111936 Internal Server Error: /api/v1/auth/login/
Traceback (most recent call last):
  File "/Users/owner/Desktop/flixcave/venv/lib/python3.10/site-packages/rest_framework/fields.py", line 457, in get_attribute
    return get_attribute(instance, self.source_attrs)
  File "/Users/owner/Desktop/flixcave/venv/lib/python3.10/site-packages/rest_framework/fields.py", line 97, in get_attribute
    instance = getattr(instance, attr)
AttributeError: 'CustomUser' object has no attribute 'initials'

During handling of the above exception, another exception occurred:

Traceback (most recent call last):
  File "/Users/owner/Desktop/flixcave/venv/lib/python3.10/site-packages/django/core/handlers/exception.py", line 55, in inner
    response = get_response(request)
  File "/Users/owner/Desktop/flixcave/venv/lib/python3.10/site-packages/django/core/handlers/base.py", line 197, in _get_response
    response = wrapped_callback(request, *callback_args, **callback_kwargs)
  File "/Users/owner/Desktop/flixcave/venv/lib/python3.10/site-packages/django/views/decorators/csrf.py", line 54, in wrapped_view
    return view_func(*args, **kwargs)
  File "/Users/owner/Desktop/flixcave/venv/lib/python3.10/site-packages/django/views/generic/base.py", line 84, in view
    return self.dispatch(request, *args, **kwargs)
  File "/Users/owner/Desktop/flixcave/venv/lib/python3.10/site-packages/rest_framework/views.py", line 509, in dispatch
    response = self.handle_exception(exc)
  File "/Users/owner/Desktop/flixcave/venv/lib/python3.10/site-packages/rest_framework/views.py", line 469, in handle_exception
    self.raise_uncaught_exception(exc)
  File "/Users/owner/Desktop/flixcave/venv/lib/python3.10/site-packages/rest_framework/views.py", line 480, in raise_uncaught_exception
    raise exc
  File "/Users/owner/Desktop/flixcave/venv/lib/python3.10/site-packages/rest_framework/views.py", line 506, in dispatch
    response = handler(request, *args, **kwargs)
  File "/Users/owner/Desktop/flixcave/authentication/views.py", line 114, in post
    'user': user_serializer.data,
  File "/Users/owner/Desktop/flixcave/venv/lib/python3.10/site-packages/rest_framework/serializers.py", line 555, in data
    ret = super().data
  File "/Users/owner/Desktop/flixcave/venv/lib/python3.10/site-packages/rest_framework/serializers.py", line 253, in data
    self._data = self.to_representation(self.instance)
  File "/Users/owner/Desktop/flixcave/venv/lib/python3.10/site-packages/rest_framework/serializers.py", line 509, in to_representation
    attribute = field.get_attribute(instance)
  File "/Users/owner/Desktop/flixcave/venv/lib/python3.10/site-packages/rest_framework/fields.py", line 490, in get_attribute
    raise type(exc)(msg)
AttributeError: Got AttributeError when attempting to get a value for field `initials` on serializer `UserSerializer`.
The serializer field might be named incorrectly and not match any attribute or key on the `CustomUser` instance.
Original exception text was: 'CustomUser' object has no attribute 'initials'.
ERROR 2022-07-24 17:32:05,995 187 basehttp.py basehttp 43761 123145491111936 "POST /api/v1/auth/login/ HTTP/1.1" 500 121059
ERROR 2022-07-24 17:34:26,446 241 log.py log 43831 123145419075584 Internal Server Error: /api/v1/auth/login/
Traceback (most recent call last):
  File "/Users/owner/Desktop/flixcave/venv/lib/python3.10/site-packages/django/core/handlers/exception.py", line 55, in inner
    response = get_response(request)
  File "/Users/owner/Desktop/flixcave/venv/lib/python3.10/site-packages/django/core/handlers/base.py", line 197, in _get_response
    response = wrapped_callback(request, *callback_args, **callback_kwargs)
  File "/Users/owner/Desktop/flixcave/venv/lib/python3.10/site-packages/django/views/decorators/csrf.py", line 54, in wrapped_view
    return view_func(*args, **kwargs)
  File "/Users/owner/Desktop/flixcave/venv/lib/python3.10/site-packages/django/views/generic/base.py", line 84, in view
    return self.dispatch(request, *args, **kwargs)
  File "/Users/owner/Desktop/flixcave/venv/lib/python3.10/site-packages/rest_framework/views.py", line 509, in dispatch
    response = self.handle_exception(exc)
  File "/Users/owner/Desktop/flixcave/venv/lib/python3.10/site-packages/rest_framework/views.py", line 469, in handle_exception
    self.raise_uncaught_exception(exc)
  File "/Users/owner/Desktop/flixcave/venv/lib/python3.10/site-packages/rest_framework/views.py", line 480, in raise_uncaught_exception
    raise exc
  File "/Users/owner/Desktop/flixcave/venv/lib/python3.10/site-packages/rest_framework/views.py", line 506, in dispatch
    response = handler(request, *args, **kwargs)
  File "/Users/owner/Desktop/flixcave/authentication/views.py", line 114, in post
    'user': user_serializer.data,
  File "/Users/owner/Desktop/flixcave/venv/lib/python3.10/site-packages/rest_framework/serializers.py", line 555, in data
    ret = super().data
  File "/Users/owner/Desktop/flixcave/venv/lib/python3.10/site-packages/rest_framework/serializers.py", line 253, in data
    self._data = self.to_representation(self.instance)
  File "/Users/owner/Desktop/flixcave/venv/lib/python3.10/site-packages/rest_framework/serializers.py", line 509, in to_representation
    attribute = field.get_attribute(instance)
  File "/Users/owner/Desktop/flixcave/venv/lib/python3.10/site-packages/rest_framework/fields.py", line 457, in get_attribute
    return get_attribute(instance, self.source_attrs)
  File "/Users/owner/Desktop/flixcave/venv/lib/python3.10/site-packages/rest_framework/fields.py", line 97, in get_attribute
    instance = getattr(instance, attr)
  File "/Users/owner/Desktop/flixcave/account/models.py", line 145, in initials
    print(self.first_name.split('')[0:1])
ValueError: empty separator
ERROR 2022-07-24 17:34:26,450 187 basehttp.py basehttp 43831 123145419075584 "POST /api/v1/auth/login/ HTTP/1.1" 500 116457
